Workbook
Name _Hlk501003162: BCNHANH!$E$1
Name BCN: MENU!#REF!
Name BCN: MENU!#REF!
Name BCN: MENU!#REF!
Name BCN: MENU!#REF!
Name BCN: MENU!#REF!
Name BCN: MENU!#REF!
Name BCN: MENU!#REF!
Name MS: [1]CDPS!$B$11:$B$219
Name PSCKC: [1]CDPS!$J$11:$J$219
Name PSCKN: [1]CDPS!$I$11:$I$219
Name PSDKC: [1]CDPS!$F$11:$F$219
Name PSDKN: [1]CDPS!$E$11:$E$219

Sheet MENU
B5: PHÂN TÍCH BÁO CÁO TÀI CHÍNH - TẠO THÔNG TIN HỖ TRỢ LẬP BÁO CÁO THẨM ĐỊNH

Sheet CĐKT
A2: BẢNG CÂN ĐỐI KẾ TOÁN
A4: STT | B4: Chỉ tiêu | C4: Mã số | D4: Năm 2015 | F4: Năm 2016
D5: Đầu kỳ | E5: Cuối kỳ | F5: Đầu kỳ | G5: Cuối kỳ
B6: TÀI SẢN
A7: A | B7: TÀI SẢN NGẮN HẠN (100=110+120+130+140+150) | C7: 100 | D7: =D8+D11+D15+D24+D27 -> 5844829 | E7: =E8+E11+E15+E24+E27 -> 5844829 | F7: =F8+F11+F15+F24+F27 -> 4127123 | G7: =G8+G11+G15+G24+G27 -> 4127123
A8: I | B8: Tiền và các khoản tương đương tiền (110=111+112) | C8: 110 | D8: =D9+D10 -> 2004349 | E8: =E9+E10 -> 2004349 | F8: =F9+F10 -> 396214 | G8: =G9+G10 -> 396214
A9: 1 | B9: Tiền | C9: 111 | D9: 1704000 | E9: 1704000 | F9: 295865 | G9: 295865
A10: 2 | B10: Các khoản tương đương tiền | C10: 112 | D10: 300349 | E10: 300349 | F10: 100349 | G10: 100349
A11: II | B11: Các khoản đầu tư tài chính ngắn hạn (120=121+129) | C11: 120 | D11: =D12+D13+D14 -> 1600 | E11: =E12+E13+E14 -> 1600 | F11: =F12+F13+F14 -> 0 | G11: =G12+G13+G14 -> 0
A12: 1 | B12: Chứng khoán kinh doanh | C12: 121 | D12: 1700 | E12: 1700 | F12: 0 | G12: 0
A13: 2 | B13: Dự phòng giảm giá chứng khoán kinh doanh (*) | C13: 122 | D13: -100 | E13: -100 | F13: 0 | G13: 0
A14: 3 | B14: Đầu tư nắm giữ đến ngày đáo hạn | C14: 123 | D14: 0 | E14: 0 | F14: 0 | G14: 0
A15: III | B15: Các khoản phải thu ngắn hạn (130 = 131 + 132 + 133 + 134 + 135 + 139) | C15: 130 | D15: =SUM(D16:D23) -> 1412543 | E15: =SUM(E16:E23) -> 1412543 | F15: =SUM(F16:F23) -> 938461 | G15: =SUM(G16:G23) -> 938461
A16: 1 | B16: Phải thu ngắn hạn của khách hàng | C16: 131 | D16: 1052236 | E16: 1052236 | F16: 509498 | G16: 509498
A17: 2 | B17: Trả trước cho người bán ngắn hạn | C17: 132 | D17: 480329 | E17: 480329 | F17: 404143 | G17: 404143
A18: 3 | B18: Phải thu nội bộ ngắn hạn | C18: 133 | D18: 0 | E18: 0 | F18: 0 | G18: 0
A19: 4 | B19: Phải thu theo tiến độ kế hoạch hợp đồng xây dựng | C19: 134 | D19: 0 | E19: 0 | F19: 0 | G19: 0
A20: 5 | B20: Phải thu về cho vay ngắn hạn | C20: 135 | D20: 0 | E20: 0 | F20: 0 | G20: 0
A21: 6 | B21: Các khoản phải thu ngắn hạn khác | C21: 136 | D21: 174616 | E21: 174616 | F21: 364179 | G21: 364179
A22: 7 | B22: Tài sản thiếu chờ xử lý | C22: 137 | D22: 60083 | E22: 60083 | F22: 6428 | G22: 6428
A23: 8 | B23: Dự phòng phải thu ngắn hạn khó đòi (*) | C23: 139 | D23: -354721 | E23: -354721 | F23: -345787 | G23: -345787
A24: IV | B24: Hàng tồn kho (140 = 141 + 149) | C24: 140 | D24: =D25+D26 -> 2225065 | E24: =E25+E26 -> 2225065 | F24: =F25+F26 -> 2616859 | G24: =G25+G26 -> 2616859
A25: 1 | B25: Hàng tồn kho | C25: 141 | D25: 2229006 | E25: 2229006 | F25: 2620718 | G25: 2620718
A26: 2 | B26: Dự phòng giảm giá hàng tồn kho (*) | C26: 149 | D26: -3941 | E26: -3941 | F26: -3859 | G26: -3859
A27: V | B27: Tài sản ngắn hạn khác (150 = 151 + 152 + 154 + 158) | C27: 150 | D27: =SUM(D28:D32) -> 201272 | E27: =SUM(E28:E32) -> 201272 | F27: =SUM(F28:F32) -> 175589 | G27: =SUM(G28:G32) -> 175589
A28: 1 | B28: 1. Chi phí trả trước ngắn hạn | C28: 151 | D28: 161134 | E28: 161134 | F28: 120247 | G28: 120247
A29: 2 | B29: 2. Thuế GTGT được khấu trừ | C29: 152 | D29: 34995 | E29: 34995 | F29: 51187 | G29: 51187
A30: 3 | B30: 3. Thuế và các khoản khác phải thu nhà nước | C30: 153 | D30: 5143 | E30: 5143 | F30: 4155 | G30: 4155
A31: 4 | B31: 4. Giao dịch mua bán lại trái phiếu Chính phủ | C31: 154 | D31: 0 | E31: 0 | F31: 0 | G31: 0
A32: 5 | B32: 5. Tài sản ngắn hạn khác | C32: 155 | D32: 0 | E32: 0 | F32: 0 | G32: 0
A33: B | B33: TÀI SẢN DÀI HẠN (200=210+220+240+250+260) | C33: 200 | D33: =D34+D42+D52+D55+D58+D64 -> 3919533 | E33: =E34+E42+E52+E55+E58+E64 -> 3919533 | F33: =F34+F42+F52+F55+F58+F64 -> 3758327 | G33: =G34+G42+G52+G55+G58+G64 -> 3758327
A34: I | B34: Các khoản phải thu dài hạn (210 = 211 + 212 + 213 + 218 + 219) | C34: 210 | D34: =SUM(D35:D41) -> 591169 | E34: =SUM(E35:E41) -> 591169 | F34: =SUM(F35:F41) -> 592134 | G34: =SUM(G35:G41) -> 592134
A35: 1 | B35: Phải thu dài hạn của khách hàng | C35: 211 | D35: 575490 | E35: 575490 | F35: 583815 | G35: 583815
A36: 2 | B36: Trả trước cho người bán dài hạn | C36: 212 | D36: 0 | E36: 0 | F36: 0 | G36: 0
A37: 3 | B37: Vốn kinh doanh ở đơn vị trực thuộc | C37: 213 | D37: 0 | E37: 0 | F37: 0 | G37: 0
A38: 4 | B38: Phải thu dài hạn nội bộ | C38: 214 | D38: 0 | E38: 0 | F38: 0 | G38: 0
A39: 5 | B39: Phải thu về cho vay dài hạn | C39: 215 | D39: 0 | E39: 0 | F39: 0 | G39: 0
A40: 6 | B40: Phải thu dài hạn khác | C40: 216 | D40: 15679 | E40: 15679 | F40: 8319 | G40: 8319
A41: 7 | B41: Dự phòng phải thu dài hạn khó đòi (*) | C41: 219 | D41: 0 | E41: 0 | F41: 0 | G41: 0
A42: II | B42: Tài sản cố định (220 = 221 + 224 + 227 + 230) | C42: 220 | D42: =D43+D46+D49 -> 2179443 | E42: =E43+E46+E49 -> 2179443 | F42: =F43+F46+F49 -> 2130366 | G42: =G43+G46+G49 -> 2130366
...

Sheet CĐKT-Word
B2: BẢNG CÂN ĐỐI KẾ TOÁN
A4: STT | B4: Chỉ tiêu | C4: Mã số | D4: Năm 2015 | F4: Năm 2016 | I4: So sánh 2015/2016
I5: +/- | J5: %
B6: TÀI SẢN
A7: A | B7: TÀI SẢN NGẮN HẠN (100=110+120+130+140+150) | C7: 100 | D7: =D8+D11+D15+D24+D27 -> 5844829 | E7: =E8+E11+E15+E24+E27 -> 5844829 | F7: =F8+F11+F15+F24+F27 -> 4127123 | G7: =G8+G11+G15+G24+G27 -> 4127123 | I7: =G7-E7 -> -1717706 | J7: =I7/E7 -> -0.29388473
A8: I | B8: Tiền và các khoản tương đương tiền (110=111+112) | C8: 110 | D8: =D9+D10 -> 2004349 | E8: =E9+E10 -> 2004349 | F8: =F9+F10 -> 396214 | G8: =G9+G10 -> 396214 | I8: =G8-E8 -> -1608135 | J8: =I8/E8 -> -0.80232285
A9: 1 | B9: Tiền | C9: 111 | D9: 1704000 | E9: =CĐKT!E9 -> 1704000 | F9: 295865 | G9: =CĐKT!G9 -> 295865 | I9: =G9-E9 -> -1408135 | J9: =I9/E9 -> -0.82637031
A10: 2 | B10: Các khoản tương đương tiền | C10: 112 | D10: 300349 | E10: =CĐKT!E10 -> 300349 | F10: 100349 | G10: =CĐKT!G10 -> 100349 | I10: =G10-E10 -> -200000 | J10: =I10/E10 -> -0.66589201
A11: II | B11: Các khoản đầu tư tài chính ngắn hạn (120=121+129) | C11: 120 | D11: =D12+D13+D14 -> 1600 | E11: =E12+E13+E14 -> 1600 | F11: =F12+F13+F14 -> 0 | G11: =G12+G13+G14 -> 0 | I11: =G11-E11 -> -1600 | J11: =I11/E11 -> -1
A12: 1 | B12: Chứng khoán kinh doanh | C12: 121 | D12: 1700 | E12: =CĐKT!E12 -> 1700 | F12: 0 | G12: =CĐKT!G12 -> 0 | I12: =G12-E12 -> -1700 | J12: =I12/E12 -> -1
A13: 2 | B13: Dự phòng giảm giá chứng khoán kinh doanh (*) | C13: 122 | D13: -100 | E13: =CĐKT!E13 -> -100 | F13: 0 | G13: =CĐKT!G13 -> 0 | I13: =G13-E13 -> 100 | J13: =I13/E13 -> -1
A14: 3 | B14: Đầu tư nắm giữ đến ngày đáo hạn | C14: 123 | D14: 0 | E14: =CĐKT!E14 -> 0 | F14: 0 | G14: =CĐKT!G14 -> 0 | I14: =G14-E14 -> 0 | J14: \
A15: III | B15: Các khoản phải thu ngắn hạn (130 = 131 + 132 + 133 + 134 + 135 + 139) | C15: 130 | D15: =SUM(D16:D23) -> 1412543 | E15: =SUM(E16:E23) -> 1412543 | F15: =SUM(F16:F23) -> 938461 | G15: =SUM(G16:G23) -> 938461 | I15: =G15-E15 -> -474082 | J15: =I15/E15 -> -0.33562306
A16: 1 | B16: Phải thu ngắn hạn của khách hàng | C16: 131 | D16: 1052236 | E16: =CĐKT!E16 -> 1052236 | F16: 509498 | G16: =CĐKT!G16 -> 509498 | I16: =G16-E16 -> -542738 | J16: =I16/E16 -> -0.51579494
A17: 2 | B17: Trả trước cho người bán ngắn hạn | C17: 132 | D17: 480329 | E17: =CĐKT!E17 -> 480329 | F17: 404143 | G17: =CĐKT!G17 -> 404143 | I17: =G17-E17 -> -76186 | J17: =I17/E17 -> -0.15861212
A18: 3 | B18: Phải thu nội bộ ngắn hạn | C18: 133 | D18: 0 | E18: =CĐKT!E18 -> 0 | F18: 0 | G18: =CĐKT!G18 -> 0 | I18: =G18-E18 -> 0 | J18: \
A19: 4 | B19: Phải thu theo tiến độ kế hoạch hợp đồng xây dựng | C19: 134 | D19: 0 | E19: =CĐKT!E19 -> 0 | F19: 0 | G19: =CĐKT!G19 -> 0 | I19: =G19-E19 -> 0 | J19: \
A20: 5 | B20: Phải thu về cho vay ngắn hạn | C20: 135 | D20: 0 | E20: =CĐKT!E20 -> 0 | F20: 0 | G20: =CĐKT!G20 -> 0 | I20: =G20-E20 -> 0 | J20: \
A21: 6 | B21: Các khoản phải thu ngắn hạn khác | C21: 136 | D21: 174616 | E21: =CĐKT!E21 -> 174616 | F21: 364179 | G21: =CĐKT!G21 -> 364179 | I21: =G21-E21 -> 189563 | J21: =I21/E21 -> 1.0855993
A22: 7 | B22: Tài sản thiếu chờ xử lý | C22: 137 | D22: 60083 | E22: =CĐKT!E22 -> 60083 | F22: 6428 | G22: =CĐKT!G22 -> 6428 | I22: =G22-E22 -> -53655 | J22: =I22/E22 -> -0.89301466
A23: 8 | B23: Dự phòng phải thu ngắn hạn khó đòi (*) | C23: 139 | D23: -354721 | E23: =CĐKT!E23 -> -354721 | F23: -345787 | G23: =CĐKT!G23 -> -345787 | I23: =G23-E23 -> 8934 | J23: =I23/E23 -> -0.025185991
A24: IV | B24: Hàng tồn kho (140 = 141 + 149) | C24: 140 | D24: =D25+D26 -> 2225065 | E24: =E25+E26 -> 2225065 | F24: =F25+F26 -> 2616859 | G24: =G25+G26 -> 2616859 | I24: =G24-E24 -> 391794 | J24: =I24/E24 -> 0.17608205
A25: 1 | B25: Hàng tồn kho | C25: 141 | D25: 2229006 | E25: =CĐKT!E25 -> 2229006 | F25: 2620718 | G25: =CĐKT!G25 -> 2620718 | I25: =G25-E25 -> 391712 | J25: =I25/E25 -> 0.17573394
A26: 2 | B26: Dự phòng giảm giá hàng tồn kho (*) | C26: 149 | D26: -3941 | E26: =CĐKT!E26 -> -3941 | F26: -3859 | G26: =CĐKT!G26 -> -3859 | I26: =G26-E26 -> 82 | J26: =I26/E26 -> -0.020806902
A27: V | B27: Tài sản ngắn hạn khác (150 = 151 + 152 + 154 + 158) | C27: 150 | D27: =SUM(D28:D32) -> 201272 | E27: =SUM(E28:E32) -> 201272 | F27: =SUM(F28:F32) -> 175589 | G27: =SUM(G28:G32) -> 175589 | I27: =G27-E27 -> -25683 | J27: =I27/E27 -> -0.12760344
A28: 1 | B28: Chi phí trả trước ngắn hạn | C28: 151 | D28: 161134 | E28: =CĐKT!E28 -> 161134 | F28: 120247 | G28: =CĐKT!G28 -> 120247 | I28: =G28-E28 -> -40887 | J28: =I28/E28 -> -0.25374533
A29: 2 | B29: Thuế GTGT được khấu trừ | C29: 152 | D29: 34995 | E29: =CĐKT!E29 -> 34995 | F29: 51187 | G29: =CĐKT!G29 -> 51187 | I29: =G29-E29 -> 16192 | J29: =I29/E29 -> 0.46269467
A30: 3 | B30: Thuế và các khoản khác phải thu nhà nước | C30: 153 | D30: 5143 | E30: =CĐKT!E30 -> 5143 | F30: 4155 | G30: =CĐKT!G30 -> 4155 | I30: =G30-E30 -> -988 | J30: =I30/E30 -> -0.19210577
A31: 4 | B31: Giao dịch mua bán lại trái phiếu Chính phủ | C31: 154 | D31: 0 | E31: =CĐKT!E31 -> 0 | F31: 0 | G31: =CĐKT!G31 -> 0 | I31: =G31-E31 -> 0 | J31: \
A32: 5 | B32: Tài sản ngắn hạn khác | C32: 155 | D32: 0 | E32: =CĐKT!E32 -> 0 | F32: 0 | G32: =CĐKT!G32 -> 0 | I32: =G32-E32 -> 0 | J32: \
A33: B | B33: TÀI SẢN DÀI HẠN (200=210+220+240+250+260) | C33: 200 | D33: =D34+D42+D52+D55+D58+D64 -> 3919533 | E33: =E34+E42+E52+E55+E58+E64 -> 3919533 | F33: =F34+F42+F52+F55+F58+F64 -> 3758327 | G33: =G34+G42+G52+G55+G58+G64 -> 3758327 | I33: =G33-E33 -> -161206 | J33: =I33/E33 -> -0.041128879
A34: I | B34: Các khoản phải thu dài hạn (210 = 211 + 212 + 213 + 218 + 219) | C34: 210 | D34: =SUM(D35:D41) -> 591169 | E34: =SUM(E35:E41) -> 591169 | F34: =SUM(F35:F41) -> 592134 | G34: =SUM(G35:G41) -> 592134 | I34: =G34-E34 -> 965 | J34: =I34/E34 -> 0.0016323589
A35: 1 | B35: Phải thu dài hạn của khách hàng | C35: 211 | D35: 575490 | E35: =CĐKT!E35 -> 575490 | F35: 583815 | G35: =CĐKT!G35 -> 583815 | I35: =G35-E35 -> 8325 | J35: =I35/E35 -> 0.014465933
A36: 2 | B36: Trả trước cho người bán dài hạn | C36: 212 | D36: 0 | E36: =CĐKT!E36 -> 0 | F36: 0 | G36: =CĐKT!G36 -> 0 | I36: =G36-E36 -> 0 | J36: \
A37: 3 | B37: Vốn kinh doanh ở đơn vị trực thuộc | C37: 213 | D37: 0 | E37: =CĐKT!E37 -> 0 | F37: 0 | G37: =CĐKT!G37 -> 0 | I37: =G37-E37 -> 0 | J37: \
A38: 4 | B38: Phải thu dài hạn nội bộ | C38: 214 | D38: 0 | E38: =CĐKT!E38 -> 0 | F38: 0 | G38: =CĐKT!G38 -> 0 | I38: =G38-E38 -> 0 | J38: \
A39: 5 | B39: Phải thu về cho vay dài hạn | C39: 215 | D39: 0 | E39: =CĐKT!E39 -> 0 | F39: 0 | G39: =CĐKT!G39 -> 0 | I39: =G39-E39 -> 0 | J39: \
A40: 6 | B40: Phải thu dài hạn khác | C40: 216 | D40: 15679 | E40: =CĐKT!E40 -> 15679 | F40: 8319 | G40: =CĐKT!G40 -> 8319 | I40: =G40-E40 -> -7360 | J40: =I40/E40 -> -0.46941769
A41: 7 | B41: Dự phòng phải thu dài hạn khó đòi (*) | C41: 219 | D41: 0 | E41: =CĐKT!E41 -> 0 | F41: 0 | G41: =CĐKT!G41 -> 0 | I41: =G41-E41 -> 0 | J41: \
A42: II | B42: Tài sản cố định (220 = 221 + 224 + 227 + 230) | C42: 220 | D42: =D43+D46+D49 -> 2179443 | E42: =E43+E46+E49 -> 2179443 | F42: =F43+F46+F49 -> 2130366 | G42: =G43+G46+G49 -> 2130366 | I42: =G42-E42 -> -49077 | J42: =I42/E42 -> -0.022518139
...

Sheet KQKD
A1: BÁO CÁO KẾT QUẢ KINH DOANH
A4: STT | B4: Chỉ tiêu | C4: Mã số | D4: Năm 2015 | F4: Năm 2016 | H4: So sánh 2015/2016
D5: Đầu kỳ | E5: Cuối kỳ | F5: Đầu kỳ | G5: Cuối kỳ | H5: +/- | I5: %
A6: 1 | B6: Doanh thu bán hàng và cung cấp dịch vụ | C6: 01 | D6: 15667470 | E6: 15667470 | F6: 9969052 | G6: 9969052 | H6: =G6-E6 -> -5698418 | I6: =H6/E6 -> -0.36371016
A7: 2 | B7: Các khoản giảm trừ doanh thu | C7: 02 | D7: 15657 | E7: 15657 | F7: 17642 | G7: 17642 | H7: =G7-E7 -> 1985 | I7: =H7/E7 -> 0.12678035
A8: 3 | B8: Doanh thu thuần về bán hàng và cung cấp dịch vụ | C8: 10 | D8: =D6-D7 -> 15651813 | E8: =E6-E7 -> 15651813 | F8: =F6-F7 -> 9951410 | G8: =G6-G7 -> 9951410 | H8: =G8-E8 -> -5700403 | I8: =H8/E8 -> -0.36420081
A9: 4 | B9: Giá vốn hàng bán | C9: 11 | D9: 13069598 | E9: 13069598 | F9: 8390076 | G9: 8390076 | H9: =G9-E9 -> -4679522 | I9: =H9/E9 -> -0.35804636
A10: 5 | B10: Lợi nhuận gộp về bán hàng và cung cấp dịch vụ | C10: 20 | D10: =D8-D9 -> 2582215 | E10: =E8-E9 -> 2582215 | F10: =F8-F9 -> 1561334 | G10: =G8-G9 -> 1561334 | H10: =G10-E10 -> -1020881 | I10: =H10/E10 -> -0.39535089
A11: 6 | B11: Doanh thu hoạt động tài chính | C11: 21 | D11: 214325 | E11: 214325 | F11: 92863 | G11: 92863 | H11: =G11-E11 -> -121462 | I11: =H11/E11 -> -0.56671877
A12: 7 | B12: Chi phí tài chính | C12: 22 | D12: 523950 | E12: 523950 | F12: 53797 | G12: 53797 | H12: =G12-E12 -> -470153 | I12: =H12/E12 -> -0.89732417
B13: -Trong đó: Chi phí lãi vay | C13: 23 | D13: 233101 | E13: 233101 | F13: 137046 | G13: 137046 | H13: =G13-E13 -> -96055 | I13: =H13/E13 -> -0.41207459
A14: 8 | B14: Chi phí bán hàng | C14: 24 | D14: 2031348 | E14: 2031348 | F14: 1248769 | G14: 1248769 | H14: =G14-E14 -> -782579 | I14: =H14/E14 -> -0.38525107
A15: 9 | B15: Chí phí quản lý doanh nghiệp | C15: 25 | D15: 277125 | E15: 277125 | F15: 209680 | G15: 209680 | H15: =G15-E15 -> -67445 | I15: =H15/E15 -> -0.24337393
A16: 10 | B16: Lợi nhuận thuần từ hoạt động kinh doanh | C16: 30 | D16: =D10+D11-D12-D14-D15 -> -35883 | E16: =E10+E11-E12-E14-E15 -> -35883 | F16: =F10+F11-F12-F14-F15 -> 141951 | G16: =G10+G11-G12-G14-G15 -> 141951 | H16: =G16-E16 -> 177834 | I16: =H16/E16 -> -4.9559401
A17: 11 | B17: Thu nhập khác | C17: 31 | D17: 287151 | E17: 287151 | F17: 65403 | G17: 65403 | H17: =G17-E17 -> -221748 | I17: =H17/E17 -> -0.77223482
A18: 12 | B18: Chi phí khác | C18: 32 | D18: 95472 | E18: 95472 | F18: 45975 | G18: 45975 | H18: =G18-E18 -> -49497 | I18: =H18/E18 -> -0.5184452
A19: 13 | B19: Lợi nhuận khác | C19: 40 | D19: =D17-D18 -> 191679 | E19: =E17-E18 -> 191679 | F19: =F17-F18 -> 19428 | G19: =G17-G18 -> 19428 | H19: =G19-E19 -> -172251 | I19: =H19/E19 -> -0.89864304
A20: 14 | B20: Tổng lợi nhuận kế toán trước thuế | C20: 50 | D20: =D16+D19 -> 155796 | E20: =E16+E19 -> 155796 | F20: =F16+F19 -> 161379 | G20: =G16+G19 -> 161379 | H20: =G20-E20 -> 5583 | I20: =H20/E20 -> 0.035835323
A21: 15 | B21: Chi phí thuế TNDN | C21: 51 | D21: 19764 | E21: 19764 | F21: 4856 | G21: 4856 | H21: =G21-E21 -> -14908 | I21: =H21/E21 -> -0.75430075
A22: 16 | B22: Lợi nhuận sau thuế thu nhập doanh nghiệp | C22: 60 | D22: =D20-D21 -> 136032 | E22: =E20-E21 -> 136032 | F22: =F20-F21 -> 156523 | G22: =G20-G21 -> 156523 | H22: =G22-E22 -> 20491 | I22: =H22/E22 -> 0.15063367

Sheet KQKD-Word
A1: BÁO CÁO KẾT QUẢ KINH DOANH
A4: STT | B4: Chỉ tiêu | C4: Mã số | D4: Năm 2015 | F4: Năm 2016 | H4: So sánh 2015/2016
H5: +/- | I5: %
A6: 1 | B6: Doanh thu bán hàng và cung cấp dịch vụ | C6: 01 | D6: 15667470 | E6: =KQKD!E6 -> 15667470 | F6: 9969052 | G6: =KQKD!G6 -> 9969052 | H6: =G6-E6 -> -5698418 | I6: =H6/E6 -> -0.36371016
A7: 2 | B7: Các khoản giảm trừ doanh thu | C7: 02 | D7: 15657 | E7: =KQKD!E7 -> 15657 | F7: 17642 | G7: =KQKD!G7 -> 17642 | H7: =G7-E7 -> 1985 | I7: =H7/E7 -> 0.12678035
A8: 3 | B8: Doanh thu thuần về bán hàng và cung cấp dịch vụ | C8: 10 | D8: =D6-D7 -> 15651813 | E8: =E6-E7 -> 15651813 | F8: =F6-F7 -> 9951410 | G8: =G6-G7 -> 9951410 | H8: =G8-E8 -> -5700403 | I8: =H8/E8 -> -0.36420081
A9: 4 | B9: Giá vốn hàng bán | C9: 11 | D9: 13069598 | E9: =KQKD!E9 -> 13069598 | F9: 8390076 | G9: =KQKD!G9 -> 8390076 | H9: =G9-E9 -> -4679522 | I9: =H9/E9 -> -0.35804636
A10: 5 | B10: Lợi nhuận gộp về bán hàng và cung cấp dịch vụ | C10: 20 | D10: =D8-D9 -> 2582215 | E10: =E8-E9 -> 2582215 | F10: =F8-F9 -> 1561334 | G10: =G8-G9 -> 1561334 | H10: =G10-E10 -> -1020881 | I10: =H10/E10 -> -0.39535089
A11: 6 | B11: Doanh thu hoạt động tài chính | C11: 21 | D11: 214325 | E11: =KQKD!E11 -> 214325 | F11: 92863 | G11: =KQKD!G11 -> 92863 | H11: =G11-E11 -> -121462 | I11: =H11/E11 -> -0.56671877
A12: 7 | B12: Chi phí tài chính | C12: 22 | D12: 523950 | E12: =KQKD!E12 -> 523950 | F12: 53797 | G12: =KQKD!G12 -> 53797 | H12: =G12-E12 -> -470153 | I12: =H12/E12 -> -0.89732417
B13: -Trong đó: Chi phí lãi vay | C13: 23 | D13: 233101 | E13: =KQKD!E13 -> 233101 | F13: 137046 | G13: =KQKD!G13 -> 137046 | H13: =G13-E13 -> -96055 | I13: =H13/E13 -> -0.41207459
A14: 8 | B14: Chi phí bán hàng | C14: 24 | D14: 2031348 | E14: =KQKD!E14 -> 2031348 | F14: 1248769 | G14: =KQKD!G14 -> 1248769 | H14: =G14-E14 -> -782579 | I14: =H14/E14 -> -0.38525107
A15: 9 | B15: Chí phí quản lý doanh nghiệp | C15: 25 | D15: 277125 | E15: =KQKD!E15 -> 277125 | F15: 209680 | G15: =KQKD!G15 -> 209680 | H15: =G15-E15 -> -67445 | I15: =H15/E15 -> -0.24337393
A16: 10 | B16: Lợi nhuận thuần từ hoạt động kinh doanh | C16: 30 | D16: =D10+D11-D12-D14-D15 -> -35883 | E16: =E10+E11-E12-E14-E15 -> -35883 | F16: =F10+F11-F12-F14-F15 -> 141951 | G16: =G10+G11-G12-G14-G15 -> 141951 | H16: =G16-E16 -> 177834 | I16: =H16/E16 -> -4.9559401
A17: 11 | B17: Thu nhập khác | C17: 31 | D17: 287151 | E17: =KQKD!E17 -> 287151 | F17: 65403 | G17: =KQKD!G17 -> 65403 | H17: =G17-E17 -> -221748 | I17: =H17/E17 -> -0.77223482
A18: 12 | B18: Chi phí khác | C18: 32 | D18: 95472 | E18: =KQKD!E18 -> 95472 | F18: 45975 | G18: =KQKD!G18 -> 45975 | H18: =G18-E18 -> -49497 | I18: =H18/E18 -> -0.5184452
A19: 13 | B19: Lợi nhuận khác | C19: 40 | D19: =D17-D18 -> 191679 | E19: =E17-E18 -> 191679 | F19: =F17-F18 -> 19428 | G19: =G17-G18 -> 19428 | H19: =G19-E19 -> -172251 | I19: =H19/E19 -> -0.89864304
A20: 14 | B20: Tổng lợi nhuận kế toán trước thuế | C20: 50 | D20: =D16+D19 -> 155796 | E20: =E16+E19 -> 155796 | F20: =F16+F19 -> 161379 | G20: =G16+G19 -> 161379 | H20: =G20-E20 -> 5583 | I20: =H20/E20 -> 0.035835323
A21: 15 | B21: Chi phí thuế TNDN | C21: 51 | D21: 19764 | E21: =KQKD!E21 -> 19764 | F21: 4856 | G21: =KQKD!G21 -> 4856 | H21: =G21-E21 -> -14908 | I21: =H21/E21 -> -0.75430075
A22: 16 | B22: Lợi nhuận sau thuế thu nhập doanh nghiệp | C22: 60 | D22: =D20-D21 -> 136032 | E22: =E20-E21 -> 136032 | F22: =F20-F21 -> 156523 | G22: =G20-G21 -> 156523 | H22: =G22-E22 -> 20491 | I22: =H22/E22 -> 0.15063367

Sheet KQKD-Word dự báo
B2: BÁO CÁO KẾT QUẢ KINH DOANH | G2: 1.1
A4: STT | B4: Chỉ tiêu | C4: Mã số | D4: Năm 2016 | F4: Năm dự kiến | H4: So sánh 2015/2016
H5: +/- | I5: %
A6: 1 | B6: Doanh thu bán hàng và cung cấp dịch vụ | C6: 01 | D6: 15667470 | E6: =KQKD!G6 -> 9969052 | F6: 9969052 | G6: =E6*$G$2 -> 10965957 | H6: =G6-E6 -> 996905.2 | I6: =H6/E6 -> 0.1
A7: 2 | B7: Các khoản giảm trừ doanh thu | C7: 02 | D7: 15657 | E7: =KQKD!G7 -> 17642 | F7: 17642 | G7: =E7*$G$2 -> 19406.2 | H7: =G7-E7 -> 1764.2 | I7: =H7/E7 -> 0.1
A8: 3 | B8: Doanh thu thuần về bán hàng và cung cấp dịch vụ | C8: 10 | D8: =D6-D7 -> 15651813 | E8: =E6-E7 -> 9951410 | F8: =F6-F7 -> 9951410 | G8: =E8*$G$2 -> 10946551 | H8: =G8-E8 -> 995141 | I8: =H8/E8 -> 0.1
A9: 4 | B9: Giá vốn hàng bán | C9: 11 | D9: 13069598 | E9: =KQKD!G9 -> 8390076 | F9: 8390076 | G9: =E9*$G$2 -> 9229083.6 | H9: =G9-E9 -> 839007.6 | I9: =H9/E9 -> 0.1
A10: 5 | B10: Lợi nhuận gộp về bán hàng và cung cấp dịch vụ | C10: 20 | D10: =D8-D9 -> 2582215 | E10: =E8-E9 -> 1561334 | F10: =F8-F9 -> 1561334 | G10: =E10*$G$2 -> 1717467.4 | H10: =G10-E10 -> 156133.4 | I10: =H10/E10 -> 0.1
A11: 6 | B11: Doanh thu hoạt động tài chính | C11: 21 | D11: 214325 | E11: =KQKD!G11 -> 92863 | F11: 92863 | G11: =E11*$G$2 -> 102149.3 | H11: =G11-E11 -> 9286.3 | I11: =H11/E11 -> 0.1
A12: 7 | B12: Chi phí tài chính | C12: 22 | D12: 523950 | E12: =KQKD!G12 -> 53797 | F12: 53797 | G12: =E12*$G$2 -> 59176.7 | H12: =G12-E12 -> 5379.7 | I12: =H12/E12 -> 0.1
B13: -Trong đó: Chi phí lãi vay | C13: 23 | D13: 233101 | E13: =KQKD!G13 -> 137046 | F13: 137046 | G13: =E13*$G$2 -> 150750.6 | H13: =G13-E13 -> 13704.6 | I13: =H13/E13 -> 0.1
A14: 8 | B14: Chi phí bán hàng | C14: 24 | D14: 2031348 | E14: =KQKD!G14 -> 1248769 | F14: 1248769 | G14: =E14*$G$2 -> 1373645.9 | H14: =G14-E14 -> 124876.9 | I14: =H14/E14 -> 0.1
A15: 9 | B15: Chí phí quản lý doanh nghiệp | C15: 25 | D15: 277125 | E15: =KQKD!G15 -> 209680 | F15: 209680 | G15: =E15*$G$2 -> 230648 | H15: =G15-E15 -> 20968 | I15: =H15/E15 -> 0.1
A16: 10 | B16: Lợi nhuận thuần từ hoạt động kinh doanh | C16: 30 | D16: =D10+D11-D12-D14-D15 -> -35883 | E16: =E10+E11-E12-E14-E15 -> 141951 | F16: =F10+F11-F12-F14-F15 -> 141951 | G16: =E16*$G$2 -> 156146.1 | H16: =G16-E16 -> 14195.1 | I16: =H16/E16 -> 0.1
A17: 11 | B17: Thu nhập khác | C17: 31 | D17: 287151 | E17: =KQKD!G17 -> 65403 | F17: 65403 | G17: =E17*$G$2 -> 71943.3 | H17: =G17-E17 -> 6540.3 | I17: =H17/E17 -> 0.1
A18: 12 | B18: Chi phí khác | C18: 32 | D18: 95472 | E18: =KQKD!G18 -> 45975 | F18: 45975 | G18: =E18*$G$2 -> 50572.5 | H18: =G18-E18 -> 4597.5 | I18: =H18/E18 -> 0.1
A19: 13 | B19: Lợi nhuận khác | C19: 40 | D19: =D17-D18 -> 191679 | E19: =E17-E18 -> 19428 | F19: =F17-F18 -> 19428 | G19: =E19*$G$2 -> 21370.8 | H19: =G19-E19 -> 1942.8 | I19: =H19/E19 -> 0.1
A20: 14 | B20: Tổng lợi nhuận kế toán trước thuế | C20: 50 | D20: =D16+D19 -> 155796 | E20: =E16+E19 -> 161379 | F20: =F16+F19 -> 161379 | G20: =E20*$G$2 -> 177516.9 | H20: =G20-E20 -> 16137.9 | I20: =H20/E20 -> 0.1
A21: 15 | B21: Chi phí thuế TNDN | C21: 51 | D21: 19764 | E21: =KQKD!G21 -> 4856 | F21: 4856 | G21: =E21*$G$2 -> 5341.6 | H21: =G21-E21 -> 485.6 | I21: =H21/E21 -> 0.1
A22: 16 | B22: Lợi nhuận sau thuế thu nhập doanh nghiệp | C22: 60 | D22: =D20-D21 -> 136032 | E22: =E20-E21 -> 156523 | F22: =F20-F21 -> 156523 | G22: =E22*$G$2 -> 172175.3 | H22: =G22-E22 -> 15652.3 | I22: =H22/E22 -> 0.1

Sheet PTTC
A2: CÁC CHỈ TIÊU TÀI CHÍNH
A4: STT | B4: Chỉ tiêu | C4: Cách tính | D4: Năm 2014 | F4: Năm 2015
D5: Đầu kỳ | E5: Cuối kỳ | F5: Đầu kỳ | G5: Cuối kỳ
A6: I | B6: KHẢ NĂNG THANH TOÁN
A7: 1 | B7: Khả năng thanh toán tổng quát - Ktq | C7: 270/300 | D7: =CĐKT!D69/CĐKT!D71 -> 1.6455748 | E7: =CĐKT!E69/CĐKT!E71 -> 1.6455748 | F7: =CĐKT!F69/CĐKT!F71 -> 2.0291778 | G7: =CĐKT!G69/CĐKT!G71 -> 2.0291778
A8: 2 | B8: Khả năng thanh toán ngắn hạn - Kng | C8: 100/310 | D8: =CĐKT!D7/CĐKT!D72 -> 1.1185728 | E8: =CĐKT!E7/CĐKT!E72 -> 1.1185728 | F8: =CĐKT!F7/CĐKT!F72 -> 1.2852665 | G8: =CĐKT!G7/CĐKT!G72 -> 1.2852665
A9: 3 | B9: Khả năng thanh toán nhanh - Knh | C9: (110+120)/310 | D9: =(CĐKT!D8+CĐKT!D11)/CĐKT!D72 -> 0.38389488 | E9: =(CĐKT!E8+CĐKT!E11)/CĐKT!E72 -> 0.38389488 | F9: =(CĐKT!F8+CĐKT!F11)/CĐKT!F72 -> 0.12338875 | G9: =(CĐKT!G8+CĐKT!G11)/CĐKT!G72 -> 0.12338875
A10: 4 | B10: Khả năng thanh toán dài hạn - Kdn | C10: (200/330) | D10: =CĐKT!D33/CĐKT!D87 -> 5.5325237 | E10: =CĐKT!E33/CĐKT!E87 -> 5.5325237 | F10: =CĐKT!F33/CĐKT!F87 -> 5.5684776 | G10: =CĐKT!G33/CĐKT!G87 -> 5.5684776
A11: 5 | B11: Khả năng thanh toán dài hạn đến hạn - Kdhđn | C11: (200/338*10%) | D11: =CĐKT!D33/CĐKT!D95/10 -> 2.962498 | E11: =CĐKT!E33/CĐKT!E95/10 -> 2.962498 | F11: =CĐKT!F33/CĐKT!F95/10 -> 4.1669368 | G11: =CĐKT!G33/CĐKT!G95/10 -> 4.1669368
A12: 6 | B12: Khả năng thanh toán lãi vay - Klv | C12: (60/23) | D12: ='KQKD-Word'!D22/'KQKD-Word'!D13 -> 0.58357536 | E12: ='KQKD-Word'!E22/'KQKD-Word'!E13 -> 0.58357536 | F12: ='KQKD-Word'!F22/'KQKD-Word'!F13 -> 1.1421202 | G12: ='KQKD-Word'!G22/'KQKD-Word'!G13 -> 1.1421202
A13: II | B13: CƠ CẤU VỐN, TÍNH ỔN ĐỊNH VÀ KHẢ NĂNG TRẢ NỢ
A14: 1 | B14: Hệ số nợ so với nguồn vốn chủ sở hữu - Ncsh | C14: 300/400 | D14: =CĐKT!D71/CĐKT!D101*100 -> 154.90076 | E14: =CĐKT!E71/CĐKT!E101*100 -> 154.90076 | F14: =CĐKT!F71/CĐKT!F101*100 -> 97.16501 | G14: =CĐKT!G71/CĐKT!G101*100 -> 97.16501
A15: 2 | B15: Hệ số nợ so với tài sản - Ntts | C15: 300/270 | D15: =CĐKT!D71/CĐKT!D69*100 -> 60.769039 | E15: =CĐKT!E71/CĐKT!E69*100 -> 60.769039 | F15: =CĐKT!F71/CĐKT!F69*100 -> 49.281043 | G15: =CĐKT!G71/CĐKT!G69*100 -> 49.281043
A16: 3 | B16: Tỷ lệ nợ quá hạn trong tổng dư nợ vay - Nqh
A17: 4 | B17: Hệ số thích ứng dài hạn của tài sản - Ktu | C17: 200/(400+330) | D17: =CĐKT!D33/(CĐKT!D101+CĐKT!D87) -> 0.86350349 | E17: =CĐKT!E33/(CĐKT!E101+CĐKT!E87) -> 0.86350349 | F17: =CĐKT!F33/(CĐKT!F101+CĐKT!F87) -> 0.80403304 | G17: =CĐKT!G33/(CĐKT!G101+CĐKT!G87) -> 0.80403304
A18: 5 | B18: Hệ số tài sản dài hạn trên vốn chủ sở hữu - Kts | C18: 200/400 | D18: =CĐKT!D33/CĐKT!D101 -> 1.0232026 | E18: =CĐKT!E33/CĐKT!E101 -> 1.0232026 | F18: =CĐKT!F33/CĐKT!F101 -> 0.93971918 | G18: =CĐKT!G33/CĐKT!G101 -> 0.93971918
A19: 6 | B19: Hệ số nguồn vốn chủ sở hữu trên Tổng tài sản - Httt | C19: 400/270 | D19: =CĐKT!D101/CĐKT!D69*100 -> 39.23095 | E19: =CĐKT!E101/CĐKT!E69*100 -> 39.23095 | F19: =CĐKT!F101/CĐKT!F69*100 -> 50.718919 | G19: =CĐKT!G101/CĐKT!G69*100 -> 50.718919
A20: III | B20: HIỆU QUẢ SỬ DỤNG VỐN VÀ SINH LỜI
A21: 1 | B21: Hiệu quả sử dụng tài sản - L | C21: (10+21+31)/270bq | D21: =2*('KQKD-Word'!D8+'KQKD-Word'!D11+'KQKD-Word'!D17)/(CĐKT!D69+CĐKT!E69) -> 1.6543107 | E21: =2*('KQKD-Word'!E8+'KQKD-Word'!E11+'KQKD-Word'!E17)/(CĐKT!D69+CĐKT!E69) -> 1.6543107 | F21: =2*('KQKD-Word'!F8+'KQKD-Word'!F11+'KQKD-Word'!F17)/(CĐKT!F69+CĐKT!G69) -> 1.2820671 | G21: =2*('KQKD-Word'!G8+'KQKD-Word'!G11+'KQKD-Word'!G17)/(CĐKT!F69+CĐKT!G69) -> 1.2820671
A22: 2 | B22: Vòng quay hàng tồn kho - V | C22: 11/(140bq) | D22: =2*'KQKD-Word'!D9/(CĐKT!D24+CĐKT!E24) -> 5.873805 | E22: =2*'KQKD-Word'!E9/(CĐKT!D24+CĐKT!E24) -> 5.873805 | F22: =2*'KQKD-Word'!F9/(CĐKT!F24+CĐKT!G24) -> 3.2061628 | G22: =2*'KQKD-Word'!G9/(CĐKT!F24+CĐKT!G24) -> 3.2061628
A23: 3 | B23: Kỳ thu tiền bình quân - Nth | C23: 360*(130bq)/(10+21+31) | D23: =360*(CĐKT!D15+CĐKT!E15)/2/('KQKD-Word'!D8+'KQKD-Word'!D11+'KQKD-Word'!D17) -> 31.480615 | E23: =360*(CĐKT!D15+CĐKT!E15)/2/('KQKD-Word'!E8+'KQKD-Word'!E11+'KQKD-Word'!E17) -> 31.480615 | F23: =360*(CĐKT!F15+CĐKT!G15)/2/('KQKD-Word'!F8+'KQKD-Word'!F11+'KQKD-Word'!F17) -> 33.41808 | G23: =360*(CĐKT!F15+CĐKT!G15)/2/('KQKD-Word'!G8+'KQKD-Word'!G11+'KQKD-Word'!G17) -> 33.41808
A24: 4 | B24: Vòng quay tài sản ngắn hạn - Vvlđ | C24: (10/100bq) | D24: =2*'KQKD-Word'!D8/(CĐKT!D7+CĐKT!E7) -> 2.6778907 | E24: =2*'KQKD-Word'!E8/(CĐKT!D7+CĐKT!E7) -> 2.6778907 | F24: =2*'KQKD-Word'!F8/(CĐKT!E7+CĐKT!G7) -> 1.99588 | G24: =2*'KQKD-Word'!F8/(CĐKT!E7+CĐKT!G7) -> 1.99588
A25: 5 | B25: Vòng quay các khoản phải thu - Vkpt | C25: (10/130bq) | D25: =2*'KQKD-Word'!D8/(CĐKT!D15+CĐKT!E15) -> 11.080592 | E25: =2*'KQKD-Word'!E8/(CĐKT!D15+CĐKT!E15) -> 11.080592 | F25: =2*'KQKD-Word'!F8/(CĐKT!F15+CĐKT!G15) -> 10.603968 | G25: =2*'KQKD-Word'!G8/(CĐKT!F15+CĐKT!G15) -> 10.603968
A26: 6 | B26: Vòng quay khoản phải trả - Vkptr | C26: (11/331bq) | D26: =2*'KQKD-Word'!D9/(CĐKT!D73+CĐKT!E73) -> 24.939601 | E26: =2*'KQKD-Word'!E9/(CĐKT!D73+CĐKT!E73) -> 24.939601 | F26: =2*'KQKD-Word'!F9/(CĐKT!F73+CĐKT!G73) -> 96.50643 | G26: =2*'KQKD-Word'!G9/(CĐKT!F73+CĐKT!G73) -> 96.50643
A27: 7 | B27: Số ngày phải hoàn trả nợ - Ntr | C27: (12tháng x 331bq/11) | D27: =12/2*(CĐKT!D73+CĐKT!E73)/'KQKD-Word'!D9 -> 0.48116247 | E27: =12/2*(CĐKT!D73+CĐKT!E73)/'KQKD-Word'!E9 -> 0.48116247 | F27: =12/2*(CĐKT!F73+CĐKT!G73)/'KQKD-Word'!F9 -> 0.12434405 | G27: =12/2*(CĐKT!F73+CĐKT!G73)/'KQKD-Word'!G9 -> 0.12434405
A28: 8 | B28: Tỷ suất lợi nhuận trước thuế trên doanh thu - LNdt | C28: 50/(10+21+31) | D28: ='KQKD-Word'!D20/('KQKD-Word'!D8+'KQKD-Word'!D11+'KQKD-Word'!D17)*100 -> 0.96448469 | E28: ='KQKD-Word'!E20/('KQKD-Word'!E8+'KQKD-Word'!E11+'KQKD-Word'!E17)*100 -> 0.96448469 | F28: ='KQKD-Word'!F20/('KQKD-Word'!F8+'KQKD-Word'!F11+'KQKD-Word'!F17)*100 -> 1.5962826 | G28: ='KQKD-Word'!G20/('KQKD-Word'!G8+'KQKD-Word'!G11+'KQKD-Word'!G17)*100 -> 1.5962826
A29: 9 | B29: Tỷ suất lợi nhuận trước thuế trên vốn chủ sở hữu - LNvsh | C29: 50/(400bq) | D29: =2*'KQKD-Word'!D20/(CĐKT!D101+CĐKT!E101)*100 -> 4.0670883 | E29: =2*'KQKD-Word'!E20/(CĐKT!D101+CĐKT!E101)*100 -> 4.0670883 | F29: =2*'KQKD-Word'!F20/(CĐKT!F101+CĐKT!G101)*100 -> 4.0350651 | G29: =2*'KQKD-Word'!G20/(CĐKT!F101+CĐKT!G101)*100 -> 4.0350651
A30: 10 | B30: Tỷ suất lợi nhuận sau thuế trên vốn chủ sở hữu (ROE) - LNvsh | C30: 60/(440bq) | D30: =2*'KQKD-Word'!D22/(CĐKT!D101+CĐKT!E101)*100 -> 3.5511448 | E30: =2*'KQKD-Word'!E22/(CĐKT!E101+CĐKT!E101)*100 -> 3.5511448 | F30: =2*'KQKD-Word'!F22/(CĐKT!F101+CĐKT!G101)*100 -> 3.9136474 | G30: =2*'KQKD-Word'!G22/(CĐKT!F101+CĐKT!G101)*100 -> 3.9136474
A31: 11 | B31: Tỷ suất lợi nhuận sau thuế trên tổng Tài sản (ROA) - LNnv | C31: 60/(440bq) | D31: =2*'KQKD-Word'!D22/(CĐKT!D120+CĐKT!E120)*100 -> 1.393148 | E31: =2*'KQKD-Word'!E22/(CĐKT!D120+CĐKT!E120)*100 -> 1.393148 | F31: =2*'KQKD-Word'!F22/(CĐKT!F120+CĐKT!G120)*100 -> 1.9849604 | G31: =2*'KQKD-Word'!G22/(CĐKT!F120+CĐKT!G120)*100 -> 1.9849604
A32: 12 | B32: Tỷ suất sinh lời của tiền vay - Tlntv | C32: (60+23/311+341) | D32: =('KQKD-Word'!D22+'KQKD-Word'!D13)/(CĐKT!D82+CĐKT!D95)*100 -> 8.1126046 | E32: =('KQKD-Word'!E22+'KQKD-Word'!E13)/(CĐKT!E82+CĐKT!E95)*100 -> 8.1126046 | F32: =('KQKD-Word'!F22+'KQKD-Word'!F13)/(CĐKT!F82+CĐKT!F95)*100 -> 10.026223 | G32: =('KQKD-Word'!G22+'KQKD-Word'!G13)/(CĐKT!G82+CĐKT!G95)*100 -> 10.026223
A33: IV | B33: SỨC TĂNG TRƯỞNG
A34: 1 | B34: Sức tăng trưởng doanh thu - TTdt | C34: (10+21+31)/(10+21+31) | D34: 0 | E34: =('KQKD-Word'!E8+'KQKD-Word'!E11+'KQKD-Word'!E17)/('KQKD-Word'!D8+'KQKD-Word'!D11+'KQKD-Word'!D17) -> 1 | F34: 0 | G34: =('KQKD-Word'!G8+'KQKD-Word'!G11+'KQKD-Word'!G17)/('KQKD-Word'!F8+'KQKD-Word'!F11+'KQKD-Word'!F17) -> 1
A35: 2 | B35: Tỷ lệ tăng trưởng doanh thu từ HĐKD chính - TTdtc | C35: (10+21)/(10+21) | D35: 0 | E35: =('KQKD-Word'!E8+'KQKD-Word'!E11)/('KQKD-Word'!D8+'KQKD-Word'!D11) -> 1 | F35: 0 | G35: =('KQKD-Word'!G8+'KQKD-Word'!G11)/('KQKD-Word'!F8+'KQKD-Word'!F11) -> 1
A36: 3 | B36: Tỷ lệ tăng trưởng lợi nhuận - TTln | C36: TTln = 50/50 | D36: 0 | E36: ='KQKD-Word'!E20/'KQKD-Word'!D20 -> 1 | F36: 0 | G36: ='KQKD-Word'!G20/'KQKD-Word'!F20 -> 1
A37: 4 | B37: Tỷ lệ tăng trưởng lợi nhuận từ hoạt động kinh doanh chính -TTln | C37: TTlnt = 30/30 | D37: 0 | E37: ='KQKD-Word'!E16/'KQKD-Word'!D16 -> 1 | F37: 0 | G37: ='KQKD-Word'!G16/'KQKD-Word'!F16 -> 1

Sheet SSKQ
A1: TỔNG HỢP VÀ SO SÁNH KẾT QUẢ | E1: Chọn lĩnh vực | H1: Nông lâm, ngư nghiệp
A3: STT | B3: Chỉ tiêu | C3: Đơn vị | D3: Năm 2015 | G3: Năm 2016 | J3: C.tiêu tham khảo | O3: Lĩnh vực, ngành nghề
D4: Đầu kỳ | E4: Cuối kỳ | F4: Bình Quân | G4: =D4 -> Đầu kỳ | H4: =E4 -> Cuối kỳ | I4: Bình Quân | J4: Min | K4: Max | O4: Nông lâm, ngư nghiệp | Q4: Công nghiệp | S4: Xây dựng | U4: Thương mai, dịch vụ
A5: I | B5: =PTTC!B6 -> KHẢ NĂNG THANH TOÁN
A6: 1 | B6: =PTTC!B7 -> Khả năng thanh toán tổng quát - Ktq | C6: lần | D6: =PTTC!D7 -> 1.6455748 | E6: =PTTC!E7 -> 1.6455748 | F6: =(D6+E6)/2 -> 1.6455748 | G6: =PTTC!F7 -> 2.0291778 | H6: =PTTC!G7 -> 2.0291778 | I6: =(G6+H6)/2 -> 2.0291778 | J6: =IF($H$1=$O$4,O6,IF($H$1=$Q$4,Q6,IF($H$1=$S$4,S6,U6))) -> 1.4 | K6: =IF($H$1=$O$4,P6,IF($H$1=$Q$4,R6,IF($H$1=$S$4,T6,V6))) -> 3.3 | O6: 1.4 | P6: 3.3 | Q6: 1.4 | R6: 2.5 | S6: 1.4 | T6: 2.2 | U6: 1.5 | V6: 4
A7: 2 | B7: =PTTC!B8 -> Khả năng thanh toán ngắn hạn - Kng | C7: lần | D7: =PTTC!D8 -> 1.1185728 | E7: =PTTC!E8 -> 1.1185728 | F7: =(D7+E7)/2 -> 1.1185728 | G7: =PTTC!F8 -> 1.2852665 | H7: =PTTC!G8 -> 1.2852665 | I7: =(G7+H7)/2 -> 1.2852665 | J7: =IF($H$1=$O$4,O7,IF($H$1=$Q$4,Q7,IF($H$1=$S$4,S7,U7))) -> 0.7 | K7: =IF($H$1=$O$4,P7,IF($H$1=$Q$4,R7,IF($H$1=$S$4,T7,V7))) -> 2.5 | O7: 0.7 | P7: 2.5 | Q7: 0.5 | R7: 2.5 | S7: 0.5 | T7: 2.3 | U7: 0.8 | V7: 2.9
A8: 3 | B8: =PTTC!B9 -> Khả năng thanh toán nhanh - Knh | C8: lần | D8: =PTTC!D9 -> 0.38389488 | E8: =PTTC!E9 -> 0.38389488 | F8: =(D8+E8)/2 -> 0.38389488 | G8: =PTTC!F9 -> 0.12338875 | H8: =PTTC!G9 -> 0.12338875 | I8: =(G8+H8)/2 -> 0.12338875 | J8: =IF($H$1=$O$4,O8,IF($H$1=$Q$4,Q8,IF($H$1=$S$4,S8,U8))) -> 0.2 | K8: =IF($H$1=$O$4,P8,IF($H$1=$Q$4,R8,IF($H$1=$S$4,T8,V8))) -> 1.5 | O8: 0.2 | P8: 1.5 | Q8: 0.2 | R8: 1.3 | S8: 0.1 | T8: 1.2 | U8: 0.4 | V8: 2.2
A9: 4 | B9: =PTTC!B10 -> Khả năng thanh toán dài hạn - Kdn | C9: lần | D9: =PTTC!D10 -> 5.5325237 | E9: =PTTC!E10 -> 5.5325237 | F9: =(D9+E9)/2 -> 5.5325237 | G9: =PTTC!F10 -> 5.5684776 | H9: =PTTC!G10 -> 5.5684776 | I9: =(G9+H9)/2 -> 5.5684776 | J9: =IF($H$1=$O$4,O9,IF($H$1=$Q$4,Q9,IF($H$1=$S$4,S9,U9))) -> 1 | K9: =IF($H$1=$O$4,P9,IF($H$1=$Q$4,R9,IF($H$1=$S$4,T9,V9))) -> 1.4 | O9: 1 | P9: 1.4 | Q9: 1 | R9: 1.4 | S9: 1 | T9: 1.4 | U9: 1 | V9: 1.5
A10: 5 | B10: =PTTC!B11 -> Khả năng thanh toán dài hạn đến hạn - Kdhđn | C10: lần | D10: =PTTC!D11 -> 2.962498 | E10: =PTTC!E11 -> 2.962498 | F10: =(D10+E10)/2 -> 2.962498 | G10: =PTTC!F11 -> 4.1669368 | H10: =PTTC!G11 -> 4.1669368 | I10: =(G10+H10)/2 -> 4.1669368
A11: 6 | B11: =PTTC!B12 -> Khả năng thanh toán lãi vay - Klv | C11: lần | D11: =PTTC!D12 -> 0.58357536 | E11: =PTTC!E12 -> 0.58357536 | F11: =(D11+E11)/2 -> 0.58357536 | G11: =PTTC!F12 -> 1.1421202 | H11: =PTTC!G12 -> 1.1421202 | I11: =(G11+H11)/2 -> 1.1421202
A12: II | B12: =PTTC!B13 -> CƠ CẤU VỐN, TÍNH ỔN ĐỊNH VÀ KHẢ NĂNG TRẢ NỢ | D12: =PTTC!D13 -> 0 | E12: =PTTC!E13 -> 0 | F12: =(D12+E12)/2 -> 0 | G12: =PTTC!F13 -> 0 | H12: =PTTC!G13 -> 0 | I12: =(G12+H12)/2 -> 0 | J12: =IF($H$1=$O$4,O12,IF($H$1=$Q$4,Q12,IF($H$1=$S$4,S12,U12))) -> 0 | K12: =IF($H$1=$O$4,P12,IF($H$1=$Q$4,R12,IF($H$1=$S$4,T12,V12))) -> 0
A13: 1 | B13: =PTTC!B14 -> Hệ số nợ so với nguồn vốn chủ sở hữu - Ncsh | C13: % | D13: =PTTC!D14 -> 154.90076 | E13: =PTTC!E14 -> 154.90076 | F13: =(D13+E13)/2 -> 154.90076 | G13: =PTTC!F14 -> 97.16501 | H13: =PTTC!G14 -> 97.16501 | I13: =(G13+H13)/2 -> 97.16501 | J13: =IF($H$1=$O$4,O13,IF($H$1=$Q$4,Q13,IF($H$1=$S$4,S13,U13))) -> 42 | K13: =IF($H$1=$O$4,P13,IF($H$1=$Q$4,R13,IF($H$1=$S$4,T13,V13))) -> 233 | O13: 42 | P13: 233 | Q13: 82 | R13: 233 | S13: 66 | T13: 233 | U13: 33 | V13: 185
A14: 2 | B14: =PTTC!B15 -> Hệ số nợ so với tài sản - Ntts | C14: % | D14: =PTTC!D15 -> 60.769039 | E14: =PTTC!E15 -> 60.769039 | F14: =(D14+E14)/2 -> 60.769039 | G14: =PTTC!F15 -> 49.281043 | H14: =PTTC!G15 -> 49.281043 | I14: =(G14+H14)/2 -> 49.281043 | J14: =IF($H$1=$O$4,O14,IF($H$1=$Q$4,Q14,IF($H$1=$S$4,S14,U14))) -> 0 | K14: =IF($H$1=$O$4,P14,IF($H$1=$Q$4,R14,IF($H$1=$S$4,T14,V14))) -> 3 | O14: 0 | P14: 3 | Q14: 0 | R14: 3 | S14: 0 | T14: 3 | U14: 0 | V14: 3
A15: 3 | B15: =PTTC!B16 -> Tỷ lệ nợ quá hạn trong tổng dư nợ vay - Nqh | C15: % | D15: =PTTC!D16 -> 0 | E15: =PTTC!E16 -> 0 | F15: =(D15+E15)/2 -> 0 | G15: =PTTC!F16 -> 0 | H15: =PTTC!G16 -> 0 | I15: =(G15+H15)/2 -> 0 | J15: =IF($H$1=$O$4,O15,IF($H$1=$Q$4,Q15,IF($H$1=$S$4,S15,U15))) -> 0 | K15: =IF($H$1=$O$4,P15,IF($H$1=$Q$4,R15,IF($H$1=$S$4,T15,V15))) -> 0
A16: 4 | B16: =PTTC!B17 -> Hệ số thích ứng dài hạn của tài sản - Ktu | C16: lần | D16: =PTTC!D17 -> 0.86350349 | E16: =PTTC!E17 -> 0.86350349 | F16: =(D16+E16)/2 -> 0.86350349 | G16: =PTTC!F17 -> 0.80403304 | H16: =PTTC!G17 -> 0.80403304 | I16: =(G16+H16)/2 -> 0.80403304 | J16: =IF($H$1=$O$4,O16,IF($H$1=$Q$4,Q16,IF($H$1=$S$4,S16,U16))) -> 0 | K16: =IF($H$1=$O$4,P16,IF($H$1=$Q$4,R16,IF($H$1=$S$4,T16,V16))) -> 0
A17: 5 | B17: =PTTC!B18 -> Hệ số tài sản dài hạn trên vốn chủ sở hữu - Kts | C17: lần | D17: =PTTC!D18 -> 1.0232026 | E17: =PTTC!E18 -> 1.0232026 | F17: =(D17+E17)/2 -> 1.0232026 | G17: =PTTC!F18 -> 0.93971918 | H17: =PTTC!G18 -> 0.93971918 | I17: =(G17+H17)/2 -> 0.93971918 | J17: =IF($H$1=$O$4,O17,IF($H$1=$Q$4,Q17,IF($H$1=$S$4,S17,U17))) -> 0 | K17: =IF($H$1=$O$4,P17,IF($H$1=$Q$4,R17,IF($H$1=$S$4,T17,V17))) -> 0
A18: 6 | B18: =PTTC!B19 -> Hệ số nguồn vốn chủ sở hữu trên Tổng tài sản - Httt | C18: % | D18: =PTTC!D19 -> 39.23095 | E18: =PTTC!E19 -> 39.23095 | F18: =(D18+E18)/2 -> 39.23095 | G18: =PTTC!F19 -> 50.718919 | H18: =PTTC!G19 -> 50.718919 | I18: =(G18+H18)/2 -> 50.718919
A19: III | B19: =PTTC!B20 -> HIỆU QUẢ SỬ DỤNG VỐN VÀ SINH LỜI | D19: =PTTC!D20 -> 0 | E19: =PTTC!E20 -> 0 | F19: =(D19+E19)/2 -> 0 | G19: =PTTC!F20 -> 0 | H19: =PTTC!G20 -> 0 | I19: =(G19+H19)/2 -> 0 | J19: =IF($H$1=$O$4,O19,IF($H$1=$Q$4,Q19,IF($H$1=$S$4,S19,U19))) -> 0 | K19: =IF($H$1=$O$4,P19,IF($H$1=$Q$4,R19,IF($H$1=$S$4,T19,V19))) -> 0
A20: 1 | B20: =PTTC!B21 -> Hiệu quả sử dụng tài sản - L | C20: % | D20: =PTTC!D21 -> 1.6543107 | E20: =PTTC!E21 -> 1.6543107 | F20: =(D20+E20)/2 -> 1.6543107 | G20: =PTTC!F21 -> 1.2820671 | H20: =PTTC!G21 -> 1.2820671 | I20: =(G20+H20)/2 -> 1.2820671 | J20: =IF($H$1=$O$4,O20,IF($H$1=$Q$4,Q20,IF($H$1=$S$4,S20,U20))) -> 1.7 | K20: =IF($H$1=$O$4,P20,IF($H$1=$Q$4,R20,IF($H$1=$S$4,T20,V20))) -> 5.5 | O20: 1.7 | P20: 5.5 | Q20: 1.7 | R20: 4.2 | S20: 1.7 | T20: 5 | U20: 1.5 | V20: 4
A21: 2 | B21: =PTTC!B22 -> Vòng quay hàng tồn kho - V | C21: vòng | D21: =PTTC!D22 -> 5.873805 | E21: =PTTC!E22 -> 5.873805 | F21: =(D21+E21)/2 -> 5.873805 | G21: =PTTC!F22 -> 3.2061628 | H21: =PTTC!G22 -> 3.2061628 | I21: =(G21+H21)/2 -> 3.2061628 | J21: =IF($H$1=$O$4,O21,IF($H$1=$Q$4,Q21,IF($H$1=$S$4,S21,U21))) -> 2 | K21: =IF($H$1=$O$4,P21,IF($H$1=$Q$4,R21,IF($H$1=$S$4,T21,V21))) -> 4.5 | O21: 2 | P21: 4.5 | Q21: 2.5 | R21: 6 | S21: 2 | T21: 4 | U21: 3.5 | V21: 7
A22: 3 | B22: =PTTC!B23 -> Kỳ thu tiền bình quân - Nth | C22: ngày | D22: =PTTC!D23 -> 31.480615 | E22: =PTTC!E23 -> 31.480615 | F22: =(D22+E22)/2 -> 31.480615 | G22: =PTTC!F23 -> 33.41808 | H22: =PTTC!G23 -> 33.41808 | I22: =(G22+H22)/2 -> 33.41808 | J22: =IF($H$1=$O$4,O22,IF($H$1=$Q$4,Q22,IF($H$1=$S$4,S22,U22))) -> 34 | K22: =IF($H$1=$O$4,P22,IF($H$1=$Q$4,R22,IF($H$1=$S$4,T22,V22))) -> 70 | O22: 34 | P22: 70 | Q22: 30 | R22: 65 | S22: 40 | T22: 150 | U22: 32 | V22: 60
A23: 4 | B23: =PTTC!B24 -> Vòng quay tài sản ngắn hạn - Vvlđ | C23: vòng | D23: =PTTC!D24 -> 2.6778907 | E23: =PTTC!E24 -> 2.6778907 | F23: =(D23+E23)/2 -> 2.6778907 | G23: =PTTC!F24 -> 1.99588 | H23: =PTTC!G24 -> 1.99588 | I23: =(G23+H23)/2 -> 1.99588
A24: 5 | B24: =PTTC!B25 -> Vòng quay các khoản phải thu - Vkpt | C24: vòng | D24: =PTTC!D25 -> 11.080592 | E24: =PTTC!E25 -> 11.080592 | F24: =(D24+E24)/2 -> 11.080592 | G24: =PTTC!F25 -> 10.603968 | H24: =PTTC!G25 -> 10.603968 | I24: =(G24+H24)/2 -> 10.603968
A25: 6 | B25: =PTTC!B26 -> Vòng quay khoản phải trả - Vkptr | C25: vòng | D25: =PTTC!D26 -> 24.939601 | E25: =PTTC!E26 -> 24.939601 | F25: =(D25+E25)/2 -> 24.939601 | G25: =PTTC!F26 -> 96.50643 | H25: =PTTC!G26 -> 96.50643 | I25: =(G25+H25)/2 -> 96.50643
A26: 7 | B26: =PTTC!B27 -> Số ngày phải hoàn trả nợ - Ntr | C26: ngày | D26: =PTTC!D27 -> 0.48116247 | E26: =PTTC!E27 -> 0.48116247 | F26: =(D26+E26)/2 -> 0.48116247 | G26: =PTTC!G27 -> 0.12434405 | H26: =PTTC!G27 -> 0.12434405 | I26: =(G26+H26)/2 -> 0.12434405
A27: 8 | B27: =PTTC!B28 -> Tỷ suất lợi nhuận trước thuế trên doanh thu - LNdt | C27: % | D27: =PTTC!D28 -> 0.96448469 | E27: =PTTC!E28 -> 0.96448469 | F27: =(D27+E27)/2 -> 0.96448469 | G27: =PTTC!F28 -> 1.5962826 | H27: =PTTC!G28 -> 1.5962826 | I27: =(G27+H27)/2 -> 1.5962826 | J27: =IF($H$1=$O$4,O27,IF($H$1=$Q$4,Q27,IF($H$1=$S$4,S27,U27))) -> 1.5 | K27: =IF($H$1=$O$4,P27,IF($H$1=$Q$4,R27,IF($H$1=$S$4,T27,V27))) -> 5 | O27: 1.5 | P27: 5 | Q27: 3 | R27: 6.5 | S27: 5 | T27: 10 | U27: 5.5 | V27: 8
A28: 9 | B28: =PTTC!B29 -> Tỷ suất lợi nhuận trước thuế trên vốn chủ sở hữu - LNvsh | C28: % | D28: =PTTC!D29 -> 4.0670883 | E28: =PTTC!E29 -> 4.0670883 | F28: =(D28+E28)/2 -> 4.0670883 | G28: =PTTC!F29 -> 4.0350651 | H28: =PTTC!G29 -> 4.0350651 | I28: =(G28+H28)/2 -> 4.0350651 | J28: =IF($H$1=$O$4,O28,IF($H$1=$Q$4,Q28,IF($H$1=$S$4,S28,U28))) -> 7 | K28: =IF($H$1=$O$4,P28,IF($H$1=$Q$4,R28,IF($H$1=$S$4,T28,V28))) -> 10 | O28: 7 | P28: 10 | Q28: 12.2 | R28: 14.2 | S28: 8.3 | T28: 11.5 | U28: 9.6 | V28: 14.2
A29: 10 | B29: =PTTC!B30 -> Tỷ suất lợi nhuận sau thuế trên vốn chủ sở hữu (ROE) - LNvsh | C29: % | D29: =PTTC!D30 -> 3.5511448 | E29: =PTTC!E30 -> 3.5511448 | F29: =(D29+E29)/2 -> 3.5511448 | G29: =PTTC!F30 -> 3.9136474 | H29: =PTTC!G30 -> 3.9136474 | I29: =(G29+H29)/2 -> 3.9136474
A30: 11 | B30: =PTTC!B31 -> Tỷ suất lợi nhuận sau thuế trên tổng Tài sản (ROA) - LNnv | C30: % | D30: =PTTC!D31 -> 1.393148 | E30: =PTTC!E31 -> 1.393148 | F30: =(D30+E30)/2 -> 1.393148 | G30: =PTTC!F31 -> 1.9849604 | H30: =PTTC!G31 -> 1.9849604 | I30: =(G30+H30)/2 -> 1.9849604 | J30: =IF($H$1=$O$4,O30,IF($H$1=$Q$4,Q30,IF($H$1=$S$4,S30,U30))) -> 3 | K30: =IF($H$1=$O$4,P30,IF($H$1=$Q$4,R30,IF($H$1=$S$4,T30,V30))) -> 6 | O30: 3 | P30: 6 | Q30: 4 | R30: 7 | S30: 2.5 | T30: 7.5 | U30: 5 | V30: 7.5
A31: 12 | B31: =PTTC!B32 -> Tỷ suất sinh lời của tiền vay - Tlntv | C31: % | D31: =PTTC!D32 -> 8.1126046 | E31: =PTTC!E32 -> 8.1126046 | F31: =(D31+E31)/2 -> 8.1126046 | G31: =PTTC!F32 -> 10.026223 | H31: =PTTC!G32 -> 10.026223 | I31: =(G31+H31)/2 -> 10.026223
A32: IV | B32: =PTTC!B33 -> SỨC TĂNG TRƯỞNG | D32: =PTTC!D33 -> 0 | E32: =PTTC!E33 -> 0 | F32: =(D32+E32)/2 -> 0 | G32: =PTTC!F33 -> 0 | H32: =PTTC!G33 -> 0 | I32: =(G32+H32)/2 -> 0 | J32: =IF($H$1=$O$4,O32,IF($H$1=$Q$4,Q32,IF($H$1=$S$4,S32,U32))) -> 0 | K32: =IF($H$1=$O$4,P32,IF($H$1=$Q$4,R32,IF($H$1=$S$4,T32,V32))) -> 0
A33: 1 | B33: =PTTC!B34 -> Sức tăng trưởng doanh thu - TTdt | D33: =PTTC!D34 -> 0 | E33: =PTTC!E34 -> 1 | F33: =(D33+E33)/2 -> 0.5 | G33: =PTTC!F34 -> 0 | H33: =PTTC!G34 -> 1 | I33: =(G33+H33)/2 -> 0.5 | J33: =IF($H$1=$O$4,O33,IF($H$1=$Q$4,Q33,IF($H$1=$S$4,S33,U33))) -> 0 | K33: =IF($H$1=$O$4,P33,IF($H$1=$Q$4,R33,IF($H$1=$S$4,T33,V33))) -> 0
A34: 2 | B34: =PTTC!B35 -> Tỷ lệ tăng trưởng doanh thu từ HĐKD chính - TTdtc | D34: =PTTC!D35 -> 0 | E34: =PTTC!E35 -> 1 | F34: =(D34+E34)/2 -> 0.5 | G34: =PTTC!F35 -> 0 | H34: =PTTC!G35 -> 1 | I34: =(G34+H34)/2 -> 0.5 | J34: =IF($H$1=$O$4,O34,IF($H$1=$Q$4,Q34,IF($H$1=$S$4,S34,U34))) -> 0 | K34: =IF($H$1=$O$4,P34,IF($H$1=$Q$4,R34,IF($H$1=$S$4,T34,V34))) -> 0
A35: 3 | B35: =PTTC!B36 -> Tỷ lệ tăng trưởng lợi nhuận - TTln | D35: =PTTC!D36 -> 0 | E35: =PTTC!E36 -> 1 | F35: =(D35+E35)/2 -> 0.5 | G35: =PTTC!F36 -> 0 | H35: =PTTC!G36 -> 1 | I35: =(G35+H35)/2 -> 0.5 | J35: =IF($H$1=$O$4,O35,IF($H$1=$Q$4,Q35,IF($H$1=$S$4,S35,U35))) -> 0 | K35: =IF($H$1=$O$4,P35,IF($H$1=$Q$4,R35,IF($H$1=$S$4,T35,V35))) -> 0
A36: 4 | B36: =PTTC!B37 -> Tỷ lệ tăng trưởng lợi nhuận từ hoạt động kinh doanh chính -TTln | D36: =PTTC!D37 -> 0 | E36: =PTTC!E37 -> 1 | F36: =(D36+E36)/2 -> 0.5 | G36: =PTTC!F37 -> 0 | H36: =PTTC!G37 -> 1 | I36: =(G36+H36)/2 -> 0.5 | J36: =IF($H$1=$O$4,O36,IF($H$1=$Q$4,Q36,IF($H$1=$S$4,S36,U36))) -> 0 | K36: =IF($H$1=$O$4,P36,IF($H$1=$Q$4,R36,IF($H$1=$S$4,T36,V36))) -> 0

Sheet SSKQ-Word
A1: TỔNG HỢP VÀ SO SÁNH KẾT QUẢ | G1: Chọn lĩnh vực | K1: Thương mai, dịch vụ
A3: STT | B3: Chỉ tiêu | C3: Đơn vị | D3: Năm 2015 | G3: Năm 2016 | J3: So sánh +/- | K3: C.tiêu tham khảo | Q3: Lĩnh vực, ngành nghề
K4: Min | L4: Max | Q4: Nông lâm, ngư nghiệp | S4: Công nghiệp | U4: Xây dựng | W4: Thương mai, dịch vụ
A5: I | B5: =PTTC!B6 -> KHẢ NĂNG THANH TOÁN
A6: 1 | B6: =PTTC!B7 -> Khả năng thanh toán tổng quát - Ktq | C6: lần | D6: =PTTC!D7 -> 1.6455748 | E6: =PTTC!E7 -> 1.6455748 | F6: =(D6+E6)/2 -> 1.6455748 | G6: =PTTC!F7 -> 2.0291778 | H6: =PTTC!G7 -> 2.0291778 | I6: =(G6+H6)/2 -> 2.0291778 | J6: =I6-F6 -> 0.38360304 | K6: =IF($K$1=$Q$4,Q6,IF($K$1=$S$4,S6,IF($K$1=$U$4,U6,W6))) -> 1.5 | L6: =IF($K$1=$Q$4,R6,IF($K$1=$S$4,T6,IF($K$1=$U$4,V6,X6))) -> 4 | Q6: 1.4 | R6: 3.3 | S6: 1.4 | T6: 2.5 | U6: 1.4 | V6: 2.2 | W6: 1.5 | X6: 4
A7: 2 | B7: =PTTC!B8 -> Khả năng thanh toán ngắn hạn - Kng | C7: lần | D7: =PTTC!D8 -> 1.1185728 | E7: =PTTC!E8 -> 1.1185728 | F7: =(D7+E7)/2 -> 1.1185728 | G7: =PTTC!F8 -> 1.2852665 | H7: =PTTC!G8 -> 1.2852665 | I7: =(G7+H7)/2 -> 1.2852665 | J7: =I7-F7 -> 0.16669371 | K7: =IF($K$1=$Q$4,Q7,IF($K$1=$S$4,S7,IF($K$1=$U$4,U7,W7))) -> 0.8 | L7: =IF($K$1=$Q$4,R7,IF($K$1=$S$4,T7,IF($K$1=$U$4,V7,X7))) -> 2.9 | Q7: 0.7 | R7: 2.5 | S7: 0.5 | T7: 2.5 | U7: 0.5 | V7: 2.3 | W7: 0.8 | X7: 2.9
A8: 3 | B8: =PTTC!B9 -> Khả năng thanh toán nhanh - Knh | C8: lần | D8: =PTTC!D9 -> 0.38389488 | E8: =PTTC!E9 -> 0.38389488 | F8: =(D8+E8)/2 -> 0.38389488 | G8: =PTTC!F9 -> 0.12338875 | H8: =PTTC!G9 -> 0.12338875 | I8: =(G8+H8)/2 -> 0.12338875 | J8: =I8-F8 -> -0.26050612 | K8: =IF($K$1=$Q$4,Q8,IF($K$1=$S$4,S8,IF($K$1=$U$4,U8,W8))) -> 0.4 | L8: =IF($K$1=$Q$4,R8,IF($K$1=$S$4,T8,IF($K$1=$U$4,V8,X8))) -> 2.2 | Q8: 0.2 | R8: 1.5 | S8: 0.2 | T8: 1.3 | U8: 0.1 | V8: 1.2 | W8: 0.4 | X8: 2.2
A9: 4 | B9: =PTTC!B10 -> Khả năng thanh toán dài hạn - Kdn | C9: lần | D9: =PTTC!D10 -> 5.5325237 | E9: =PTTC!E10 -> 5.5325237 | F9: =(D9+E9)/2 -> 5.5325237 | G9: =PTTC!F10 -> 5.5684776 | H9: =PTTC!G10 -> 5.5684776 | I9: =(G9+H9)/2 -> 5.5684776 | J9: =I9-F9 -> 0.035953891 | K9: =IF($K$1=$Q$4,Q9,IF($K$1=$S$4,S9,IF($K$1=$U$4,U9,W9))) -> 1 | L9: =IF($K$1=$Q$4,R9,IF($K$1=$S$4,T9,IF($K$1=$U$4,V9,X9))) -> 1.5 | Q9: 1 | R9: 1.4 | S9: 1 | T9: 1.4 | U9: 1 | V9: 1.4 | W9: 1 | X9: 1.5
A10: 5 | B10: =PTTC!B11 -> Khả năng thanh toán dài hạn đến hạn - Kdhđn | C10: lần | D10: =PTTC!D11 -> 2.962498 | E10: =PTTC!E11 -> 2.962498 | F10: =(D10+E10)/2 -> 2.962498 | G10: =PTTC!F11 -> 4.1669368 | H10: =PTTC!G11 -> 4.1669368 | I10: =(G10+H10)/2 -> 4.1669368 | J10: =I10-F10 -> 1.2044388
A11: 6 | B11: =PTTC!B12 -> Khả năng thanh toán lãi vay - Klv | C11: lần | D11: =PTTC!D12 -> 0.58357536 | E11: =PTTC!E12 -> 0.58357536 | F11: =(D11+E11)/2 -> 0.58357536 | G11: =PTTC!F12 -> 1.1421202 | H11: =PTTC!G12 -> 1.1421202 | I11: =(G11+H11)/2 -> 1.1421202 | J11: =I11-F11 -> 0.5585448
A12: II | B12: =PTTC!B13 -> CƠ CẤU VỐN, TÍNH ỔN ĐỊNH VÀ KHẢ NĂNG TRẢ NỢ
A13: 1 | B13: =PTTC!B14 -> Hệ số nợ so với nguồn vốn chủ sở hữu - Ncsh | C13: % | D13: =PTTC!D14 -> 154.90076 | E13: =PTTC!E14 -> 154.90076 | F13: =(D13+E13)/2 -> 154.90076 | G13: =PTTC!F14 -> 97.16501 | H13: =PTTC!G14 -> 97.16501 | I13: =(G13+H13)/2 -> 97.16501 | J13: =I13-F13 -> -57.735748 | K13: =IF($K$1=$Q$4,Q13,IF($K$1=$S$4,S13,IF($K$1=$U$4,U13,W13))) -> 33 | L13: =IF($K$1=$Q$4,R13,IF($K$1=$S$4,T13,IF($K$1=$U$4,V13,X13))) -> 185 | Q13: 42 | R13: 233 | S13: 82 | T13: 233 | U13: 66 | V13: 233 | W13: 33 | X13: 185
A14: 2 | B14: =PTTC!B15 -> Hệ số nợ so với tài sản - Ntts | C14: % | D14: =PTTC!D15 -> 60.769039 | E14: =PTTC!E15 -> 60.769039 | F14: =(D14+E14)/2 -> 60.769039 | G14: =PTTC!F15 -> 49.281043 | H14: =PTTC!G15 -> 49.281043 | I14: =(G14+H14)/2 -> 49.281043 | J14: =I14-F14 -> -11.487997 | K14: =IF($K$1=$Q$4,Q14,IF($K$1=$S$4,S14,IF($K$1=$U$4,U14,W14))) -> 0 | L14: =IF($K$1=$Q$4,R14,IF($K$1=$S$4,T14,IF($K$1=$U$4,V14,X14))) -> 3 | Q14: 0 | R14: 3 | S14: 0 | T14: 3 | U14: 0 | V14: 3 | W14: 0 | X14: 3
A15: 3 | B15: =PTTC!B16 -> Tỷ lệ nợ quá hạn trong tổng dư nợ vay - Nqh | C15: % | D15: =PTTC!D16 -> 0 | E15: =PTTC!E16 -> 0 | F15: =(D15+E15)/2 -> 0 | G15: =PTTC!F16 -> 0 | H15: =PTTC!G16 -> 0 | I15: =(G15+H15)/2 -> 0 | J15: =I15-F15 -> 0 | K15: =IF($K$1=$Q$4,Q15,IF($K$1=$S$4,S15,IF($K$1=$U$4,U15,W15))) -> 0 | L15: =IF($K$1=$Q$4,R15,IF($K$1=$S$4,T15,IF($K$1=$U$4,V15,X15))) -> 0
A16: 4 | B16: =PTTC!B17 -> Hệ số thích ứng dài hạn của tài sản - Ktu | C16: lần | D16: =PTTC!D17 -> 0.86350349 | E16: =PTTC!E17 -> 0.86350349 | F16: =(D16+E16)/2 -> 0.86350349 | G16: =PTTC!F17 -> 0.80403304 | H16: =PTTC!G17 -> 0.80403304 | I16: =(G16+H16)/2 -> 0.80403304 | J16: =I16-F16 -> -0.059470452 | K16: =IF($K$1=$Q$4,Q16,IF($K$1=$S$4,S16,IF($K$1=$U$4,U16,W16))) -> 0 | L16: =IF($K$1=$Q$4,R16,IF($K$1=$S$4,T16,IF($K$1=$U$4,V16,X16))) -> 0
A17: 5 | B17: =PTTC!B18 -> Hệ số tài sản dài hạn trên vốn chủ sở hữu - Kts | C17: lần | D17: =PTTC!D18 -> 1.0232026 | E17: =PTTC!E18 -> 1.0232026 | F17: =(D17+E17)/2 -> 1.0232026 | G17: =PTTC!F18 -> 0.93971918 | H17: =PTTC!G18 -> 0.93971918 | I17: =(G17+H17)/2 -> 0.93971918 | J17: =I17-F17 -> -0.083483394 | K17: =IF($K$1=$Q$4,Q17,IF($K$1=$S$4,S17,IF($K$1=$U$4,U17,W17))) -> 0 | L17: =IF($K$1=$Q$4,R17,IF($K$1=$S$4,T17,IF($K$1=$U$4,V17,X17))) -> 0
A18: 6 | B18: =PTTC!B19 -> Hệ số nguồn vốn chủ sở hữu trên Tổng tài sản - Httt | C18: % | D18: =PTTC!D19 -> 39.23095 | E18: =PTTC!E19 -> 39.23095 | F18: =(D18+E18)/2 -> 39.23095 | G18: =PTTC!F19 -> 50.718919 | H18: =PTTC!G19 -> 50.718919 | I18: =(G18+H18)/2 -> 50.718919 | J18: =I18-F18 -> 11.487969
A19: III | B19: =PTTC!B20 -> HIỆU QUẢ SỬ DỤNG VỐN VÀ SINH LỜI
A20: 1 | B20: =PTTC!B21 -> Hiệu quả sử dụng tài sản - L | C20: % | D20: =PTTC!D21 -> 1.6543107 | E20: =PTTC!E21 -> 1.6543107 | F20: =(D20+E20)/2 -> 1.6543107 | G20: =PTTC!F21 -> 1.2820671 | H20: =PTTC!G21 -> 1.2820671 | I20: =(G20+H20)/2 -> 1.2820671 | J20: =I20-F20 -> -0.37224365 | K20: =IF($K$1=$Q$4,Q20,IF($K$1=$S$4,S20,IF($K$1=$U$4,U20,W20))) -> 1.5 | L20: =IF($K$1=$Q$4,R20,IF($K$1=$S$4,T20,IF($K$1=$U$4,V20,X20))) -> 4 | Q20: 1.7 | R20: 5.5 | S20: 1.7 | T20: 4.2 | U20: 1.7 | V20: 5 | W20: 1.5 | X20: 4
A21: 2 | B21: =PTTC!B22 -> Vòng quay hàng tồn kho - V | C21: vòng | D21: =PTTC!D22 -> 5.873805 | E21: =PTTC!E22 -> 5.873805 | F21: =(D21+E21)/2 -> 5.873805 | G21: =PTTC!F22 -> 3.2061628 | H21: =PTTC!G22 -> 3.2061628 | I21: =(G21+H21)/2 -> 3.2061628 | J21: =I21-F21 -> -2.6676422 | K21: =IF($K$1=$Q$4,Q21,IF($K$1=$S$4,S21,IF($K$1=$U$4,U21,W21))) -> 3.5 | L21: =IF($K$1=$Q$4,R21,IF($K$1=$S$4,T21,IF($K$1=$U$4,V21,X21))) -> 7 | Q21: 2 | R21: 4.5 | S21: 2.5 | T21: 6 | U21: 2 | V21: 4 | W21: 3.5 | X21: 7
A22: 3 | B22: =PTTC!B23 -> Kỳ thu tiền bình quân - Nth | C22: ngày | D22: =PTTC!D23 -> 31.480615 | E22: =PTTC!E23 -> 31.480615 | F22: =(D22+E22)/2 -> 31.480615 | G22: =PTTC!F23 -> 33.41808 | H22: =PTTC!G23 -> 33.41808 | I22: =(G22+H22)/2 -> 33.41808 | J22: =I22-F22 -> 1.9374644 | K22: =IF($K$1=$Q$4,Q22,IF($K$1=$S$4,S22,IF($K$1=$U$4,U22,W22))) -> 32 | L22: =IF($K$1=$Q$4,R22,IF($K$1=$S$4,T22,IF($K$1=$U$4,V22,X22))) -> 60 | Q22: 34 | R22: 70 | S22: 30 | T22: 65 | U22: 40 | V22: 150 | W22: 32 | X22: 60
A23: 4 | B23: =PTTC!B24 -> Vòng quay tài sản ngắn hạn - Vvlđ | C23: vòng | D23: =PTTC!D24 -> 2.6778907 | E23: =PTTC!E24 -> 2.6778907 | F23: =(D23+E23)/2 -> 2.6778907 | G23: =PTTC!F24 -> 1.99588 | H23: =PTTC!G24 -> 1.99588 | I23: =(G23+H23)/2 -> 1.99588 | J23: =I23-F23 -> -0.68201062
A24: 5 | B24: =PTTC!B25 -> Vòng quay các khoản phải thu - Vkpt | C24: vòng | D24: =PTTC!D25 -> 11.080592 | E24: =PTTC!E25 -> 11.080592 | F24: =(D24+E24)/2 -> 11.080592 | G24: =PTTC!F25 -> 10.603968 | H24: =PTTC!G25 -> 10.603968 | I24: =(G24+H24)/2 -> 10.603968 | J24: =I24-F24 -> -0.47662468
A25: 6 | B25: =PTTC!B26 -> Vòng quay khoản phải trả - Vkptr | C25: vòng | D25: =PTTC!D26 -> 24.939601 | E25: =PTTC!E26 -> 24.939601 | F25: =(D25+E25)/2 -> 24.939601 | G25: =PTTC!F26 -> 96.50643 | H25: =PTTC!G26 -> 96.50643 | I25: =(G25+H25)/2 -> 96.50643 | J25: =I25-F25 -> 71.566829
A26: 7 | B26: =PTTC!B27 -> Số ngày phải hoàn trả nợ - Ntr | C26: ngày | D26: =PTTC!D27 -> 0.48116247 | E26: =PTTC!E27 -> 0.48116247 | F26: =(D26+E26)/2 -> 0.48116247 | G26: =PTTC!G27 -> 0.12434405 | H26: =PTTC!G27 -> 0.12434405 | I26: =(G26+H26)/2 -> 0.12434405 | J26: =I26-F26 -> -0.35681842
A27: 8 | B27: =PTTC!B28 -> Tỷ suất lợi nhuận trước thuế trên doanh thu - LNdt | C27: % | D27: =PTTC!D28 -> 0.96448469 | E27: =PTTC!E28 -> 0.96448469 | F27: =(D27+E27)/2 -> 0.96448469 | G27: =PTTC!F28 -> 1.5962826 | H27: =PTTC!G28 -> 1.5962826 | I27: =(G27+H27)/2 -> 1.5962826 | J27: =I27-F27 -> 0.63179792 | K27: =IF($K$1=$Q$4,Q27,IF($K$1=$S$4,S27,IF($K$1=$U$4,U27,W27))) -> 5.5 | L27: =IF($K$1=$Q$4,R27,IF($K$1=$S$4,T27,IF($K$1=$U$4,V27,X27))) -> 8 | Q27: 1.5 | R27: 5 | S27: 3 | T27: 6.5 | U27: 5 | V27: 10 | W27: 5.5 | X27: 8
A28: 9 | B28: =PTTC!B29 -> Tỷ suất lợi nhuận trước thuế trên vốn chủ sở hữu - LNvsh | C28: % | D28: =PTTC!D29 -> 4.0670883 | E28: =PTTC!E29 -> 4.0670883 | F28: =(D28+E28)/2 -> 4.0670883 | G28: =PTTC!F29 -> 4.0350651 | H28: =PTTC!G29 -> 4.0350651 | I28: =(G28+H28)/2 -> 4.0350651 | J28: =I28-F28 -> -0.03202319 | K28: =IF($K$1=$Q$4,Q28,IF($K$1=$S$4,S28,IF($K$1=$U$4,U28,W28))) -> 9.6 | L28: =IF($K$1=$Q$4,R28,IF($K$1=$S$4,T28,IF($K$1=$U$4,V28,X28))) -> 14.2 | Q28: 7 | R28: 10 | S28: 12.2 | T28: 14.2 | U28: 8.3 | V28: 11.5 | W28: 9.6 | X28: 14.2
A29: 10 | B29: =PTTC!B30 -> Tỷ suất lợi nhuận sau thuế trên vốn chủ sở hữu (ROE) - LNvsh | C29: % | D29: =PTTC!D30 -> 3.5511448 | E29: =PTTC!E30 -> 3.5511448 | F29: =(D29+E29)/2 -> 3.5511448 | G29: =PTTC!F30 -> 3.9136474 | H29: =PTTC!G30 -> 3.9136474 | I29: =(G29+H29)/2 -> 3.9136474 | J29: =I29-F29 -> 0.36250255
A30: 11 | B30: =PTTC!B31 -> Tỷ suất lợi nhuận sau thuế trên tổng Tài sản (ROA) - LNnv | C30: % | D30: =PTTC!D31 -> 1.393148 | E30: =PTTC!E31 -> 1.393148 | F30: =(D30+E30)/2 -> 1.393148 | G30: =PTTC!F31 -> 1.9849604 | H30: =PTTC!G31 -> 1.9849604 | I30: =(G30+H30)/2 -> 1.9849604 | J30: =I30-F30 -> 0.5918124 | K30: =IF($K$1=$Q$4,Q30,IF($K$1=$S$4,S30,IF($K$1=$U$4,U30,W30))) -> 5 | L30: =IF($K$1=$Q$4,R30,IF($K$1=$S$4,T30,IF($K$1=$U$4,V30,X30))) -> 7.5 | Q30: 3 | R30: 6 | S30: 4 | T30: 7 | U30: 2.5 | V30: 7.5 | W30: 5 | X30: 7.5
A31: 12 | B31: =PTTC!B32 -> Tỷ suất sinh lời của tiền vay - Tlntv | C31: % | D31: =PTTC!D32 -> 8.1126046 | E31: =PTTC!E32 -> 8.1126046 | F31: =(D31+E31)/2 -> 8.1126046 | G31: =PTTC!F32 -> 10.026223 | H31: =PTTC!G32 -> 10.026223 | I31: =(G31+H31)/2 -> 10.026223 | J31: =I31-F31 -> 1.913618
A32: IV | B32: =PTTC!B33 -> SỨC TĂNG TRƯỞNG
A33: 1 | B33: =PTTC!B34 -> Sức tăng trưởng doanh thu - TTdt | D33: =PTTC!D34 -> 0 | E33: =PTTC!E34 -> 1 | F33: =(D33+E33)/2 -> 0.5 | G33: =PTTC!F34 -> 0 | H33: =PTTC!G34 -> 1 | I33: =(G33+H33)/2 -> 0.5 | J33: =I33-F33 -> 0 | K33: =IF($K$1=$Q$4,Q33,IF($K$1=$S$4,S33,IF($K$1=$U$4,U33,W33))) -> 0 | L33: =IF($K$1=$Q$4,R33,IF($K$1=$S$4,T33,IF($K$1=$U$4,V33,X33))) -> 0
A34: 2 | B34: =PTTC!B35 -> Tỷ lệ tăng trưởng doanh thu từ HĐKD chính - TTdtc | D34: =PTTC!D35 -> 0 | E34: =PTTC!E35 -> 1 | F34: =(D34+E34)/2 -> 0.5 | G34: =PTTC!F35 -> 0 | H34: =PTTC!G35 -> 1 | I34: =(G34+H34)/2 -> 0.5 | K34: =IF($K$1=$Q$4,Q34,IF($K$1=$S$4,S34,IF($K$1=$U$4,U34,W34))) -> 0 | L34: =IF($K$1=$Q$4,R34,IF($K$1=$S$4,T34,IF($K$1=$U$4,V34,X34))) -> 0
A35: 3 | B35: =PTTC!B36 -> Tỷ lệ tăng trưởng lợi nhuận - TTln | D35: =PTTC!D36 -> 0 | E35: =PTTC!E36 -> 1 | F35: =(D35+E35)/2 -> 0.5 | G35: =PTTC!F36 -> 0 | H35: =PTTC!G36 -> 1 | I35: =(G35+H35)/2 -> 0.5 | K35: =IF($K$1=$Q$4,Q35,IF($K$1=$S$4,S35,IF($K$1=$U$4,U35,W35))) -> 0 | L35: =IF($K$1=$Q$4,R35,IF($K$1=$S$4,T35,IF($K$1=$U$4,V35,X35))) -> 0
A36: 4 | B36: =PTTC!B37 -> Tỷ lệ tăng trưởng lợi nhuận từ hoạt động kinh doanh chính -TTln | D36: =PTTC!D37 -> 0 | E36: =PTTC!E37 -> 1 | F36: =(D36+E36)/2 -> 0.5 | G36: =PTTC!F37 -> 0 | H36: =PTTC!G37 -> 1 | I36: =(G36+H36)/2 -> 0.5 | K36: =IF($K$1=$Q$4,Q36,IF($K$1=$S$4,S36,IF($K$1=$U$4,U36,W36))) -> 0 | L36: =IF($K$1=$Q$4,R36,IF($K$1=$S$4,T36,IF($K$1=$U$4,V36,X36))) -> 0

Sheet DN-CIC-NCV
A1: 1-Tình hình dư nợ tại các Tổ chức tín dụng theo CIC (Điểm 1.1.1 thuộc mục IV. Quan hệ Tín dụng - Báo cáo thẩm định)
A2: Loại dư nợ | B2: VND | D2: USD
A3: 1-Ngân hàng ….. | B3: =B4+B6 -> 0 | D3: =E4+E6 -> 0
A4: -Dư nợ cho vay ngắn hạn:
A5: +Dư nợ đủ tiêu chuẩn
A6: -Dư nợ cho vay trung, dài hạn:
A7: +Dư nợ đủ tiêu chuẩn
A8: 2-Ngân hàng… | B8: =B9+B11 -> 0 | D8: =E9+E11 -> 0
A9: -Dư nợ cho vay ngắn hạn:
A10: +Dư nợ đủ tiêu chuẩn
A11: -Dư nợ cho vay trung, dài hạn:
A12: +Dư nợ đủ tiêu chuẩn
A13: Tổng cộng | B13: =B3+B8 -> 0 | D13: =D3+D8 -> 0
A15: 2-Tình hình quan hệ tín dụng với Agribank (Điểm 1.1.2 thuộc mục IV. Quan hệ Tín dụng - Báo cáo thẩm định)
A16: Chỉ tiêu | B16: Mức cấp tín dụng | C16: Dư nợ đến ngày …. | E16: Doanh số cho vay Năm … | G16: Doanh số thu nợ | I16: Thu lãi/phí
C17: VNĐ | D17: Ngoại tệ | E17: VNĐ | F17: Ngoại tệ | G17: VNĐ | H17: Ngoại tệ
A18: 1-Tại Chi nhánh ….. | B18: =B19+B23 -> 0 | C18: =C19+C23 -> 0 | D18: =D19+D23 -> 0 | E18: =E19+E23 -> 0 | F18: =F19+F23 -> 0 | G18: =G19+G23 -> 0 | H18: =H19+H23 -> 0 | I18: =I19+I23 -> 0
A19: 1.1-Cho vay ngắn hạn | B19: =B20+B21+B22 -> 0 | C19: =C20+C21+C22 -> 0 | D19: =D20+D21+D22 -> 0 | E19: =E20+E21+E22 -> 0 | F19: =F20+F21+F22 -> 0 | G19: =G20+G21+G22 -> 0 | H19: =H20+H21+H22 -> 0 | I19: =I20+I21+I22 -> 0
A20: +Dư nợ
A21: +Bảo lãnh
A22: +L/C
A23: 1.2-Cho vay trung, dài hạn
A24: 2-Tại Chi nhánh ….. | B24: =B25+B29 -> 0 | C24: =C25+C29 -> 0 | D24: =D25+D29 -> 0 | E24: =E25+E29 -> 0 | F24: =F25+F29 -> 0 | G24: =G25+G29 -> 0 | H24: =H25+H29 -> 0 | I24: =I25+I29 -> 0
A25: 1.1-Cho vay ngắn hạn | B25: =B26+B27+B28 -> 0 | C25: =C26+C27+C28 -> 0 | D25: =D26+D27+D28 -> 0 | E25: =E26+E27+E28 -> 0 | F25: =F26+F27+F28 -> 0 | G25: =G26+G27+G28 -> 0 | H25: =H26+H27+H28 -> 0 | I25: =I26+I27+I28 -> 0
A26: +Dư nợ
A27: +Bảo lãnh
A28: +L/C
A29: 1.2-Cho vay trung, dài hạn
A30: Tổng cộng | B30: =B18+B24 -> 0 | C30: =C18+C24 -> 0 | D30: =D18+D24 -> 0 | E30: =E18+E24 -> 0 | F30: =F18+F24 -> 0 | G30: =G18+G24 -> 0 | H30: =H18+H24 -> 0 | I30: =I18+I24 -> 0
A32: 3-Nhóm khách hàng vay liên quan (Điểm 1.2.2 thuộc mục IV. Quan hệ Tín dụng - Báo cáo thẩm định)
A33: Tên khách hàng | B33: Mã khách hàng | C33: Mức cấp tín dụng | D33: Ngày ký hợp đồng | E33: Tình hình cấp tín dụng đến hết ngày .../.../......
E34: Tổng | F34: Dư nợ cho vay | G34: LC, bảo lãnh
A35: 1- | E35: =F35+G35 -> 0
A36: 2- | E36: =F36+G36 -> 0
A37: Tổng cộng | C37: =C35+C36 -> 0 | E37: =E35+E36 -> 0 | F37: =F35+F36 -> 0 | G37: =G35+G36 -> 0
A39: 4-Chấm điểm, xếp hạng khách hàng trên hệ thống xếp hạng tín dụng nội bộ (Điểm 2 thuộc mục IV. Quan hệ Tín dụng - Báo cáo thẩm định)
A40: Đơn vị đánh giá | B40: Xếp hạng | C40: Tổng điểm | D40: Điểm tài chính | E40: Điểm phi tài chính | F40: Ghi chú
A41: 1-Chi nhánh ….
A43: 5-Tình hình thực hiện các nội dung cấp tín dụng (Điểm 3.1 thuộc mục IV. Quan hệ Tín dụng - Báo cáo thẩm định)
A44: Nội dung | B44: Chi tiết | E44: Tình hình thực hiện | H44: Đánh giá
...

Sheet BCNHANH
A1: STT | B1: CHỈ TIÊU | C1: Năm 2016 | D1: Quý IV/2017
A2: I | B2: TÌNH HÌNH TÀI CHÍNH
A3: A | B3: Tổng tài sản | C3: =CĐKT!G69 -> 7885450
A4: 1 | B4: Tài sản ngắn hạn | C4: =CĐKT!G7 -> 4127123
A5: - | B5: Tiền mặt | C5: =CĐKT!G8 -> 396214
A6: - | B6: Các khoản phải thu | C6: =CĐKT!G15 -> 938461
A7: - | B7: Hàng tồn kho | C7: =CĐKT!G24 -> 2616859
A8: - | B8: Đầu tư tài chính ngắn hạn | C8: =CĐKT!G11 -> 0
A9: - | B9: Tài sản ngắn hạn khác | C9: =CĐKT!G27 -> 175589
A10: 2 | B10: Tài sản dài hạn | C10: =CĐKT!G33 -> 3758327
A11: - | B11: Tài sản cố định | C11: =CĐKT!G42 -> 2130366
A12: - | B12: Tài sản dài hạn khác | C12: =CĐKT!G34+CĐKT!G52+CĐKT!G55+CĐKT!G58+CĐKT!G64 -> 1627961
A13: B | B13: Tổng nguồn vốn | C13: =CĐKT!G120 -> 7885447
A14: 1 | B14: Nợ phải trả | C14: =CĐKT!G71 -> 3886032
A15: 1.1 | B15: Nợ phải trả ngắn hạn | C15: =CĐKT!G72 -> 3211103
A16: - | B16: Nợ vay ngắn hạn | C16: =CĐKT!G82 -> 2837818
A17: + | B17: Vay ngắn hạn Agribank
A18: + | B18: Vay ngắn hạn các TCTD khác
A19: - | B19: Các khoản nợ ngắn hạn phải trả khác | C19: 373285
A20: + | B20: Phải trả người bán
A21: + | B21: Người mua trả tiền trước
A22: 1.2 | B22: Nợ phải trả trung, dài hạn | C22: =CĐKT!G87 -> 674929
A23: - | B23: Nợ vay trung, dài hạn | C23: =CĐKT!G95 -> 90194
A24: + | B24: Vay trung, dài hạn Agribank
A25: + | B25: Vay trung, dài hạn các TCTD khác
A26: - | B26: Các khoản nợ trung, dài hạn phải trả khác | C26: 584735
A27: 2 | B27: Nguồn vốn chủ sở hữu | C27: =CĐKT!G101 -> 3999415
A28: + | B28: Nguồn vốn đầu tư của chủ sở hữu | C28: =CĐKT!G103 -> 2831177
A29: + | B29: Lợi nhuận chưa phân phối | C29: =CĐKT!G113 -> -798479
A30: + | B30: Nguồn vốn chủ sở hữu khác | C30: 1966717
A31: II | B31: TÌNH HÌNH SXKD
A32: 1 | B32: Tổng doanh thu | C32: ='KQKD-Word'!G8 -> 9951410
A33: 2 | B33: Tổng chi phí SXKD | C33: 9790031
A34: 3 | B34: Lợi nhuận trước thuế | C34: ='KQKD-Word'!G20 -> 161379

Sheet HMTD-DN
A1: Xác định hạn mức thông qua các chỉ số tài chính kỳ báo cáo
A3: HẠN MỨC TÍN DỤNG NGẮN HẠN | B3: Đơn vị : đ
