Workbook

Sheet Sheet1
A1: Bảng cân đối kế toán (rút gọn) | L1: 2012 | M1: BQ 2013 | N1: BQ 2014 | O1: BQ 2015
A2: Chỉ tiêu | B2: Năm | E2: Tỷ trọng | H2: So sánh
B3: 31/12/2013 | C3: 31/12/2014 | D3: 30/9/2015 | E3: 2013 | F3: 2014 | G3: 9/2015 | H3: Tuyệt đối | I3: Tương đối | J3: Tuyệt đối | K3: Tương đối
A4: 1 | B4: 2 | C4: 3 | D4: 4 | E4: 5 | F4: 6 | G4: 7 | H4: 8 = 3-2 | I4: 9 = 8/2 | J4: 10=4-3 | K4: 11=10/3
A5: Tài sản | B5: =B6+B12 -> 192364 | C5: =C6+C12 -> 246148 | D5: =D6+D12 -> 246042 | E5: =E6+E12 -> 1 | F5: =F6+F12 -> 1 | G5: =G6+G12 -> 1 | H5: =C5-B5 -> 53784 | I5: =H5/B5 -> 0.27959493 | J5: =D5-C5 -> -106 | K5: =J5/C5 -> -0.00043063523 | L5: =L6+L12 -> 251483 | M5: =(L5+B5)/2 -> 221923.5 | N5: =(C5+B5)/2 -> 219256 | O5: =(D5+C5)/2 -> 246095 | P5: TSbq
A6: I/ Tài sản ngắn hạn | B6: =SUM(B7:B11) -> 135650 | C6: =SUM(C7:C11) -> 178892 | D6: =SUM(D7:D11) -> 172912 | E6: =B6/B5 -> 0.70517353 | F6: =C6/C5 -> 0.72676601 | G6: =D6/D5 -> 0.70277432 | H6: =C6-B6 -> 43242 | I6: =H6/B6 -> 0.31877626 | J6: =D6-C6 -> -5980 | K6: =J6/C6 -> -0.03342799 | L6: 190599 | M6: =(L6+B6)/2 -> 163124.5 | N6: =(B6+C6)/2 -> 157271 | O6: =(C6+D6)/2 -> 175902 | P6: VLĐbq
A7: 1. Tiền & Các khoản TĐT | B7: 1762 | C7: 77 | D7: 40 | E7: =B7/$B$6 -> 0.012989311 | F7: =C7/$C$6 -> 0.0004304273 | G7: =D7/$D$6 -> 0.00023133154 | H7: =C7-B7 -> -1685 | I7: =H7/B7 -> -0.95629966 | J7: =D7-C7 -> -37 | K7: =J7/C7 -> -0.48051948
A8: 2. Các khoản ĐTTC NH | E8: =B8/$B$6 -> 0 | F8: =C8/$C$6 -> 0 | G8: =D8/$D$6 -> 0 | H8: =C8-B8 -> 0 | I8: 0 | J8: =D8-C8 -> 0
A9: 3. Các khoản phải thu ngắn hạn | B9: 52707 | C9: 59155 | D9: 39397 | E9: =B9/$B$6 -> 0.38855142 | F9: =C9/$C$6 -> 0.33067437 | G9: =D9/$D$6 -> 0.22784422 | H9: =C9-B9 -> 6448 | I9: =H9/B9 -> 0.12233669 | J9: =D9-C9 -> -19758 | K9: =J9/C9 -> -0.33400389 | L9: 34540 | M9: =(L9+B9)/2 -> 43623.5 | N9: =(B9+C9)/2 -> 55931 | O9: =(C9+D9)/2 -> 49276 | P9: Pthu
A10: 4. Hàng tồn kho | B10: 81045 | C10: 119538 | D10: 133353 | E10: =B10/$B$6 -> 0.59745669 | F10: =C10/$C$6 -> 0.66821322 | G10: =D10/$D$6 -> 0.77121889 | H10: =C10-B10 -> 38493 | I10: =H10/B10 -> 0.47495836 | J10: =D10-C10 -> 13815 | K10: =J10/C10 -> 0.11556994 | L10: 155480 | M10: =(L10+B10)/2 -> 118262.5 | N10: =(B10+C10)/2 -> 100291.5 | O10: =(C10+D10)/2 -> 126445.5 | P10: HTK
A11: 5. Tài sản ngắn hạn khác | B11: 136 | C11: 122 | D11: 122 | E11: =B11/$B$6 -> 0.0010025802 | F11: =C11/$C$6 -> 0.00068197572 | G11: =D11/$D$6 -> 0.00070556121 | H11: =C11-B11 -> -14 | I11: =H11/B11 -> -0.10294118 | J11: =D11-C11 -> 0 | K11: =J11/C11 -> 0
A12: II/Tài sản dài hạn | B12: =SUM(B13:B16) -> 56714 | C12: =SUM(C13:C16) -> 67256 | D12: =SUM(D13:D16) -> 73130 | E12: =B12/B5 -> 0.29482647 | F12: =C12/C5 -> 0.27323399 | G12: =D12/D5 -> 0.29722568 | H12: =C12-B12 -> 10542 | I12: =H12/B12 -> 0.18588003 | J12: =D12-C12 -> 5874 | K12: =J12/C12 -> 0.087337933 | L12: 60884 | M12: =(L12+B13)/2 -> 30442 | N12: =(M12+C13)/2 -> 15416 | O12: =(N12+D13)/2 -> 8178 | P12: TSCĐ
A13: 1. Các khoản phải thu dài hạn | C13: 390 | D13: 940 | E13: =B13/$B$12 -> 0 | F13: =C13/$C$12 -> 0.0057987391 | G13: =D13/$D$12 -> 0.012853822 | H13: =C13-B13 -> 390 | I13: =H13/B13 -> #DIV/0! | J13: =D13-C13 -> 550 | K13: =J13/C13 -> 1.4102564 | L13: Doanh số thu nợ | M13: 253000 | N13: 292000 | O13: 425000
A14: 2. Tài sản cố định | B14: 55014 | C14: 51990 | D14: 53636 | E14: =B14/$B$12 -> 0.97002504 | F14: =C14/$C$12 -> 0.77301653 | G14: =D14/$D$12 -> 0.73343361 | H14: =C14-B14 -> -3024 | I14: =H14/B14 -> -0.054967826 | J14: =D14-C14 -> 1646 | K14: =J14/C14 -> 0.031659935
A15: 3. Tài sản dài hạn dở dang | B15: 395 | C15: 13228 | D15: 16987 | E15: =B15/$B$12 -> 0.0069647706 | F15: =C15/$C$12 -> 0.19668134 | G15: =D15/$D$12 -> 0.23228497 | H15: =C15-B15 -> 12833 | I15: =H15/B15 -> 32.488608 | J15: =D15-C15 -> 3759 | K15: =J15/C15 -> 0.28416994
A16: 4. Tài sản dài hạn khác | B16: 1305 | C16: 1648 | D16: 1567 | E16: =B16/$B$12 -> 0.023010191 | F16: =C16/$C$12 -> 0.02450339 | G16: =D16/$D$12 -> 0.021427595 | H16: =C16-B16 -> 343 | I16: =H16/B16 -> 0.26283525 | J16: =D16-C16 -> -81 | K16: =J16/C16 -> -0.049150485
A17: Nguồn vốn | B17: =B18+B29 -> 192364 | C17: =C18+C29 -> 246148 | D17: =D18+D29 -> 246042 | E17: =E18+E29 -> 1 | F17: =F18+F29 -> 1 | G17: =G18+G29 -> 1 | H17: =C17-B17 -> 53784 | I17: =H17/B17 -> 0.27959493 | J17: =D17-C17 -> -106 | K17: =J17/C17 -> -0.00043063523 | L17: Vốn tự có từ 2 nguồn: | M17: s2013 | N17: s2014 | O17: s2015
A18: I/ Nợ phải trả | B18: =B19+B26 -> 111189 | C18: =C19+C26 -> 154319 | D18: =D19+D26 -> 151812 | E18: =B18/B17 -> 0.57801356 | F18: =C18/C17 -> 0.62693583 | G18: =D18/D17 -> 0.61701661 | H18: =C18-B18 -> 43130 | I18: =H18/B18 -> 0.38789808 | J18: =D18-C18 -> -2507 | K18: =J18/C18 -> -0.016245569 | L18: Vốn lưu động ròng | M18: =B6-B19 -> 36861 | N18: =C6-C19 -> 45973 | O18: =D6-D19 -> 42500
A19: 1. Nợ ngắn hạn | B19: =SUM(B20:B25) -> 98789 | C19: =SUM(C20:C25) -> 132919 | D19: =SUM(D20:D25) -> 130412 | E19: =B19/B18 -> 0.88847818 | F19: =C19/C18 -> 0.86132621 | G19: =D19/D18 -> 0.85903618 | H19: =C19-B19 -> 34130 | I19: =H19/B19 -> 0.34548381 | J19: =D19-C19 -> -2507 | K19: =J19/C19 -> -0.018861111 | L19: Vốn chiếm dụng | M19: =B21+B22 -> 11264 | N19: =C21+C22 -> 22279 | O19: =D21+D22 -> 23277
A20: Vay và nợ ngắn hạn | B20: 83564 | C20: 105605 | D20: 102076 | E20: =B20/$B$19 -> 0.84588365 | F20: =C20/$C$19 -> 0.79450643 | G20: =D20/$D$19 -> 0.78271938 | H20: =C20-B20 -> 22041 | I20: =H20/B20 -> 0.26376191 | J20: =D20-C20 -> -3529 | K20: =J20/C20 -> -0.033416978
A21: Phải trả người bán | B21: 11133 | C21: 20904 | D21: 19377 | E21: =B21/$B$19 -> 0.11269473 | F21: =C21/$C$19 -> 0.15726871 | G21: =D21/$D$19 -> 0.14858295 | H21: =C21-B21 -> 9771 | I21: =H21/B21 -> 0.87766101 | J21: =D21-C21 -> -1527 | K21: =J21/C21 -> -0.07304822
A22: Người mua trả tiền trước | B22: 131 | C22: 1375 | D22: 3900 | E22: =B22/$B$19 -> 0.0013260586 | F22: =C22/$C$19 -> 0.010344646 | G22: =D22/$D$19 -> 0.029905223 | H22: =C22-B22 -> 1244 | I22: =H22/B22 -> 9.4961832 | J22: =D22-C22 -> 2525 | K22: =J22/C22 -> 1.8363636
A23: Thuế và các khoản phải nộp | B23: 1961 | C23: 2881 | D23: 2723 | E23: =B23/$B$19 -> 0.019850388 | F23: =C23/$C$19 -> 0.021674855 | G23: =D23/$D$19 -> 0.02087998 | H23: =C23-B23 -> 920 | I23: =H23/B23 -> 0.46914839 | J23: =D23-C23 -> -158 | K23: =J23/C23 -> -0.054842069
A24: Phải trả người lao động | B24: 1655 | C24: 2083 | D24: 2258 | E24: =B24/$B$19 -> 0.016752877 | F24: =C24/$C$19 -> 0.015671198 | G24: =D24/$D$19 -> 0.017314358 | H24: =C24-B24 -> 428 | I24: =H24/B24 -> 0.25861027 | J24: =D24-C24 -> 175 | K24: =J24/C24 -> 0.084013442
A25: Các khoản phải trả, phải nộp khác | B25: 345 | C25: 71 | D25: 78 | E25: =B25/$B$19 -> 0.0034922917 | F25: =C25/$C$19 -> 0.0005341599 | G25: =D25/$D$19 -> 0.00059810447 | H25: =C25-B25 -> -274 | I25: =H25/B25 -> -0.7942029 | J25: =D25-C25 -> 7 | K25: =J25/C25 -> 0.098591549
A26: 2. Nợ dài hạn | B26: =SUM(B27:B28) -> 12400 | C26: =SUM(C27:C28) -> 21400 | D26: =SUM(D27:D28) -> 21400 | E26: =B26/B18 -> 0.11152182 | F26: =C26/C18 -> 0.13867379 | G26: =D26/D18 -> 0.14096382 | H26: =C26-B26 -> 9000 | I26: =H26/B26 -> 0.72580645 | J26: =D26-C26 -> 0 | K26: =J26/C26 -> 0
A27: Vay và nợ dài hạn | B27: 12400 | C27: 21400 | D27: 21400 | E27: =B27/$B$26 -> 1 | F27: =C27/$C$26 -> 1 | G27: =D27/$D$26 -> 1 | H27: =C27-B27 -> 9000 | I27: =H27/B27 -> 0.72580645 | J27: =D27-C27 -> 0 | K27: =J27/C27 -> 0
A28: Phải trả dài hạn người bán | B28: 0 | E28: =B28/$B$26 -> 0 | F28: =C28/$C$26 -> 0 | G28: =D28/$D$26 -> 0 | H28: =C28-B28 -> 0 | I28: =H28/B28 -> #DIV/0! | J28: =D28-C28 -> 0 | K28: =J28/C28 -> #DIV/0!
A29: II/ Nguồn vốn chủ sở hữu | B29: =SUM(B30:B32) -> 81175 | C29: =SUM(C30:C32) -> 91829 | D29: =SUM(D30:D32) -> 94230 | E29: =B29/B17 -> 0.42198644 | F29: =C29/C17 -> 0.37306417 | G29: =D29/D17 -> 0.38298339 | H29: =C29-B29 -> 10654 | I29: =H29/B29 -> 0.13124731 | J29: =D29-C29 -> 2401 | K29: =J29/C29 -> 0.026146424
A30: 1. Vốn đầu tư của CSH | B30: 72000 | C30: 81000 | D30: 81000 | E30: =B30/$B$29 -> 0.88697259 | F30: =C30/$C$29 -> 0.88207429 | G30: =D30/$D$29 -> 0.85959885 | H30: =C30-B30 -> 9000 | I30: =H30/B30 -> 0.125 | J30: =D30-C30 -> 0 | K30: =J30/C30 -> 0
A31: 2. Vốn khác của CSH | H31: =C31-B31 -> 0 | I31: =H31/B31 -> #DIV/0! | J31: =D31-C31 -> 0 | K31: =J31/C31 -> #DIV/0!
A32: 3. Lợi nhuận chưa phân phối | B32: 9175 | C32: 10829 | D32: 13230 | E32: =B32/$B$29 -> 0.11302741 | F32: =C32/$C$29 -> 0.11792571 | G32: =D32/$D$29 -> 0.14040115 | H32: =C32-B32 -> 1654 | I32: =H32/B32 -> 0.18027248 | J32: =D32-C32 -> 2401 | K32: =J32/C32 -> 0.22171946
H34: Vốn lưu động ròng = TS ngắn hạn - Nợ ngắn hạn
A35: CÁC HỆ SỐ TÀI CHÍNH | B35: Năm 2013 | C35: Năm 2014 | D35: 30/9/15 | E35: So sánh (2)/(1) | F35: So sánh (3)/(2) | H35: Vốn chủ sở hữu + Nợ dài hạn – Tài sản dài hạn - Phải thu khó đòi
A36: 1. Các chỉ tiêu về thanh khoản
A37: Hệ số thanh toán ngắn hạn | B37: =B6/B19 -> 1.3731286 | C37: =C6/C19 -> 1.3458723 | D37: =D6/D19 -> 1.3258903 | E37: =C37-B37 -> -0.027256289 | F37: =D37-C37 -> -0.019982043 | H37: Tài sản ngắn hạn/ Nợ ngắn hạn
A38: Hệ số thanh toán nhanh | B38: =(B6-B10)/B19 -> 0.55274373 | C38: =(C6-C10)/C19 -> 0.44654263 | D38: =(D6-D10)/D19 -> 0.30333865 | E38: =C38-B38 -> -0.1062011 | F38: =D38-C38 -> -0.14320398 | H38: (TS ngắn hạn - Hàng tồn kho)/ Nợ NH
A39: 2. Các chỉ tiêu về hoạt động
A40: Vòng quay các khoản phải thu | B40: =Sheet2!B5/Sheet1!M9 -> 12.351072 | C40: =Sheet2!C5/Sheet1!N9 -> 7.3845989 | D40: =Sheet2!D5/Sheet1!O9 -> 2.513881 | E40: =C40-B40 -> -4.9664734 | F40: =D40-C40 -> -4.8707179 | H40: Doanh thu thuần/ Các khoản phải thu BQ
A41: Kỳ thu tiền bình quân | B41: =360/B40 -> 29.147267 | C41: =360/C40 -> 48.750109 | D41: =360/D40 -> 143.20487 | E41: =C41-B41 -> 19.602842 | F41: =D41-C41 -> 94.454761 | H41: 360/ vòng quay các khoản phải thu
...

Sheet Sheet2
A1: KẾT QUẢ HOẠT ĐỘNG KINH DOANH
A3: CHỈ TIÊU | B3: 2013 (1) | C3: 2014 (2) | D3: 9-2015 (3) | E3: So sánh (2) - (1) | F3: So sánh (3) - (2) | G3: So sánh tương đối (2) - (1) | H3: So sánh tương đối (3) - (2) | J3: Tỷ trọng/doanh thu
A4: Tổng doanh thu | B4: 380696 | C4: 492421 | D4: 538797 | E4: =C4-B4 -> 111725 | F4: =D4-C4 -> 46376 | G4: =E4/B4 -> 0.29347563 | H4: =F4/C4 -> 0.094179574
A5: + Doanh thu thuần | B5: 538797 | C5: 413028 | D5: 123874 | E5: =C5-B5 -> -125769 | F5: =D5-C5 -> -289154 | G5: =E5/B5 -> -0.23342558 | H5: =F5/C5 -> -0.70008329 | J5: =B5 -> 538797 | K5: =C5 -> 413028 | L5: =D5 -> 123874
A6: + Giá vốn hàng bán | B6: 507126 | C6: 369497 | D6: 114665 | E6: =C6-B6 -> -137629 | F6: =D6-C6 -> -254832 | G6: =E6/B6 -> -0.27139015 | H6: =F6/C6 -> -0.68967272 | J6: =B6/B5*100 -> 94.121905 | K6: =C6/C5*100 -> 89.460521 | L6: =D6/D5*100 -> 92.565833
A7: + Lợi nhuận gộp | B7: =B5-B6 -> 31671 | C7: =C5-C6 -> 43531 | D7: =D5-D6 -> 9209 | E7: =C7-B7 -> 11860 | F7: =D7-C7 -> -34322 | G7: =E7/B7 -> 0.37447507 | H7: =F7/C7 -> -0.78844961 | J7: =B7/B5*100 -> 5.8780951 | K7: =C7/C5*100 -> 10.539479 | L7: =D7/D5*100 -> 7.434167
A8: - Chi phí bán hàng | B8: 10216 | C8: 16514 | D8: 4225 | E8: =C8-B8 -> 6298 | F8: =D8-C8 -> -12289 | G8: =E8/B8 -> 0.61648395 | H8: =F8/C8 -> -0.74415647 | J8: =B8/B5*100 -> 1.8960759 | K8: =C8/C5*100 -> 3.9982761 | L8: =D8/D5*100 -> 3.4107238
A9: - Chi phí quản lý | B9: 6467 | C9: 7241 | D9: 1823 | E9: =C9-B9 -> 774 | F9: =D9-C9 -> -5418 | G9: =E9/B9 -> 0.11968455 | H9: =F9/C9 -> -0.74823919 | J9: =B9/B5*100 -> 1.2002665 | K9: =C9/C5*100 -> 1.7531499 | L9: =D9/D5*100 -> 1.4716567
A10: + Lợi nhuận thuần từ HĐKD | B10: =B7-B9-B8 -> 14988 | C10: =C7-C9-C8 -> 19776 | D10: =D7-D9-D8 -> 3161 | E10: =C10-B10 -> 4788 | F10: =D10-C10 -> -16615 | G10: =E10/B10 -> 0.31945556 | H10: =F10/C10 -> -0.84015979 | J10: =B10/B5*100 -> 2.7817527 | K10: =C10/C5*100 -> 4.7880531 | L10: =D10/D5*100 -> 2.5517865
A11: - Thu nhập hoạt động tài chính | B11: 34 | C11: 46 | E11: =C11-B11 -> 12 | F11: =D11-C11 -> -46 | G11: =E11/B11 -> 0.35294118 | H11: =F11/C11 -> -1 | J11: =B11/B5*100 -> 0.0063103544 | K11: =C11/C5*100 -> 0.011137259 | L11: =D11/D5*100 -> 0
A12: - Chi phí hoạt động tài chính | B12: 6102 | C12: 5722 | D12: 1958 | E12: =C12-B12 -> -380 | F12: =D12-C12 -> -3764 | G12: =E12/B12 -> -0.062274664 | H12: =F12/C12 -> -0.65781195 | J12: =B12/B5*100 -> 1.132523 | K12: =C12/C5*100 -> 1.3853782 | L12: =D12/D5*100 -> 1.5806384
A13: + Lợi nhuận thuần từ HĐTC | B13: =B11-B12 -> -6068 | C13: =C11-C12 -> -5676 | D13: =D11-D12 -> -1958 | E13: =C13-B13 -> 392 | F13: =D13-C13 -> 3718 | G13: =E13/B13 -> -0.064601187 | H13: =F13/C13 -> -0.65503876
A14: - Các khoản thu nhập khác | B14: 1683 | C14: 544 | D14: 1249 | E14: =C14-B14 -> -1139 | F14: =D14-C14 -> 705 | G14: =E14/B14 -> -0.67676768 | H14: =F14/C14 -> 1.2959559 | J14: =B14/B5*100 -> 0.31236254 | K14: =C14/C5*100 -> 0.1317102 | L14: =D14/D5*100 -> 1.0082826
A15: - Chi phí khác | B15: 3 | C15: 278 | E15: =C15-B15 -> 275 | F15: =D15-C15 -> -278 | G15: =E15/B15 -> 91.666667 | H15: =F15/C15 -> -1 | J15: =B15/B5*100 -> 0.00055679597 | K15: =C15/C5*100 -> 0.067307785 | L15: =D15/D5*100 -> 0
A16: + Lợi nhuận khác | B16: =B14-B15 -> 1680 | C16: =C14-C15 -> 266 | D16: =D14-D15 -> 1249 | E16: =C16-B16 -> -1414 | F16: =D16-C16 -> 983 | G16: =E16/B16 -> -0.84166667 | H16: =F16/C16 -> 3.6954887
A17: * Tổng lợi nhuận trước thuế | B17: =B16+B13+B10 -> 10600 | C17: =C16+C13+C10 -> 14366 | D17: =D16+D13+D10 -> 2452 | E17: =C17-B17 -> 3766 | F17: =D17-C17 -> -11914 | G17: =E17/B17 -> 0.35528302 | H17: =F17/C17 -> -0.82931923 | J17: =B17/B5*100 -> 1.9673458 | K17: =C17/C5*100 -> 3.4782146 | L17: =D17/D5*100 -> 1.9794307
A18: * Thuế thu nhập | B18: 2332 | C18: 2873 | D18: 490 | E18: =C18-B18 -> 541 | F18: =D18-C18 -> -2383 | G18: =E18/B18 -> 0.23198971 | H18: =F18/C18 -> -0.82944657 | J18: =B18/B5*100 -> 0.43281607 | K18: =C18/C5*100 -> 0.69559449 | L18: =D18/D5*100 -> 0.39556323
A19: Tổng lợi nhuận sau thuế | B19: =B17-B18 -> 8268 | C19: =C17-C18 -> 11493 | D19: =D17-D18 -> 1962 | E19: =C19-B19 -> 3225 | F19: =D19-C19 -> -9531 | G19: =E19/B19 -> 0.39005806 | H19: =F19/C19 -> -0.82928739 | J19: =B19/B5*100 -> 1.5345297 | K19: =C19/C5*100 -> 2.7826201 | L19: =D19/D5*100 -> 1.5838675

Sheet Sheet3
D8: 2014 | E8: 2015 | F8: tăng giảm | G8: Tốc độ +/-
D10: 31439 | E10: 47768 | F10: =E10-D10 -> 16329 | G10: =E10/D10*100 -> 151.93867
D11: 36145 | E11: 49589 | F11: =E11-D11 -> 13444 | G11: =E11/D11*100 -> 137.19463
D12: 17307 | E12: 15732 | F12: =E12-D12 -> -1575 | G12: =E12/D12*100 -> 90.899636
D13: 406 | E13: 556 | F13: =E13-D13 -> 150 | G13: =E13/D13*100 -> 136.94581
D14: 24510 | E14: 27067 | F14: =E14-D14 -> 2557 | G14: =E14/D14*100 -> 110.43248
A15: Tài sản cố định hữu hình | D15: =SUM(D10:D14) -> 109807 | E15: =SUM(E10:E14) -> 140712 | F15: =SUM(F10:F14) -> 30905 | G15: =E15/D15*100 -> 128.14484
A16: TSCĐ vô hình | D16: 9432 | E16: 9230 | F16: =E16-D16 -> -202 | G16: =E16/D16*100 -> 97.858355
A17: CP XD dở dang | D17: 3712 | E17: 653 | F17: =E17-D17 -> -3059 | G17: =E17/D17*100 -> 17.591595
D18: =D15+D16+D17 -> 122951 | E18: =E15+E16+E17 -> 150595 | F18: =E18-D18 -> 27644 | G18: =E18/D18*100 -> 122.48375
