Workbook

Sheet KQKD- Bảng 4  (2)
A1: Bảng 4: Bảng dự kiến Doanh thu, chi phí của dự án
D2: 2017 | E2: 2018 | F2: 2019 | G2: 2020 | H2: 2021 | I2: 2022 | J2: 2023 | K2: 2024 | L2: 2025 | M2: 2026 | N2: 2027 | O2: 2028 | P2: 2029 | Q2: 2030 | R2: 2031 | S2: 2032
A3: TT | B3: Chỉ tiêu | D3: Năm thực hiện dự án
D4: 0 | E4: 1 | F4: 2 | G4: 3 | H4: 4 | I4: 5 | J4: 6 | K4: 7 | L4: 8 | M4: 9 | N4: 10 | O4: 11 | P4: 12 | Q4: 13 | R4: 14 | S4: 15
A5: A | B5: Tổng Doanh thu | E5: =E6+E16+E19+E22 -> 71514.893 | F5: =F6+F16+F19+F22 -> 300751.18 | G5: =G6+G16+G19+G22 -> 342853.23 | H5: =H6+H16+H19+H22 -> 351424.56 | I5: =I6+I16+I19+I22 -> 360210.17 | J5: =J6+J16+J19+J22 -> 369215.43 | K5: =K6+K16+K19+K22 -> 378445.81 | L5: =L6+L16+L19+L22 -> 387906.96 | ... S5: =S6+S16+S19+S22 -> 461099.48
A6: 1 | B6: Doanh thu chính | E6: =E11+E7 -> 70864.519 | F6: =F11+F7 -> 294479.08 | G6: =G11+G7 -> 336424.32 | H6: =H11+H7 -> 344834.93 | I6: =I11+I7 -> 353455.8 | J6: =J11+J7 -> 362292.2 | K6: =K11+K7 -> 371349.5 | L6: =L11+L7 -> 380633.24 | ... S6: =S11+S7 -> 452453.31
A7: 1.1 | B7: Doanh thu bán gà giống lông màu | E7: =E10 -> 9466.055 | F7: =F10 -> 32452.106 | G7: =G10 -> 34528.979 | H7: =H10 -> 35392.204 | I7: =I10 -> 36277.009 | J7: =J10 -> 37183.934 | K7: =K10 -> 38113.532 | L7: =L10 -> 39066.37 | ... S7: =S10 -> 46437.638
B8: Số lượng gà con lông màu (Nghìn con) | E8: 1391.9685 | F8: 4282.98 | G8: 4282.98 | H8: 4282.98 | I8: 4282.98 | J8: 4282.98 | K8: 4282.98 | L8: 4282.98 | M8: 4282.98 | N8: 4282.98 | O8: 4282.98 | P8: 4282.98 | Q8: 4282.98 | R8: 4282.98 | S8: 4282.98
B9: Đơn giá bán gà con (Tỷ lệ tăng giá 2,5%) | C9: =7.5*(1-'Thong so - Độ nhậy - Bảng 1'!N24) -> 7.5 | D9: 0.025 | E9: =$C$9*((1+$D$9)^E4) -> 7.6875 | F9: =$C$9*((1+$D$9)^F4) -> 7.8796875 | G9: =$C$9*((1+$D$9)^G4) -> 8.0766797 | H9: =$C$9*((1+$D$9)^H4) -> 8.2785967 | I9: =$C$9*((1+$D$9)^I4) -> 8.4855616 | J9: =$C$9*((1+$D$9)^J4) -> 8.6977006 | K9: =$C$9*((1+$D$9)^K4) -> 8.9151432 | L9: =$C$9*((1+$D$9)^L4) -> 9.1380217 | ... S9: =$C$9*((1+$D$9)^S4) -> 10.862236
B10: Doanh thu bán gà giống thực tế (Độ trễ: 03 tuần) | E10: =E8*E9*23/26 -> 9466.055 | F10: =E9*E8*3/26+F8*F9*37/40 -> 32452.106 | G10: =F9*F8*3/40+G8*G9*37/40 -> 34528.979 | H10: =G9*G8*3/40+H8*H9*37/40 -> 35392.204 | I10: =H9*H8*3/40+I8*I9*37/40 -> 36277.009 | J10: =I9*I8*3/40+J8*J9*37/40 -> 37183.934 | K10: =J9*J8*3/40+K8*K9*37/40 -> 38113.532 | L10: =K9*K8*3/40+L8*L9*37/40 -> 39066.37 | M10: =L9*L8*3/40+M8*M9*37/40 -> 40043.03 | N10: =M9*M8*3/40+N8*N9*37/40 -> 41044.105 | ... S10: =R9*R8*3/40+S8*S9*37/40 -> 46437.638
A11: 1.2 | B11: Doanh thu bán gà lông trắng gia công | E11: =E15 -> 61398.464 | F11: =F15 -> 262026.97 | G11: =G15 -> 301895.34 | H11: =H15 -> 309442.73 | I11: =I15 -> 317178.8 | J11: =J15 -> 325108.27 | K11: =K15 -> 333235.97 | L11: =L15 -> 341566.87 | ... S11: =S15 -> 406015.67
B12: Số lượng gà con lông trắng (Nghìn con) | C12: 2.747 | E12: 1439.9946 | F12: 4430.7525 | G12: 4430.7525 | H12: 4430.7525 | I12: 4430.7525 | J12: 4430.7525 | K12: 4430.7525 | L12: 4430.7525 | M12: 4430.7525 | N12: 4430.7525 | O12: 4430.7525 | P12: 4430.7525 | Q12: 4430.7525 | R12: 4430.7525 | S12: 4430.7525
B13: Đơn giá bán gà thịt (Tỷ lệ tăng giá 2,5%) | C13: =24*(1-'Thong so - Độ nhậy - Bảng 1'!N24) -> 24 | D13: =D9 -> 0.025 | E13: =$C$13*$C$12*((1+$D$13)^E4) -> 67.5762 | F13: =$C$13*$C$12*((1+$D$13)^F4) -> 69.265605 | G13: =$C$13*$C$12*((1+$D$13)^G4) -> 70.997245 | H13: =$C$13*$C$12*((1+$D$13)^H4) -> 72.772176 | I13: =$C$13*$C$12*((1+$D$13)^I4) -> 74.591481 | J13: =$C$13*$C$12*((1+$D$13)^J4) -> 76.456268 | K13: =$C$13*$C$12*((1+$D$13)^K4) -> 78.367674 | L13: =$C$13*$C$12*((1+$D$13)^L4) -> 80.326866 | ... S13: =$C$13*$C$12*((1+$D$13)^S4) -> 95.483402
B14: Hao hụt định mức | C14: 0.035 | E14: =E13*E12*(1-$C$14) -> 93903.533 | F14: =F13*F12*(1-$C$14) -> 296157.3 | G14: =G13*G12*(1-$C$14) -> 303561.23 | H14: =H13*H12*(1-$C$14) -> 311150.26 | I14: =I13*I12*(1-$C$14) -> 318929.02 | J14: =J13*J12*(1-$C$14) -> 326902.24 | K14: =K13*K12*(1-$C$14) -> 335074.8 | L14: =L13*L12*(1-$C$14) -> 343451.67 | ... S14: =S13*S12*(1-$C$14) -> 408256.1
B15: Doanh số bán gia công thực tế (Độ trễ: 09 tuần) | E15: =E14*17/26 -> 61398.464 | F15: =E14/26*9+F14*31/40 -> 262026.97 | G15: =F14/40*9+G14*31/40 -> 301895.34 | H15: =G14/40*9+H14*31/40 -> 309442.73 | I15: =H14/40*9+I14*31/40 -> 317178.8 | J15: =I14/40*9+J14*31/40 -> 325108.27 | K15: =J14/40*9+K14*31/40 -> 333235.97 | L15: =K14/40*9+L14*31/40 -> 341566.87 | M15: =L14/40*9+M14*31/40 -> 350106.04 | N15: =M14/40*9+N14*31/40 -> 358858.69 | ... S15: =R14/40*9+S14*31/40 -> 406015.67
A16: 2 | B16: Doanh thu từ bán trứng loại | E16: =E17*E18 -> 233.65887 | F16: =F17*F18 -> 736.92413 | G16: =G17*G18 -> 755.34724 | H16: =H17*H18 -> 774.23092 | I16: =I17*I18 -> 793.58669 | J16: =J17*J18 -> 813.42636 | K16: =K17*K18 -> 833.76202 | L16: =L17*L18 -> 854.60607 | ... S16: =S17*S18 -> 1015.8581
B17: Số lượng trứng loại | E17: 175.35375 | F17: 539.55 | G17: 539.55 | H17: 539.55 | I17: 539.55 | J17: 539.55 | K17: 539.55 | L17: 539.55 | M17: 539.55 | N17: 539.55 | O17: 539.55 | P17: 539.55 | Q17: 539.55 | R17: 539.55 | S17: 539.55
B18: Đơn giá (Tỷ lệ tăng giá 2,5%) | C18: 1.3 | E18: =$C$18*((1+$D$9)^E4) -> 1.3325 | F18: =$C$18*((1+$D$9)^F4) -> 1.3658125 | G18: =$C$18*((1+$D$9)^G4) -> 1.3999578 | H18: =$C$18*((1+$D$9)^H4) -> 1.4349568 | I18: =$C$18*((1+$D$9)^I4) -> 1.4708307 | J18: =$C$18*((1+$D$9)^J4) -> 1.5076014 | K18: =$C$18*((1+$D$9)^K4) -> 1.5452915 | L18: =$C$18*((1+$D$9)^L4) -> 1.5839238 | ... S18: =$C$18*((1+$D$9)^S4) -> 1.8827876
A19: 3 | B19: Doanh thu từ bán gà thịt tận thu | E19: =E20*E21 -> 0 | F19: =F20*F21 -> 4680.9126 | G19: =G20*G21 -> 4797.9354 | H19: =H20*H21 -> 4917.8838 | I19: =I20*I21 -> 5040.8309 | J19: =J20*J21 -> 5166.8517 | K19: =K20*K21 -> 5296.023 | L19: =L20*L21 -> 5428.4235 | ... S19: =S20*S21 -> 6452.6897
B20: Số lượng gà bán thịt tận thu | E20: 0 | F20: 55.692 | G20: 55.692 | H20: 55.692 | I20: 55.692 | J20: 55.692 | K20: 55.692 | L20: 55.692 | M20: 55.692 | N20: 55.692 | O20: 55.692 | P20: 55.692 | Q20: 55.692 | R20: 55.692 | S20: 55.692
B21: Đơn giá | C21: 80 | E21: =$C$21*((1+$D$9)^E4) -> 82 | F21: =$C$21*((1+$D$9)^F4) -> 84.05 | G21: =$C$21*((1+$D$9)^G4) -> 86.15125 | H21: =$C$21*((1+$D$9)^H4) -> 88.305031 | I21: =$C$21*((1+$D$9)^I4) -> 90.512657 | J21: =$C$21*((1+$D$9)^J4) -> 92.775473 | K21: =$C$21*((1+$D$9)^K4) -> 95.09486 | L21: =$C$21*((1+$D$9)^L4) -> 97.472232 | ... S21: =$C$21*((1+$D$9)^S4) -> 115.86385
A22: 4 | B22: Doanh thu từ bán phân gà | E22: =E23*E24 -> 416.71539 | F22: =F23*F24 -> 854.26655 | G22: =G23*G24 -> 875.62321 | H22: =H23*H24 -> 897.51379 | I22: =I23*I24 -> 919.95164 | J22: =J23*J24 -> 942.95043 | K22: =K23*K24 -> 966.52419 | L22: =L23*L24 -> 990.68729 | ... S22: =S23*S24 -> 1177.6159
B23: Khối lượng phân gà thu được | C23: tấn | E23: 0.8131032 | F23: 1.6262064 | G23: 1.6262064 | H23: 1.6262064 | I23: 1.6262064 | J23: 1.6262064 | K23: 1.6262064 | L23: 1.6262064 | M23: 1.6262064 | N23: 1.6262064 | O23: 1.6262064 | P23: 1.6262064 | Q23: 1.6262064 | R23: 1.6262064 | S23: 1.6262064
B24: Đơn giá (Tỷ lệ tăng giá 2,5%) | C24: 500 | E24: =$C$24*((1+$D$9)^E4) -> 512.5 | F24: =$C$24*((1+$D$9)^F4) -> 525.3125 | G24: =$C$24*((1+$D$9)^G4) -> 538.44531 | H24: =$C$24*((1+$D$9)^H4) -> 551.90645 | I24: =$C$24*((1+$D$9)^I4) -> 565.70411 | J24: =$C$24*((1+$D$9)^J4) -> 579.84671 | K24: =$C$24*((1+$D$9)^K4) -> 594.34288 | L24: =$C$24*((1+$D$9)^L4) -> 609.20145 | ... S24: =$C$24*((1+$D$9)^S4) -> 724.14908
A25: B | B25: Tổng chi phí | E25: =(E26+E49) -> 92889.524 | F25: =(F26+F49) -> 295286.9 | G25: =(G26+G49) -> 329122.65 | H25: =(H26+H49) -> 334954.89 | I25: =(I26+I49) -> 340565.95 | J25: =(J26+J49) -> 346998.35 | K25: =(K26+K49) -> 352944.29 | L25: =(L26+L49) -> 358910.47 | ... S25: =(S26+S49) -> 423441.42
A26: 1 | B26: Biến phí | E26: =(E27+SUM(E34:E48))*(1+'Thong so - Độ nhậy - Bảng 1'!$N$28) -> 78796.606 | F26: =(F27+SUM(F34:F48))*(1+'Thong so - Độ nhậy - Bảng 1'!$N$28) -> 281193.98 | G26: =(G27+SUM(G34:G48))*(1+'Thong so - Độ nhậy - Bảng 1'!$N$28) -> 314172.19 | H26: =(H27+SUM(H34:H48))*(1+'Thong so - Độ nhậy - Bảng 1'!$N$28) -> 320004.43 | I26: =(I27+SUM(I34:I48))*(1+'Thong so - Độ nhậy - Bảng 1'!$N$28) -> 325615.49 | J26: =(J27+SUM(J34:J48))*(1+'Thong so - Độ nhậy - Bảng 1'!$N$28) -> 332047.89 | K26: =(K27+SUM(K34:K48))*(1+'Thong so - Độ nhậy - Bảng 1'!$N$28) -> 337993.82 | L26: =(L27+SUM(L34:L48))*(1+'Thong so - Độ nhậy - Bảng 1'!$N$28) -> 343960.01 | ... S26: =(S27+SUM(S34:S48))*(1+'Thong so - Độ nhậy - Bảng 1'!$N$28) -> 408490.96
A27: - | B27: Nhập mua gà giống | C27: 25900 | E27: =ROUNDUP((E28*E29+E30*E31+E32*E33)*$C$27/1000000,0) -> 7416 | F27: =ROUNDUP((F28*F29+F30*F31+F32*F33)*$C$27/1000000,0) -> 7601 | G27: =ROUNDUP((G28*G29+G30*G31+G32*G33)*$C$27/1000000,0) -> 7791 | H27: =ROUNDUP((H28*H29+H30*H31+H32*H33)*$C$27/1000000,0) -> 7986 | I27: =ROUNDUP((I28*I29+I30*I31+I32*I33)*$C$27/1000000,0) -> 8186 | J27: =ROUNDUP((J28*J29+J30*J31+J32*J33)*$C$27/1000000,0) -> 8391 | K27: =ROUNDUP((K28*K29+K30*K31+K32*K33)*$C$27/1000000,0) -> 8600 | L27: =ROUNDUP((L28*L29+L30*L31+L32*L33)*$C$27/1000000,0) -> 8815 | ... S27: =ROUNDUP((S28*S29+S30*S31+S32*S33)*$C$27/1000000,0) -> 10479
B28: Số lượng gà trắng giống (con) | C28: 15790 | D28: 1667 | E28: =(C28+D28)*2 -> 34914 | F28: =E28 -> 34914 | G28: =F28 -> 34914 | H28: =G28 -> 34914 | I28: =H28 -> 34914 | J28: =I28 -> 34914 | K28: =J28 -> 34914 | L28: =K28 -> 34914 | M28: =L28 -> 34914 | ... S28: =R28 -> 34914
B29: Giá mua gà trắng giống (EUR) | C29: 4.2 | E29: =$C$29*((1+$D$9)^E4) -> 4.305 | F29: =$C$29*((1+$D$9)^F4) -> 4.412625 | G29: =$C$29*((1+$D$9)^G4) -> 4.5229406 | H29: =$C$29*((1+$D$9)^H4) -> 4.6360141 | I29: =$C$29*((1+$D$9)^I4) -> 4.7519145 | J29: =$C$29*((1+$D$9)^J4) -> 4.8707124 | K29: =$C$29*((1+$D$9)^K4) -> 4.9924802 | L29: =$C$29*((1+$D$9)^L4) -> 5.1172922 | ... S29: =$C$29*((1+$D$9)^S4) -> 6.0828523
B30: Số lượng gà màu giống - mái | C30: 12632 | E30: =$C$30*2 -> 25264 | F30: =E30 -> 25264 | G30: =F30 -> 25264 | H30: =G30 -> 25264 | I30: =H30 -> 25264 | J30: =I30 -> 25264 | K30: =J30 -> 25264 | L30: =K30 -> 25264 | M30: =L30 -> 25264 | ... S30: =R30 -> 25264
B31: Giá mua gà màu giống - mái (EUR) | C31: 4.41 | E31: =$C$31*((1+$D$9)^E4) -> 4.52025 | F31: =$C$31*((1+$D$9)^F4) -> 4.6332562 | G31: =$C$31*((1+$D$9)^G4) -> 4.7490877 | H31: =$C$31*((1+$D$9)^H4) -> 4.8678148 | I31: =$C$31*((1+$D$9)^I4) -> 4.9895102 | J31: =$C$31*((1+$D$9)^J4) -> 5.114248 | K31: =$C$31*((1+$D$9)^K4) -> 5.2421042 | L31: =$C$31*((1+$D$9)^L4) -> 5.3731568 | ... S31: =$C$31*((1+$D$9)^S4) -> 6.3869949
B32: Số lượng gà màu giống - trống | C32: 1380 | E32: =$C$32*2 -> 2760 | F32: =E32 -> 2760 | G32: =F32 -> 2760 | H32: =G32 -> 2760 | I32: =H32 -> 2760 | J32: =I32 -> 2760 | K32: =J32 -> 2760 | L32: =K32 -> 2760 | M32: =L32 -> 2760 | ... S32: =R32 -> 2760
B33: Giá mua gà màu giống - trống (EUR) | C33: 7.71 | E33: =$C$33*((1+$D$9)^E4) -> 7.90275 | F33: =$C$33*((1+$D$9)^F4) -> 8.1003187 | G33: =$C$33*((1+$D$9)^G4) -> 8.3028267 | H33: =$C$33*((1+$D$9)^H4) -> 8.5103974 | I33: =$C$33*((1+$D$9)^I4) -> 8.7231573 | J33: =$C$33*((1+$D$9)^J4) -> 8.9412363 | K33: =$C$33*((1+$D$9)^K4) -> 9.1647672 | L33: =$C$33*((1+$D$9)^L4) -> 9.3938863 | ... S33: =$C$33*((1+$D$9)^S4) -> 11.166379
A34: - | B34: Chi phí thức ăn chăn nuôi | E34: 11277.878 | F34: 22456 | G34: 23017 | H34: 23593 | I34: 23874 | J34: 24787 | K34: 25407 | L34: 26041 | M34: 26693 | N34: 27360 | O34: 28044 | P34: 28745 | Q34: 29465 | R34: 30200 | S34: 30955
A35: - | B35: Chi phí thuốc thú y | E35: 822.55248 | F35: 843.11629 | G35: 864.19419 | H35: 885.79905 | I35: 907.94403 | J35: 930.64263 | K35: 953.90869 | L35: 977.75641 | M35: 1002.2003 | N35: 1027.2553 | O35: 1052.9367 | P35: 1079.2601 | Q35: 1106.2416 | R35: 1133.8977 | S35: 1162.2451
A36: - | B36: Chi phí lương nhân viên | C36: 10 | D36: 25 | E36: =$C$36*(1+$D$13)^E4*$D$36*12 -> 3075 | F36: =$C$36*(1+$D$13)^F4*$D$36*12 -> 3151.875 | G36: =$C$36*(1+$D$13)^G4*$D$36*12 -> 3230.6719 | H36: =$C$36*(1+$D$13)^H4*$D$36*12 -> 3311.4387 | I36: =$C$36*(1+$D$13)^I4*$D$36*12 -> 3394.2246 | J36: =$C$36*(1+$D$13)^J4*$D$36*12 -> 3479.0803 | K36: =$C$36*(1+$D$13)^K4*$D$36*12 -> 3566.0573 | L36: =$C$36*(1+$D$13)^L4*$D$36*12 -> 3655.2087 | ... S36: =$C$36*(1+$D$13)^S4*$D$36*12 -> 4344.8945
A37: - | B37: Chi phí điện | E37: 165.5814 | F37: 381.10268 | G37: 390.63024 | H37: 400.396 | I37: 467.31465 | J37: 712.3234 | K37: 730.13149 | L37: 748.38477 | M37: 767.09439 | N37: 786.27175 | O37: 805.92855 | P37: 826.07676 | Q37: 846.72868 | R37: 867.8969 | S37: 889.59432
A38: - | B38: Chi phí trả cho bên chăn nuôi gà | E38: 7947.6759 | F38: 33933.36 | G38: 39098.973 | H38: 40076.447 | I38: 41078.358 | J38: 42105.317 | K38: 43157.95 | L38: 44236.899 | M38: 45342.822 | N38: 46476.392 | O38: 47638.302 | P38: 48829.259 | Q38: 50049.991 | R38: 51301.241 | S38: 52583.772
A39: - | B39: Chi phí cám cho gà gia công | E39: 37981.943 | F39: 162167.53 | G39: 186853.99 | H39: 191525.34 | I39: 196313.48 | J39: 201221.31 | K39: 206251.84 | L39: 211408.14 | M39: 216693.34 | N39: 222110.68 | O39: 227663.44 | P39: 233355.03 | Q39: 239188.91 | R39: 245168.63 | S39: 251297.85
A40: - | B40: Chi phí thuốc thú y cho gà gia công | C40: 3.3 | E40: =E12*(1+$D$13)^E4*$C$40 -> 4870.7816 | F40: =F12*(1+$D$13)^F4*$C$40 -> 15361.696 | G40: =G12*(1+$D$13)^G4*$C$40 -> 15745.738 | H40: =H12*(1+$D$13)^H4*$C$40 -> 16139.382 | I40: =I12*(1+$D$13)^I4*$C$40 -> 16542.866 | J40: =J12*(1+$D$13)^J4*$C$40 -> 16956.438 | K40: =K12*(1+$D$13)^K4*$C$40 -> 17380.349 | L40: =L12*(1+$D$13)^L4*$C$40 -> 17814.858 | ... S40: =S12*(1+$D$13)^S4*$C$40 -> 21176.267
...

Sheet Thông tin giả định
A1: BẢNG 10: MỘT SỐ THÔNG TIN GIẢ ĐỊNH
A3: STT | B3: Nội dung | C3: Gà màu | D3: Gà trắng | E3: Đơn vị tính
A4: 1 | B4: Tỷ lệ gà trống/ gà mái | C4: 1:9
A5: 2 | B5: Số trứng thu hoạch | C5: 5525 | D5: 4,6 | E5: Quả /1 tuần/1 con
A6: 3 | B6: Tỷ lệ trứng đạt/ trứng đẻ ra | C6: 0.95
A7: 4 | B7: Tỷ lệ trứng nở ra gà/ trứng vào ấp | C7: 0.85
A8: 5 | B8: Giá bán gà con giống | C8: 7,5 | E8: Nghìn đồng/ con
A9: 6 | B9: Giá bán gà thịt | D9: 24 | E9: Nghìn đồng/ kg
A10: 7 | B10: Tỷ lệ tăng giá (Tỷ lệ lạm phát) | C10: 0.025
A11: 8 | B11: Trọng lượng gà | D11: 2.747 | E11: Kg/con
A12: 9 | B12: Giá bán gà thịt tận thu | C12: 80 | E12: Nghìn đồng/ con
A13: 10 | B13: Số lượng phân gà/con/ngày | C13: 0,08 | E13: Kg
A14: 11 | B14: Giá bán trứng loại | C14: 1,3 | E14: Nghìn đồng/quả
A15: 12 | B15: Giá bán phân gà | C15: 500 | E15: Nghìn đồng/tấn
A16: 13 | B16: Đơn giá thức ăn chăn nuôi gà hậu bị | C16: 9 | E16: Nghìn đồng/kg
A17: 14 | B17: Đơn giá thức ăn chăn nuôi gà gia công | D17: 8.1 | E17: Nghìn đồng/kg
A18: 15 | B18: Chi phí lương nhân viên | C18: 10 | E18: Triệu đồng/người
A19: 16 | B19: Chi phí thuốc thú y cho gà gia công | D19: 3,3 | E19: Nghìn đồng/con
A20: 17 | B20: Chi phí trả cho bên nuôi gia công | D20: 3 | E20: Nghìn đồng/kg/con
A21: 18 | B21: Tỷ lệ gà chết sau giai đoạn hậu bị / gà mái | C21: 0.02 | D21: 0.05
A22: 19 | B22: Tỷ lệ gà chết sau giai đoạn hậu bị / gà trống | C22: 0.05 | D22: 0.1
A23: 20 | B23: Tỷ lệ gà chết sau giai đoạn đẻ/gà mái | C23: 0.06 | D23: 0.06
A24: 21 | B24: Tỷ lệ gà chết sau giai đoạn đẻ / gà trống | C24: 0.12 | D24: 0.06
A25: 22 | B25: Tỷ giá mua vào chuyển khoản | C25: 25900 | E25: VND/ EUR
A26: 23 | B26: Giá mua gà giống (CIF) - mái | C26: 4.2 | D26: 4 | E26: EUR /1 con
A27: 24 | B27: Giá mua gà giống (CIF) - trống | C27: 7.5 | D27: 4 | E27: EUR /1 con
A28: 25 | B28: Chi phí vận chuyển + Kiểm định + HQ | C28: 0.21 | D28: 0.2 | E28: EUR /1 con
A29: 26 | B29: Số tuần gà đẻ trứng trong 1 năm | C29: 40 | E29: Tuần
A30: 27 | B30: Số ngày trong 1 năm | C30: 365 | E30: Ngày
A31: 28 | B31: Chi phí dự phòng | C31: 1,0% | E31: Doanh thu chính
A32: 29 | B32: Chi phí quản lý | C32: 2,0% | E32: Doanh thu chính
A33: 30 | B33: Chi phí bán hàng | C33: 3,0% | E33: Doanh thu chính
A34: 31 | B34: Chi phí khác | C34: 0,5% | E34: Doanh thu chính

Sheet Thong so - Độ nhậy - Bảng 1
A2: BẢNG 1: CÁC THÔNG SỐ ĐẦU VÀO CỦA DỰ ÁN | S2: Bảng 8: Phân tích độ nhạy dự án
A3: Thông số về vốn đầu tư và nguồn vốn | G3: Thông số về dự án và vận hành dự án | K3: Phương án trả nợ | S3: Khi tăng lãi suất
C4: Trước thuế | D4: VAT | E4: Sau thuế | F4: Tỷ trọng | H4: Địa điểm xây dựng: | I4: Thanh Hóa | K4: I | L4: Khoản vay NHTM và nước ngoài | S4: Chỉ tiêu đánh giá | T4: 0 | U4: 0.05 | V4: 0.07 | W4: 0.1 | X4: 0.15
A5: A | B5: Tổng nhu cầu vốn trong thời gian xây dựng | C5: =(C6+C13) -> 157351 | D5: =D6+D13 -> 14157.9 | E5: =E6+E13 -> 171508.9 | F5: =C5/C5 -> 1 | H5: Chủ đầu tư: Công ty CP Nông sản Phú Gia | K5: 1 | L5: Thời gian cho vay | N5: 88 | O5: tháng | S5: NPV | T5: ='NPV (Tong dau tu) -Bảng 7'!C20 -> 68315.151 | U5: 61360.899 | V5: 58669.082 | W5: 54724.105 | X5: 48387.441
B6: Tổng mức đầu tư chưa bao gồm lãi vay | C6: =SUM(C7:C12) -> 141579 | D6: =SUM(D7:D12) -> 14157.9 | E6: =SUM(E7:E12) -> 155736.9 | F6: =C6/C5 -> 0.89976549 | H6: Thời gian xây dựng | I6: 1 | J6: năm | K6: 2 | L6: Thời gian trả nợ | N6: 73 | O6: tháng | S6: IRR | T6: ='NPV (Tong dau tu) -Bảng 7'!C21 -> 0.14357365 | U6: 0.1439131 | V6: 0.14405061 | W6: 0.14425873 | X6: 0.14461059
A7: 1 | B7: Xây lắp | C7: =54793*(1+N23) -> 54793 | D7: =C7*10% -> 5479.3 | E7: =C7+D7 -> 60272.3 | F7: =C7/C5 -> 0.34822149 | G7: I | H7: Chỉ tiêu về chế độ dự án | K7: 3 | L7: Thời gian ân hạn | N7: 15 | O7: tháng
A8: 2 | B8: Thiết bị | C8: =72519*(1+N23) -> 72519 | D8: =C8*10% -> 7251.9 | E8: =C8+D8 -> 79770.9 | F8: =C8/C5 -> 0.4608741 | G8: 1 | H8: Công suất thiết kế | I8: =60000*(1-$N$27) -> 60000 | J8: con gà bố mẹ | K8: 4 | L8: Thời gian xây dựng | N8: 15 | O8: tháng | S8: Khi giảm giá bán
A9: 3 | B9: Chi phí quản lý dự án | C9: =637*(1+N23) -> 637 | D9: =C9*10% -> 63.7 | E9: =C9+D9 -> 700.7 | F9: =C9/$C$5 -> 0.0040482742 | H9: Năm đầu | I9: 0.5 | J9: CSTK | K9: 5 | L9: Trả nợ gốc theo nguồn ngân lưu thực tế của dự án | S9: Chỉ tiêu đánh giá | T9: 0 | U9: 0.005 | V9: 0.01 | W9: 0.015 | X9: 0.02
A10: 4 | B10: Chi phí tư vấn dự án | C10: =1273*(1+N23) -> 1273 | D10: =C10*10% -> 127.3 | E10: =C10+D10 -> 1400.3 | F10: =C10/$C$5 -> 0.0080901933 | H10: Các năm tiếp theo | I10: 1 | J10: CSTK | K10: 6 | L10: Nguồn trả nợ | S10: NPV | T10: ='NPV (Tong dau tu) -Bảng 7'!C20 -> 68315.151 | U10: 58460.274 | V10: 48605.397 | W10: 38750.521 | X10: 28896.375
A11: 5 | B11: Chi phi khác | C11: 10955 | D11: =C11*10% -> 1095.5 | E11: =C11+D11 -> 12050.5 | F11: =C11/$C$5 -> 0.06962142 | G11: 2 | H11: Sản phẩm | K11: - | L11: KHCB | N11: 0.7 | O11: KHCB | S11: IRR | T11: ='NPV (Tong dau tu) -Bảng 7'!C21 -> 0.14357365 | U11: 0.1364883 | V11: 0.12925558 | W11: 0.12186402 | X11: 0.11430139
A12: 6 | B12: Dự phòng | C12: =1402*(1+N23) -> 1402 | D12: =C12*10% -> 140.2 | E12: =C12+D12 -> 1542.2 | F12: =C12/$C$5 -> 0.0089100165 | H12: Gà giống, gà thịt, trứng và phân gà | K12: - | L12: Lợi nhuận sau thuế dùng trả nợ | N12: 0.7 | O12: LT thuần
A13: 7 | B13: Lãi vay trong thời gian thi công | C13: 15772 | E13: =C13+D13 -> 15772 | F13: =C13/$C$5 -> 0.10023451 | G13: 3 | H13: Giá bán bình quân sản phẩm | K13: - | L13: Nguồn khác (.............) | N13: 0 | O13: trđ
A14: B | B14: Cơ cấu nguồn vốn | C14: =C15+C16+C21 -> 171509 | D14: Tỷ trọng | H14: Giá gà con lông màu | I14: =7500*(1-$N$24) -> 7500 | J14: VNĐ/con | K14: II | L14: Chi phí sử dụng VTC (chi phí cơ hội) | N14: =7%*(1+N25) -> 0.07 | O14: năm | S14: Khi chi phí hoạt động tăng
A15: 1 | B15: Vốn tự có tham gia dự án (không tính VAT) | C15: 51509 | D15: =C15/C14 -> 0.30032826 | H15: Giá gà thịt lông trắng | I15: =24000*(1-$N$24) -> 24000 | J15: VNĐ/kg | K15: III | L15: Lãi suất vay vốn cố định | S15: Chỉ tiêu đánh giá | T15: 0 | U15: 0.01 | V15: 0.02 | W15: 0.03 | X15: 0.04
A16: 2 | B16: Vốn vay NHTM | C16: 120000 | D16: =C16/C14 -> 0.69967174 | H16: Giá trứng gà | I16: =1300*(1-$N$24) -> 1300 | J16: VNĐ/quả | K16: 1 | L16: Vốn vay nội tệ NHTM | N16: =10%*(1+N25) -> 0.1 | O16: năm | S16: NPV | T16: ='NPV (Tong dau tu) -Bảng 7'!C20 -> 68315.151 | U16: 48772.814 | V16: 29197.347 | W16: 9633.358 | X16: -9971.4659
A17: 2.1 | B17: Cơ cấu vốn vay NHTM | C17: 120000 | H17: Giá phân gà | I17: =500000*(1-$N$24) -> 500000 | J17: VNĐ/tấn | K17: 2 | L17: Vốn vay cá nhân | S17: IRR | T17: ='NPV (Tong dau tu) -Bảng 7'!C21 -> 0.14357365 | U17: 0.12931994 | V17: 0.11445814 | W17: 0.098925084 | X17: 0.08255387
A18: * | B18: Đầu tư XDCB | C18: =C17-C19 -> 104228 | G18: II | H18: Chi phí | K18: IV | L18: Tỷ suất chiết khấu (WACC) | N18: =(D15+D21)*N14+D16*N16 -> 0.090990152 | O18: năm
A19: * | B19: Lãi vay trong thời gian xây dựng | C19: =C13 -> 15772 | G19: 1 | H19: C/Phí nguyên vật liệu đầu vào | R19: NPV | T19: Lãi suất tăng
A20: 2.2 | B20: Vay Agribank | C20: =C16 -> 120000 | H20: Gà trắng giống | I20: 4.2 | J20: EUR/con | K20: V | L20: Lãi vay vốn lưu động | N20: 0.07 | S20: ='NPV (Tong dau tu) -Bảng 7'!C20 -> 68315.151 | T20: 0 | U20: 0.05 | V20: 0.07 | W20: 0.1 | X20: 0.15
H21: Gà màu giống - mái | I21: 4.41 | J21: EUR/con | R21: Giá bán giảm | S21: 0 | T21: 68315.151 | U21: 61360.899 | V21: 58669.082 | W21: 54724.105 | X21: 48387.441
A22: Thông số về vốn lưu động | H22: Gà màu giống - trống | I22: 7.71 | J22: EUR/con | K22: Hồ sơ biến đổi | S22: 0.005 | T22: 58460.274 | U22: 51815.814 | V22: 49244.146 | W22: 45475.495 | X22: 39422.673
A23: 1 | B23: Khoản phải thu | C23: 0.01 | D23: DT | H23: Thức ăn chăn nuôi | I23: 9000 | J23: VNĐ/kg | L23: Tăng tổng mức đầu tư | N23: 0 | S23: 0.01 | T23: 48605.397 | U23: 42270.73 | V23: 39819.209 | W23: 36226.884 | X23: 30457.904
A24: 2 | B24: Khoản phải trả | C24: 0.01 | D24: CP | H24: Thuốc thú y | I24: 3300 | J24: VNĐ/con | L24: Giá bán giảm | N24: 0 | S24: 0.015 | T24: 38750.521 | U24: 32725.645 | V24: 30394.273 | W24: 26978.273 | X24: 21503.474
A25: 3 | B25: Cân đối tiền mặt | C25: 0.01 | D25: DT | G25: 2 | H25: Chi phí quản lý | I25: 0.02 | J25: Doanh thu | L25: Tăng lãi suất cho vay | N25: 0 | S25: 0.02 | T25: 28896.375 | U25: 23194.008 | V25: 20988.093 | W25: 17756.612 | X25: 12569.56
A26: 4 | B26: Vòng quay hàng tồn kho | C26: 4 | D26: Vòng/năm | G26: 3 | H26: Chi phí bán hàng | I26: 0.03 | J26: Doanh thu | S26: 0.025 | T26: 19069.65 | U26: 13678.01 | V26: 11592.608 | W26: 8537.9881 | X26: 3635.6457
A27: 5 | B27: Nhu cầu vay vốn | C27: 0.85 | D27: VLĐ | G27: 4 | H27: Chi phí khác | I27: 0.005 | J27: Doanh thu | L27: Tỷ lệ giảm sản lượng | N27: 0
A28: 6 | B28: Vòng quay VLĐ | C28: 3 | D28: Vòng/năm | G28: 5 | H28: Chi phí dự phòng | I28: 0.01 | J28: Doanh thu | L28: Chi phí nguyên liệu đầu vào tăng | N28: 0 | R28: IRR | T28: Lãi suất tăng
A29: Thông số về thuế | G29: III | H29: Khấu hao | S29: ='NPV (Tong dau tu) -Bảng 7'!C21 -> 0.14357365 | T29: 0 | U29: 0.03 | V29: =V20 -> 0.07 | W29: =W20 -> 0.1 | X29: =X20 -> 0.15
A30: 1 | B30: Thuế TNDN | C30: 0.2 | H30: Xây dựng | I30: 15 | J30: năm | K30: Hiệu quả của dự án | R30: Giá bán giảm | S30: 0 | T30: 0.14357365 | U30: 0.14377659 | V30: 0.14405061 | W30: 0.14425873 | X30: 0.14461059
H31: Thiết bị | I31: 10 | J31: năm | L31: NPV | N31: ='NPV (Tong dau tu) -Bảng 7'!C20 -> 68315.151 | S31: 0.005 | T31: 0.1364883 | U31: 0.13669745 | V31: 0.13697984 | W31: 0.13719431 | X31: 0.13755692
L32: IRR | N32: ='NPV (Tong dau tu) -Bảng 7'!C21 -> 0.14357365 | S32: 0.01 | T32: 0.12925558 | U32: 0.12947115 | V32: 0.12976222 | W32: 0.12998328 | X32: 0.13035703
S33: 0.015 | T33: 0.12186402 | U33: 0.12208625 | V33: 0.12238633 | W33: 0.12261423 | X33: 0.12300835
S34: 0.02 | T34: 0.11430139 | U34: 0.11453673 | V34: 0.11485502 | W34: 0.11509716 | X34: 0.1155073
S35: 0.025 | T35: 0.10657517 | U35: 0.10681858 | V35: 0.10714777 | W35: 0.10739819 | X35: 0.10782233

Sheet Tổng mức đầu tư-Bảng 2
A1: BẢNG 2: TỔNG MỨC ĐẦU TƯ
A2: ĐẦU TƯ XÂY DỰNG TRANG TRẠI GÀ XUÂN PHÚ
A3: GIAI ĐOẠN 1: CÔNG SUẤT 60.000 CON
A5: 1. Chi tiết các hạng chi phí của dự án đầu tư
D6: Đơn vị: triệu đồng
A7: TT | B7: Hạng mục đầu tư | C7: Giá trị đầu tư trước thuế | D7: Giá trị đầu tư sau thuế | E7: Giá trị đầu tư trước thuế | G7: Giá trị đầu tư sau thuế
A8: I | B8: Chi phí xây dựng | C8: =C9+C18 -> 54792.796 | D8: =D9+D18 -> 60272.076 | E8: =E9+E18 -> 5.4792796e+10 | H8: =SUM(H9,H16,H26) -> #REF!
A9: 1 | B9: Hạ tầng | C9: =SUM(C10:C17) -> 15965.797 | D9: =SUM(D10:D17) -> 17562.376 | E9: =SUM(E10:E17) -> 1.5965797e+10 | G9: =SUM(G10:G17) -> 1.7562376e+10 | H9: =SUM(H10:H15) -> 66158546092
B10: San nền | C10: =E10/1000000 -> 2141.8311 | D10: =G10/1000000 -> 2356.0142 | E10: 2.1418311e+09 | F10: 1.1 | G10: =E10*F10 -> 2.3560142e+09 | H10: 2408971068 | I10: =E10-H10 -> -2.6713999e+08
B11: Đường giao thông nội bộ | C11: =E11/1000000 -> 3516.9318 | D11: =G11/1000000 -> 3868.6249 | E11: 3.5169318e+09 | F11: 1.1 | G11: =E11*F11 -> 3.8686249e+09 | H11: 8473988172 | I11: =E11-H11 -> -4.9570564e+09
B12: Thoát nước ngoài nhà | C12: =E12/1000000 -> 1414.0853 | D12: =G12/1000000 -> 1555.4939 | E12: 1.4140853e+09 | F12: 1.1 | G12: =E12*F12 -> 1.5554939e+09 | H12: 11992391298 | I12: =E12-H12 -> -1.0578306e+10
B13: Bờ kè | C13: =E13/1000000 -> 3106.2386 | D13: =G13/1000000 -> 3416.8625 | E13: 3.1062386e+09 | F13: 1.1 | G13: =E13*F13 -> 3.4168625e+09 | H13: 18356999284 | I13: =E13-H13 -> -1.5250761e+10
B14: Cấp nước ngoài nhà | C14: =E14/1000000 -> 1908.7132 | D14: =G14/1000000 -> 2099.5845 | E14: 1.9087132e+09 | F14: 1.1 | G14: =E14*F14 -> 2.0995845e+09 | H14: 1442437716 | I14: =E14-H14 -> 4.6627545e+08
B15: Cấp điện, chiếu sáng ngoài nhà | C15: =E15/1000000 -> 1695.7043 | D15: =G15/1000000 -> 1865.2747 | E15: 1.6957043e+09 | F15: 1.1 | G15: =E15*F15 -> 1.8652747e+09 | H15: 23483758554 | I15: =E15-H15 -> -2.1788054e+10
B16: Cảnh quan giai đoạn 1 | C16: =E16/1000000 -> 455.34683 | D16: =G16/1000000 -> 500.88151 | E16: 4.5534683e+08 | F16: 1.1 | G16: =E16*F16 -> 5.0088151e+08 | H16: =SUM(H18:H25) -> 229870670930 | I16: =E16-H16 -> -2.2941532e+11
B17: Đường giao thông quy hoạch | C17: =E17/1000000 -> 1726.9455 | D17: =G17/1000000 -> 1899.6401 | E17: 1.7269455e+09 | F17: 1.1 | G17: =E17*F17 -> 1.8996401e+09 | H17: =SUM(H19:H26) -> #REF! | I17: =E17-H17 -> #REF!
A18: 2 | B18: Chuồng trại | C18: =SUM(C19:C29) -> 38826.999 | D18: =SUM(D19:D29) -> 42709.699 | E18: =SUM(E19:E29) -> 3.8826999e+10 | G18: =SUM(G19:G29) -> 4.2709699e+10 | H18: 10024292823 | I18: =E18-H18 -> 2.8802707e+10
B19: Nhà máy ấp trứng | C19: =E19/1000000 -> 5845.0861 | D19: =G19/1000000 -> 6429.5947 | E19: 5845086063 | F19: 1.1 | G19: =E19*F19 -> 6.4295947e+09 | H19: 1756193595 | I19: =E19-H19 -> 4088892468
B20: Trại gà hậu bị 1 | C20: =E20/1000000 -> 8206.8771 | D20: =G20/1000000 -> 9027.5649 | E20: 8.2068771e+09 | F20: 1.1 | G20: =E20*F20 -> 9.0275649e+09 | H20: 2634277000 | I20: =E20-H20 -> 5.5726001e+09
B21: Trại gà đẻ 1 | C21: =E21/1000000 -> 9819.1836 | D21: =G21/1000000 -> 10801.102 | E21: 9819183573 | F21: 1.1 | G21: =E21*F21 -> 1.0801102e+10 | H21: 23558172345 | I21: =E21-H21 -> -13738988772
B22: Trại gà đẻ 2 | C22: =E22/1000000 -> 9819.1836 | D22: =G22/1000000 -> 10801.102 | E22: 9819183573 | F22: 1.1 | G22: =E22*F22 -> 1.0801102e+10 | H22: 827181439 | I22: =E22-H22 -> 8992002134
B23: Nhà trưởng trại 1,2 (2 nhà) | C23: =E23/1000000 -> 415.78362 | D23: =G23/1000000 -> 457.36198 | E23: 4.1578362e+08 | F23: 1.1 | G23: =E23*F23 -> 4.5736198e+08 | H23: 2722478314 | I23: =E23-H23 -> -2.3066947e+09
B24: Kho chứa đệm lót cơ khí | C24: =E24/1000000 -> 465.56936 | D24: =G24/1000000 -> 512.1263 | E24: 4.6556936e+08 | F24: 1.1 | G24: =E24*F24 -> 5.121263e+08 | H24: 718510324 | I24: =E24-H24 -> -2.5294096e+08
B25: Nhà quản lý điều hành | C25: =E25/1000000 -> 749.40471 | D25: =G25/1000000 -> 824.34518 | E25: 7.4940471e+08 | F25: 1.1 | G25: =E25*F25 -> 8.2434518e+08 | H25: 187629565090 | I25: =E25-H25 -> -1.8688016e+11
B26: Nhà ở công nhân | C26: =E26/1000000 -> 660.76984 | D26: =G26/1000000 -> 726.84682 | E26: 6.6076984e+08 | F26: 1.1 | G26: =E26*F26 -> 7.2684682e+08 | H26: =SUM(H27,#REF!) -> #REF! | I26: =E26-H26 -> #REF!
B27: Hố sát trùng (3 bể) | C27: =E27/1000000 -> 81.443005 | D27: =G27/1000000 -> 89.587306 | E27: 81443005 | F27: 1.1 | G27: =E27*F27 -> 89587306 | H27: =SUM(H28:H41) -> 7504156462 | I27: =E27-H27 -> -7.4227135e+09
B28: Cổng, tường rào | C28: =E28/1000000 -> 1905.3393 | D28: =G28/1000000 -> 2095.8733 | E28: 1.9053393e+09 | F28: 1.1 | G28: =E28*F28 -> 2.0958733e+09 | H28: 1543794234 | I28: =E28-H28 -> 3.615451e+08
B29: Bể ngầm (bể ngầm, bể cứu hỏa, hẩm phân) | C29: =E29/1000000 -> 858.35922 | D29: =G29/1000000 -> 944.19514 | E29: 8.5835922e+08 | F29: 1.1 | G29: =E29*F29 -> 9.4419514e+08 | H29: 1039368753 | I29: =E29-H29 -> -1.8100954e+08
A30: II | B30: Thiết bị | C30: =SUM(C31:C35)-C36 -> 72518.543 | D30: =SUM(D31:D35)-D36 -> 79770.397 | E30: =SUM(E31:E35)-E36 -> 7.2518543e+10 | G30: =SUM(G31:G35)-G36 -> 7.9770397e+10
B31: Thiết bị trại gà | C31: =E31/1000000 -> 61931.288 | D31: =G31/1000000 -> 68124.417 | E31: 61931288016 | F31: 1.1 | G31: =E31*F31 -> 6.8124417e+10
B32: Thiết bị trạm biến áp | C32: =E32/1000000 -> 2728.8039 | D32: =G32/1000000 -> 3001.6843 | E32: 2728803925 | F32: 1.1 | G32: =E32*F32 -> 3.0016843e+09
B33: Máy phát điện (SL: 2 cái) | C33: =E33/1000000 -> 2181.8182 | D33: =G33/1000000 -> 2400 | E33: 2.1818182e+09 | F33: 1.1 | G33: =E33*F33 -> 2400000000
B34: Thuế Nhập Khẩu máy móc TB (3% GTNK) | C34: =E34/1000000 -> 2223.3685 | D34: =G34/1000000 -> 2445.7053 | E34: 2.2233685e+09 | F34: 1.1 | G34: =E34*F34 -> 2.4457053e+09
B35: Dự phòng thiết bị | C35: =E35/1000000 -> 6906.5279 | D35: =G35/1000000 -> 7597.1806 | E35: 6.9065279e+09 | F35: 1.1 | G35: =E35*F35 -> 7.5971806e+09
B36: Tiết kiệm chi phí | C36: =E36/1000000 -> 3453.2639 | D36: =G36/1000000 -> 3798.5903 | E36: 3.4532639e+09 | F36: 1.1 | G36: =E36*F36 -> 3.7985903e+09
A37: III | B37: Chi phí quản lý dự án GĐ1 | C37: =E37/1000000 -> 636.55832 | D37: =G37/1000000 -> 700.21415 | E37: 6.3655832e+08 | F37: 1.1 | G37: =E37*F37 -> 7.0021415e+08
A38: IV | B38: Chi phí tư vấn | C38: =E38/1000000 -> 1272.7951 | D38: =G38/1000000 -> 1400.0746 | E38: 1.2727951e+09 | F38: 1.1 | G38: =E38*F38 -> 1.4000746e+09
A39: V | B39: Chi phí khác | C39: =E39/1000000 -> 10955.794 | D39: =G39/1000000 -> 12051.374 | E39: 1.0955794e+10 | F39: 1.1 | G39: =E39*F39 -> 1.2051374e+10
A40: VI | B40: Chi phí dự phòng GĐ1 | C40: =E40/1000000 -> 1401.7681 | D40: =G40/1000000 -> 1541.9449 | E40: 1.4017681e+09 | F40: 1.1 | G40: =E40*F40 -> 1.5419449e+09 | H40: 3041651267 | I40: =E40-H40 -> -1.6398831e+09
A41: VII | B41: Chi phí lãi vay vốn hóa | C41: =E41/1000000 -> 15772.5 | D41: =C41 -> 15772.5 | E41: 15772500000 | G41: =E41 -> 15772500000 | H41: 1879342208 | I41: =E41-H41 -> 13893157792
...

Sheet Khấu hao- Bảng 3
A1: Bảng 3: Kế hoạch khấu hao
E2: 2018 | F2: 2019 | G2: 2020 | H2: 2021 | I2: 2022 | J2: 2023 | K2: 2024 | L2: 2025 | M2: 2026 | N2: 2027 | O2: 2028 | P2: 2029 | Q2: 2030 | R2: 2031 | S2: 2032
A3: TT | B3: Chỉ tiêu | C3: Giá trị | D3: Thời gian khấu hao | E3: Năm hoạt động
E4: 1 | F4: 2 | G4: 3 | H4: 4 | I4: 5 | J4: 6 | K4: 7 | L4: 8 | M4: 9 | N4: 10 | O4: 11 | P4: 12 | Q4: 13 | R4: 14 | S4: 15
A5: 1 | B5: Hạng mục chuồng trại | C5: ='[4]Tổng mức đầu tư-Bảng 1'!D47 -> 91738.183 | D5: 15 | E5: =C5/D5 -> 6115.8789 | F5: =E5 -> 6115.8789 | G5: =F5 -> 6115.8789 | H5: =G5 -> 6115.8789 | I5: =H5 -> 6115.8789 | J5: =I5 -> 6115.8789 | K5: =J5 -> 6115.8789 | L5: =K5 -> 6115.8789 | M5: =L5 -> 6115.8789 | ... S5: =R5 -> 6115.8789 | T5: =SUM(E5:S5) -> 91738.183
A6: 2 | B6: Hạng mục thiết bị | C6: ='[4]Tổng mức đầu tư-Bảng 1'!D48 -> 79770.397 | D6: 10 | E6: =C6/D6 -> 7977.0397 | F6: =E6 -> 7977.0397 | G6: =F6 -> 7977.0397 | H6: =G6 -> 7977.0397 | I6: =H6 -> 7977.0397 | J6: =I6 -> 7977.0397 | K6: =J6 -> 7977.0397 | L6: =K6 -> 7977.0397 | M6: =L6 -> 7977.0397 | N6: =M6 -> 7977.0397 | O6: 0 | P6: 0 | Q6: 0 | R6: 0 | S6: 0 | T6: =SUM(E6:S6) -> 79770.397
B7: Tái đầu tư thiết bị | C7: =C6 -> 79770.397 | D7: 10 | O7: =$C$7/$D$7 -> 7977.0397 | P7: =$C$7/$D$7 -> 7977.0397 | Q7: =$C$7/$D$7 -> 7977.0397 | R7: =$C$7/$D$7 -> 7977.0397 | S7: =$C$7/$D$7 -> 7977.0397 | T7: =SUM(E7:S7) -> 39885.198
B8: Tổng cộng | C8: =SUM(C5:C6) -> 171508.58 | E8: =SUM(E5:E7) -> 14092.919 | F8: =SUM(F5:F7) -> 14092.919 | G8: =SUM(G5:G7) -> 14092.919 | H8: =SUM(H5:H7) -> 14092.919 | I8: =SUM(I5:I7) -> 14092.919 | J8: =SUM(J5:J7) -> 14092.919 | K8: =SUM(K5:K7) -> 14092.919 | L8: =SUM(L5:L7) -> 14092.919 | ... S8: =SUM(S5:S7) -> 14092.919 | T8: =SUM(E8:S8) -> 211393.78

Sheet KQKD- Bảng 4 
A1: Bảng 4: Bảng dự kiến Doanh thu, chi phí của dự án
D2: 2017 | E2: 2018 | F2: 2019 | G2: 2020 | H2: 2021 | I2: 2022 | J2: 2023 | K2: 2024 | L2: 2025 | M2: 2026 | N2: 2027 | O2: 2028 | P2: 2029 | Q2: 2030 | R2: 2031 | S2: 2032
A3: TT | B3: Chỉ tiêu | D3: Năm thực hiện dự án
D4: 0 | E4: 1 | F4: 2 | G4: 3 | H4: 4 | I4: 5 | J4: 6 | K4: 7 | L4: 8 | M4: 9 | N4: 10 | O4: 11 | P4: 12 | Q4: 13 | R4: 14 | S4: 15
A5: A | B5: Tổng Doanh thu | E5: =E6+E16+E19+E22 -> 71514.893 | F5: =F6+F16+F19+F22 -> 300751.18 | G5: =G6+G16+G19+G22 -> 342853.23 | H5: =H6+H16+H19+H22 -> 351424.56 | I5: =I6+I16+I19+I22 -> 360210.17 | J5: =J6+J16+J19+J22 -> 369215.43 | K5: =K6+K16+K19+K22 -> 378445.81 | L5: =L6+L16+L19+L22 -> 387906.96 | ... S5: =S6+S16+S19+S22 -> 461099.48
A6: 1 | B6: Doanh thu chính | E6: =E11+E7 -> 70864.519 | F6: =F11+F7 -> 294479.08 | G6: =G11+G7 -> 336424.32 | H6: =H11+H7 -> 344834.93 | I6: =I11+I7 -> 353455.8 | J6: =J11+J7 -> 362292.2 | K6: =K11+K7 -> 371349.5 | L6: =L11+L7 -> 380633.24 | ... S6: =S11+S7 -> 452453.31
A7: 1.1 | B7: Doanh thu bán gà giống lông màu | E7: =E10 -> 9466.055 | F7: =F10 -> 32452.106 | G7: =G10 -> 34528.979 | H7: =H10 -> 35392.204 | I7: =I10 -> 36277.009 | J7: =J10 -> 37183.934 | K7: =K10 -> 38113.532 | L7: =L10 -> 39066.37 | ... S7: =S10 -> 46437.638
B8: Số lượng gà con lông màu (Nghìn con) | E8: 1391.9685 | F8: 4282.98 | G8: 4282.98 | H8: 4282.98 | I8: 4282.98 | J8: 4282.98 | K8: 4282.98 | L8: 4282.98 | M8: 4282.98 | N8: 4282.98 | O8: 4282.98 | P8: 4282.98 | Q8: 4282.98 | R8: 4282.98 | S8: 4282.98
B9: Đơn giá bán gà con (Tỷ lệ tăng giá 2,5%) | C9: =7.5*(1-'Thong so - Độ nhậy - Bảng 1'!N24) -> 7.5 | D9: 0.025 | E9: =$C$9*((1+$D$9)^E4) -> 7.6875 | F9: =$C$9*((1+$D$9)^F4) -> 7.8796875 | G9: =$C$9*((1+$D$9)^G4) -> 8.0766797 | H9: =$C$9*((1+$D$9)^H4) -> 8.2785967 | I9: =$C$9*((1+$D$9)^I4) -> 8.4855616 | J9: =$C$9*((1+$D$9)^J4) -> 8.6977006 | K9: =$C$9*((1+$D$9)^K4) -> 8.9151432 | L9: =$C$9*((1+$D$9)^L4) -> 9.1380217 | ... S9: =$C$9*((1+$D$9)^S4) -> 10.862236
B10: Doanh thu bán gà giống thực tế (Độ trễ: 03 tuần) | E10: =E8*E9*23/26 -> 9466.055 | F10: =E9*E8*3/26+F8*F9*37/40 -> 32452.106 | G10: =F9*F8*3/40+G8*G9*37/40 -> 34528.979 | H10: =G9*G8*3/40+H8*H9*37/40 -> 35392.204 | I10: =H9*H8*3/40+I8*I9*37/40 -> 36277.009 | J10: =I9*I8*3/40+J8*J9*37/40 -> 37183.934 | K10: =J9*J8*3/40+K8*K9*37/40 -> 38113.532 | L10: =K9*K8*3/40+L8*L9*37/40 -> 39066.37 | M10: =L9*L8*3/40+M8*M9*37/40 -> 40043.03 | N10: =M9*M8*3/40+N8*N9*37/40 -> 41044.105 | ... S10: =R9*R8*3/40+S8*S9*37/40 -> 46437.638
A11: 1.2 | B11: Doanh thu bán gà lông trắng gia công | E11: =E15 -> 61398.464 | F11: =F15 -> 262026.97 | G11: =G15 -> 301895.34 | H11: =H15 -> 309442.73 | I11: =I15 -> 317178.8 | J11: =J15 -> 325108.27 | K11: =K15 -> 333235.97 | L11: =L15 -> 341566.87 | ... S11: =S15 -> 406015.67
B12: Số lượng gà con lông trắng (Nghìn con) | C12: 2.747 | E12: 1439.9946 | F12: 4430.7525 | G12: 4430.7525 | H12: 4430.7525 | I12: 4430.7525 | J12: 4430.7525 | K12: 4430.7525 | L12: 4430.7525 | M12: 4430.7525 | N12: 4430.7525 | O12: 4430.7525 | P12: 4430.7525 | Q12: 4430.7525 | R12: 4430.7525 | S12: 4430.7525
B13: Đơn giá bán gà thịt (Tỷ lệ tăng giá 2,5%) | C13: =24*(1-'Thong so - Độ nhậy - Bảng 1'!N24) -> 24 | D13: =D9 -> 0.025 | E13: =$C$13*$C$12*((1+$D$13)^E4) -> 67.5762 | F13: =$C$13*$C$12*((1+$D$13)^F4) -> 69.265605 | G13: =$C$13*$C$12*((1+$D$13)^G4) -> 70.997245 | H13: =$C$13*$C$12*((1+$D$13)^H4) -> 72.772176 | I13: =$C$13*$C$12*((1+$D$13)^I4) -> 74.591481 | J13: =$C$13*$C$12*((1+$D$13)^J4) -> 76.456268 | K13: =$C$13*$C$12*((1+$D$13)^K4) -> 78.367674 | L13: =$C$13*$C$12*((1+$D$13)^L4) -> 80.326866 | ... S13: =$C$13*$C$12*((1+$D$13)^S4) -> 95.483402
B14: Hao hụt định mức | C14: 0.035 | E14: =E13*E12*(1-$C$14) -> 93903.533 | F14: =F13*F12*(1-$C$14) -> 296157.3 | G14: =G13*G12*(1-$C$14) -> 303561.23 | H14: =H13*H12*(1-$C$14) -> 311150.26 | I14: =I13*I12*(1-$C$14) -> 318929.02 | J14: =J13*J12*(1-$C$14) -> 326902.24 | K14: =K13*K12*(1-$C$14) -> 335074.8 | L14: =L13*L12*(1-$C$14) -> 343451.67 | ... S14: =S13*S12*(1-$C$14) -> 408256.1
B15: Doanh số bán gia công thực tế (Độ trễ: 09 tuần) | E15: =E14*17/26 -> 61398.464 | F15: =E14/26*9+F14*31/40 -> 262026.97 | G15: =F14/40*9+G14*31/40 -> 301895.34 | H15: =G14/40*9+H14*31/40 -> 309442.73 | I15: =H14/40*9+I14*31/40 -> 317178.8 | J15: =I14/40*9+J14*31/40 -> 325108.27 | K15: =J14/40*9+K14*31/40 -> 333235.97 | L15: =K14/40*9+L14*31/40 -> 341566.87 | M15: =L14/40*9+M14*31/40 -> 350106.04 | N15: =M14/40*9+N14*31/40 -> 358858.69 | ... S15: =R14/40*9+S14*31/40 -> 406015.67
A16: 2 | B16: Doanh thu từ bán trứng loại | E16: =E17*E18 -> 233.65887 | F16: =F17*F18 -> 736.92413 | G16: =G17*G18 -> 755.34724 | H16: =H17*H18 -> 774.23092 | I16: =I17*I18 -> 793.58669 | J16: =J17*J18 -> 813.42636 | K16: =K17*K18 -> 833.76202 | L16: =L17*L18 -> 854.60607 | ... S16: =S17*S18 -> 1015.8581
B17: Số lượng trứng loại | E17: 175.35375 | F17: 539.55 | G17: 539.55 | H17: 539.55 | I17: 539.55 | J17: 539.55 | K17: 539.55 | L17: 539.55 | M17: 539.55 | N17: 539.55 | O17: 539.55 | P17: 539.55 | Q17: 539.55 | R17: 539.55 | S17: 539.55
B18: Đơn giá (Tỷ lệ tăng giá 2,5%) | C18: 1.3 | E18: =$C$18*((1+$D$9)^E4) -> 1.3325 | F18: =$C$18*((1+$D$9)^F4) -> 1.3658125 | G18: =$C$18*((1+$D$9)^G4) -> 1.3999578 | H18: =$C$18*((1+$D$9)^H4) -> 1.4349568 | I18: =$C$18*((1+$D$9)^I4) -> 1.4708307 | J18: =$C$18*((1+$D$9)^J4) -> 1.5076014 | K18: =$C$18*((1+$D$9)^K4) -> 1.5452915 | L18: =$C$18*((1+$D$9)^L4) -> 1.5839238 | ... S18: =$C$18*((1+$D$9)^S4) -> 1.8827876
A19: 3 | B19: Doanh thu từ bán gà thịt tận thu | E19: =E20*E21 -> 0 | F19: =F20*F21 -> 4680.9126 | G19: =G20*G21 -> 4797.9354 | H19: =H20*H21 -> 4917.8838 | I19: =I20*I21 -> 5040.8309 | J19: =J20*J21 -> 5166.8517 | K19: =K20*K21 -> 5296.023 | L19: =L20*L21 -> 5428.4235 | ... S19: =S20*S21 -> 6452.6897
B20: Số lượng gà bán thịt tận thu | E20: 0 | F20: 55.692 | G20: 55.692 | H20: 55.692 | I20: 55.692 | J20: 55.692 | K20: 55.692 | L20: 55.692 | M20: 55.692 | N20: 55.692 | O20: 55.692 | P20: 55.692 | Q20: 55.692 | R20: 55.692 | S20: 55.692
B21: Đơn giá | C21: 80 | E21: =$C$21*((1+$D$9)^E4) -> 82 | F21: =$C$21*((1+$D$9)^F4) -> 84.05 | G21: =$C$21*((1+$D$9)^G4) -> 86.15125 | H21: =$C$21*((1+$D$9)^H4) -> 88.305031 | I21: =$C$21*((1+$D$9)^I4) -> 90.512657 | J21: =$C$21*((1+$D$9)^J4) -> 92.775473 | K21: =$C$21*((1+$D$9)^K4) -> 95.09486 | L21: =$C$21*((1+$D$9)^L4) -> 97.472232 | ... S21: =$C$21*((1+$D$9)^S4) -> 115.86385
A22: 4 | B22: Doanh thu từ bán phân gà | E22: =E23*E24 -> 416.71539 | F22: =F23*F24 -> 854.26655 | G22: =G23*G24 -> 875.62321 | H22: =H23*H24 -> 897.51379 | I22: =I23*I24 -> 919.95164 | J22: =J23*J24 -> 942.95043 | K22: =K23*K24 -> 966.52419 | L22: =L23*L24 -> 990.68729 | ... S22: =S23*S24 -> 1177.6159
B23: Khối lượng phân gà thu được | C23: tấn | E23: 0.8131032 | F23: 1.6262064 | G23: 1.6262064 | H23: 1.6262064 | I23: 1.6262064 | J23: 1.6262064 | K23: 1.6262064 | L23: 1.6262064 | M23: 1.6262064 | N23: 1.6262064 | O23: 1.6262064 | P23: 1.6262064 | Q23: 1.6262064 | R23: 1.6262064 | S23: 1.6262064
B24: Đơn giá (Tỷ lệ tăng giá 2,5%) | C24: 500 | E24: =$C$24*((1+$D$9)^E4) -> 512.5 | F24: =$C$24*((1+$D$9)^F4) -> 525.3125 | G24: =$C$24*((1+$D$9)^G4) -> 538.44531 | H24: =$C$24*((1+$D$9)^H4) -> 551.90645 | I24: =$C$24*((1+$D$9)^I4) -> 565.70411 | J24: =$C$24*((1+$D$9)^J4) -> 579.84671 | K24: =$C$24*((1+$D$9)^K4) -> 594.34288 | L24: =$C$24*((1+$D$9)^L4) -> 609.20145 | ... S24: =$C$24*((1+$D$9)^S4) -> 724.14908
A25: B | B25: Tổng chi phí | E25: =(E26+E49) -> 92889.524 | F25: =(F26+F49) -> 295286.9 | G25: =(G26+G49) -> 329122.65 | H25: =(H26+H49) -> 334954.89 | I25: =(I26+I49) -> 340565.95 | J25: =(J26+J49) -> 346998.35 | K25: =(K26+K49) -> 352944.29 | L25: =(L26+L49) -> 358910.47 | ... S25: =(S26+S49) -> 423441.42
A26: 1 | B26: Biến phí | E26: =(E27+SUM(E34:E48))*(1+'Thong so - Độ nhậy - Bảng 1'!$N$28) -> 78796.606 | F26: =(F27+SUM(F34:F48))*(1+'Thong so - Độ nhậy - Bảng 1'!$N$28) -> 281193.98 | G26: =(G27+SUM(G34:G48))*(1+'Thong so - Độ nhậy - Bảng 1'!$N$28) -> 314172.19 | H26: =(H27+SUM(H34:H48))*(1+'Thong so - Độ nhậy - Bảng 1'!$N$28) -> 320004.43 | I26: =(I27+SUM(I34:I48))*(1+'Thong so - Độ nhậy - Bảng 1'!$N$28) -> 325615.49 | J26: =(J27+SUM(J34:J48))*(1+'Thong so - Độ nhậy - Bảng 1'!$N$28) -> 332047.89 | K26: =(K27+SUM(K34:K48))*(1+'Thong so - Độ nhậy - Bảng 1'!$N$28) -> 337993.82 | L26: =(L27+SUM(L34:L48))*(1+'Thong so - Độ nhậy - Bảng 1'!$N$28) -> 343960.01 | ... S26: =(S27+SUM(S34:S48))*(1+'Thong so - Độ nhậy - Bảng 1'!$N$28) -> 408490.96
A27: - | B27: Nhập mua gà giống | C27: 25900 | E27: =ROUNDUP((E28*E29+E30*E31+E32*E33)*$C$27/1000000,0) -> 7416 | F27: =ROUNDUP((F28*F29+F30*F31+F32*F33)*$C$27/1000000,0) -> 7601 | G27: =ROUNDUP((G28*G29+G30*G31+G32*G33)*$C$27/1000000,0) -> 7791 | H27: =ROUNDUP((H28*H29+H30*H31+H32*H33)*$C$27/1000000,0) -> 7986 | I27: =ROUNDUP((I28*I29+I30*I31+I32*I33)*$C$27/1000000,0) -> 8186 | J27: =ROUNDUP((J28*J29+J30*J31+J32*J33)*$C$27/1000000,0) -> 8391 | K27: =ROUNDUP((K28*K29+K30*K31+K32*K33)*$C$27/1000000,0) -> 8600 | L27: =ROUNDUP((L28*L29+L30*L31+L32*L33)*$C$27/1000000,0) -> 8815 | ... S27: =ROUNDUP((S28*S29+S30*S31+S32*S33)*$C$27/1000000,0) -> 10479
B28: Số lượng gà trắng giống (con) | C28: 15790 | D28: 1667 | E28: =(C28+D28)*2 -> 34914 | F28: =E28 -> 34914 | G28: =F28 -> 34914 | H28: =G28 -> 34914 | I28: =H28 -> 34914 | J28: =I28 -> 34914 | K28: =J28 -> 34914 | L28: =K28 -> 34914 | M28: =L28 -> 34914 | ... S28: =R28 -> 34914
B29: Giá mua gà trắng giống (EUR) | C29: 4.2 | E29: =$C$29*((1+$D$9)^E4) -> 4.305 | F29: =$C$29*((1+$D$9)^F4) -> 4.412625 | G29: =$C$29*((1+$D$9)^G4) -> 4.5229406 | H29: =$C$29*((1+$D$9)^H4) -> 4.6360141 | I29: =$C$29*((1+$D$9)^I4) -> 4.7519145 | J29: =$C$29*((1+$D$9)^J4) -> 4.8707124 | K29: =$C$29*((1+$D$9)^K4) -> 4.9924802 | L29: =$C$29*((1+$D$9)^L4) -> 5.1172922 | ... S29: =$C$29*((1+$D$9)^S4) -> 6.0828523
B30: Số lượng gà màu giống - mái | C30: 12632 | E30: =$C$30*2 -> 25264 | F30: =E30 -> 25264 | G30: =F30 -> 25264 | H30: =G30 -> 25264 | I30: =H30 -> 25264 | J30: =I30 -> 25264 | K30: =J30 -> 25264 | L30: =K30 -> 25264 | M30: =L30 -> 25264 | ... S30: =R30 -> 25264
B31: Giá mua gà màu giống - mái (EUR) | C31: 4.41 | E31: =$C$31*((1+$D$9)^E4) -> 4.52025 | F31: =$C$31*((1+$D$9)^F4) -> 4.6332562 | G31: =$C$31*((1+$D$9)^G4) -> 4.7490877 | H31: =$C$31*((1+$D$9)^H4) -> 4.8678148 | I31: =$C$31*((1+$D$9)^I4) -> 4.9895102 | J31: =$C$31*((1+$D$9)^J4) -> 5.114248 | K31: =$C$31*((1+$D$9)^K4) -> 5.2421042 | L31: =$C$31*((1+$D$9)^L4) -> 5.3731568 | ... S31: =$C$31*((1+$D$9)^S4) -> 6.3869949
B32: Số lượng gà màu giống - trống | C32: 1380 | E32: =$C$32*2 -> 2760 | F32: =E32 -> 2760 | G32: =F32 -> 2760 | H32: =G32 -> 2760 | I32: =H32 -> 2760 | J32: =I32 -> 2760 | K32: =J32 -> 2760 | L32: =K32 -> 2760 | M32: =L32 -> 2760 | ... S32: =R32 -> 2760
B33: Giá mua gà màu giống - trống (EUR) | C33: 7.71 | E33: =$C$33*((1+$D$9)^E4) -> 7.90275 | F33: =$C$33*((1+$D$9)^F4) -> 8.1003187 | G33: =$C$33*((1+$D$9)^G4) -> 8.3028267 | H33: =$C$33*((1+$D$9)^H4) -> 8.5103974 | I33: =$C$33*((1+$D$9)^I4) -> 8.7231573 | J33: =$C$33*((1+$D$9)^J4) -> 8.9412363 | K33: =$C$33*((1+$D$9)^K4) -> 9.1647672 | L33: =$C$33*((1+$D$9)^L4) -> 9.3938863 | ... S33: =$C$33*((1+$D$9)^S4) -> 11.166379
A34: - | B34: Chi phí thức ăn chăn nuôi | E34: 11277.878 | F34: 22456 | G34: 23017 | H34: 23593 | I34: 23874 | J34: 24787 | K34: 25407 | L34: 26041 | M34: 26693 | N34: 27360 | O34: 28044 | P34: 28745 | Q34: 29465 | R34: 30200 | S34: 30955
A35: - | B35: Chi phí thuốc thú y | E35: 822.55248 | F35: 843.11629 | G35: 864.19419 | H35: 885.79905 | I35: 907.94403 | J35: 930.64263 | K35: 953.90869 | L35: 977.75641 | M35: 1002.2003 | N35: 1027.2553 | O35: 1052.9367 | P35: 1079.2601 | Q35: 1106.2416 | R35: 1133.8977 | S35: 1162.2451
A36: - | B36: Chi phí lương nhân viên | C36: 10 | D36: 25 | E36: =$C$36*(1+$D$13)^E4*$D$36*12 -> 3075 | F36: =$C$36*(1+$D$13)^F4*$D$36*12 -> 3151.875 | G36: =$C$36*(1+$D$13)^G4*$D$36*12 -> 3230.6719 | H36: =$C$36*(1+$D$13)^H4*$D$36*12 -> 3311.4387 | I36: =$C$36*(1+$D$13)^I4*$D$36*12 -> 3394.2246 | J36: =$C$36*(1+$D$13)^J4*$D$36*12 -> 3479.0803 | K36: =$C$36*(1+$D$13)^K4*$D$36*12 -> 3566.0573 | L36: =$C$36*(1+$D$13)^L4*$D$36*12 -> 3655.2087 | ... S36: =$C$36*(1+$D$13)^S4*$D$36*12 -> 4344.8945
A37: - | B37: Chi phí điện | E37: 165.5814 | F37: 381.10268 | G37: 390.63024 | H37: 400.396 | I37: 467.31465 | J37: 712.3234 | K37: 730.13149 | L37: 748.38477 | M37: 767.09439 | N37: 786.27175 | O37: 805.92855 | P37: 826.07676 | Q37: 846.72868 | R37: 867.8969 | S37: 889.59432
A38: - | B38: Chi phí trả cho bên chăn nuôi gà | E38: 7947.6759 | F38: 33933.36 | G38: 39098.973 | H38: 40076.447 | I38: 41078.358 | J38: 42105.317 | K38: 43157.95 | L38: 44236.899 | M38: 45342.822 | N38: 46476.392 | O38: 47638.302 | P38: 48829.259 | Q38: 50049.991 | R38: 51301.241 | S38: 52583.772
A39: - | B39: Chi phí cám cho gà gia công | E39: 37981.943 | F39: 162167.53 | G39: 186853.99 | H39: 191525.34 | I39: 196313.48 | J39: 201221.31 | K39: 206251.84 | L39: 211408.14 | M39: 216693.34 | N39: 222110.68 | O39: 227663.44 | P39: 233355.03 | Q39: 239188.91 | R39: 245168.63 | S39: 251297.85
A40: - | B40: Chi phí thuốc thú y cho gà gia công | C40: 3.3 | E40: =E12*(1+$D$13)^E4*$C$40 -> 4870.7816 | F40: =F12*(1+$D$13)^F4*$C$40 -> 15361.696 | G40: =G12*(1+$D$13)^G4*$C$40 -> 15745.738 | H40: =H12*(1+$D$13)^H4*$C$40 -> 16139.382 | I40: =I12*(1+$D$13)^I4*$C$40 -> 16542.866 | J40: =J12*(1+$D$13)^J4*$C$40 -> 16956.438 | K40: =K12*(1+$D$13)^K4*$C$40 -> 17380.349 | L40: =L12*(1+$D$13)^L4*$C$40 -> 17814.858 | ... S40: =S12*(1+$D$13)^S4*$C$40 -> 21176.267
...

Sheet KH trả nợ-Bảng 5
A1: BẢNG 5: KẾ HOẠCH TRẢ NỢ GỐC
B2: 0 | C2: 1 | D2: 2 | E2: 3 | F2: 4 | G2: 5 | H2: 6 | I2: 7 | J2: 8 | K2: 9 | L2: 10 | M2: 10 | N2: 11 | O2: 14 | P2: 15 | Q2: 16
A3: Thông số | B3: Năm XDCB | C3: Năm 2018 | D3: Năm 2019 | E3: Năm 2020 | F3: Năm 2021 | G3: Năm 2022 | H3: Năm 2023 | I3: Năm 2024 | J3: Năm 2025 | K3: Năm 2026 | L3: Năm 2027 | M3: Năm 2028 | N3: Năm 2029 | O3: Năm 2030 | P3: Năm 2031 | Q3: Năm 2032
A4: I. Nguồn trả nợ gốc | C4: =SUM(C5:C6) -> -11509.588 | D4: =SUM(D5:D6) -> 12925.041 | E4: =SUM(E5:E6) -> 17554.166 | F4: =SUM(F5:F6) -> 19088.059 | G4: =SUM(G5:G6) -> 20865.806 | H4: =SUM(H5:H6) -> 22306.608 | I4: =SUM(I5:I6) -> 24145.899 | J4: =SUM(J5:J6) -> 26103.075 | ... Q4: =SUM(Q5:Q6) -> 30953.552
A5: 1. Khấu hao cơ bản | C5: ='Thong so - Độ nhậy - Bảng 1'!$N$11*'Khấu hao- Bảng 3'!E8 -> 9865.043 | D5: ='Thong so - Độ nhậy - Bảng 1'!$N$11*'Khấu hao- Bảng 3'!F8 -> 9865.043 | E5: ='Thong so - Độ nhậy - Bảng 1'!$N$11*'Khấu hao- Bảng 3'!G8 -> 9865.043 | F5: ='Thong so - Độ nhậy - Bảng 1'!$N$11*'Khấu hao- Bảng 3'!H8 -> 9865.043 | G5: ='Thong so - Độ nhậy - Bảng 1'!$N$11*'Khấu hao- Bảng 3'!I8 -> 9865.043 | H5: ='Thong so - Độ nhậy - Bảng 1'!$N$11*'Khấu hao- Bảng 3'!J8 -> 9865.043 | I5: ='Thong so - Độ nhậy - Bảng 1'!$N$11*'Khấu hao- Bảng 3'!K8 -> 9865.043 | J5: ='Thong so - Độ nhậy - Bảng 1'!$N$11*'Khấu hao- Bảng 3'!L8 -> 9865.043 | ... Q5: ='Thong so - Độ nhậy - Bảng 1'!$N$11*'Khấu hao- Bảng 3'!S8 -> 9865.043
A6: 2. Lợi nhuận sau thuế | C6: =IF('KQKD- Bảng 4 '!E54>0,'KQKD- Bảng 4 '!E54*'Thong so - Độ nhậy - Bảng 1'!$N$12,'KQKD- Bảng 4 '!E54) -> -21374.631 | D6: =IF('KQKD- Bảng 4 '!F54>0,'KQKD- Bảng 4 '!F54*'Thong so - Độ nhậy - Bảng 1'!$N$12,'KQKD- Bảng 4 '!F54) -> 3059.9978 | E6: =IF('KQKD- Bảng 4 '!G54>0,'KQKD- Bảng 4 '!G54*'Thong so - Độ nhậy - Bảng 1'!$N$12,'KQKD- Bảng 4 '!G54) -> 7689.1234 | F6: =IF('KQKD- Bảng 4 '!H54>0,'KQKD- Bảng 4 '!H54*'Thong so - Độ nhậy - Bảng 1'!$N$12,'KQKD- Bảng 4 '!H54) -> 9223.0156 | G6: =IF('KQKD- Bảng 4 '!I54>0,'KQKD- Bảng 4 '!I54*'Thong so - Độ nhậy - Bảng 1'!$N$12,'KQKD- Bảng 4 '!I54) -> 11000.763 | H6: =IF('KQKD- Bảng 4 '!J54>0,'KQKD- Bảng 4 '!J54*'Thong so - Độ nhậy - Bảng 1'!$N$12,'KQKD- Bảng 4 '!J54) -> 12441.565 | I6: =IF('KQKD- Bảng 4 '!K54>0,'KQKD- Bảng 4 '!K54*'Thong so - Độ nhậy - Bảng 1'!$N$12,'KQKD- Bảng 4 '!K54) -> 14280.856 | J6: =IF('KQKD- Bảng 4 '!L54>0,'KQKD- Bảng 4 '!L54*'Thong so - Độ nhậy - Bảng 1'!$N$12,'KQKD- Bảng 4 '!L54) -> 16238.032 | ... Q6: =IF('KQKD- Bảng 4 '!S54>0,'KQKD- Bảng 4 '!S54*'Thong so - Độ nhậy - Bảng 1'!$N$12,'KQKD- Bảng 4 '!S54) -> 21088.509
A7: Cân đối trả nợ
A8: II. Trả nợ Agribank | C8: =IF(C9<C11,C9/C11*12/100+C3-1,0) -> 0 | D8: =IF(D9<D4,IF(C13>0,D9/D4+C2,0),0) -> 0 | E8: =IF(E9<E4,IF(D13>0,E9/E4+D2,0),0) -> 0 | F8: =IF(F9<F4,IF(E13>0,F9/F4+E2,0),0) -> 0 | G8: =IF(G9<G4,IF(F13>0,G9/G4+F2,0),0) -> 0 | H8: =IF(H9<H4,IF(G13>0,H9/H4+G2,0),0) -> 0 | I8: =IF(I9<I4,IF(H13>0,I9/I4+H2,0),0) -> 0 | J8: =IF(J9<J4,IF(I13>0,J9/J4+I2,0),0) -> 7.1193124 | K8: =IF(K9<K4,IF(J13>0,K9/K4+J2,0),0) -> 8
A9: 1. Dư nợ đầu kỳ | B9: 120000 | C9: =B13 -> 120000 | D9: =C13 -> 120000 | E9: =D13 -> 107074.96 | F9: =E13 -> 89520.793 | G9: =F13 -> 70432.734 | H9: =G13 -> 49566.928 | I9: =H13 -> 27260.32 | J9: =I13 -> 3114.421
A10: 2. Giải ngân trong kỳ
A11: 3. Trả Gốc | D11: =D4 -> 12925.041 | E11: =E4 -> 17554.166 | F11: =F4 -> 19088.059 | G11: =G4 -> 20865.806 | H11: =H4 -> 22306.608 | I11: =I4 -> 24145.899 | J11: 3114
A12: 4. Lãi vay | D12: =D9*'Thong so - Độ nhậy - Bảng 1'!$N$16 -> 12000 | E12: =E9*'Thong so - Độ nhậy - Bảng 1'!$N$16 -> 10707.496 | F12: =F9*'Thong so - Độ nhậy - Bảng 1'!$N$16 -> 8952.0793 | G12: =G9*'Thong so - Độ nhậy - Bảng 1'!$N$16 -> 7043.2734 | H12: =H9*'Thong so - Độ nhậy - Bảng 1'!$N$16 -> 4956.6928 | I12: =I9*'Thong so - Độ nhậy - Bảng 1'!$N$16 -> 2726.032 | J12: =J9*'Thong so - Độ nhậy - Bảng 1'!$N$16 -> 311.4421
A13: 4. Dư nợ cuối kỳ | B13: =IF(B9>B11,B9-B11,0) -> 120000 | C13: =IF(C9>C11,C9-C11,0) -> 120000 | D13: =IF(D9>D11,D9-D11,0)+D10 -> 107074.96 | E13: =IF(E9>E11,E9-E11,0) -> 89520.793 | F13: =IF(F9>F11,F9-F11,0) -> 70432.734 | G13: =IF(G9>G11,G9-G11,0) -> 49566.928 | H13: =IF(H9>H11,H9-H11,0) -> 27260.32 | I13: =IF(I9>I11,I9-I11,0) -> 3114.421 | J13: =IF(J9>J11,J9-J11,0) -> 0.42099263
A14: III. Tổng trả nợ gốc | C14: =C15+C16 -> 0 | D14: =D15+D16 -> 12925.041 | E14: =E15+E16 -> 17554.166 | F14: =F15+F16 -> 19088.059 | G14: =G15+G16 -> 20865.806 | H14: =H15+H16 -> 22306.608 | I14: =I15+I16 -> 24145.899 | J14: =J15+J16 -> 3114
A15: 1. Gốc | C15: =C11 -> 0 | D15: =D11 -> 12925.041 | E15: =E11 -> 17554.166 | F15: =F11 -> 19088.059 | G15: =G11 -> 20865.806 | H15: =H11 -> 22306.608 | I15: =I11 -> 24145.899 | J15: =J11 -> 3114
A16: 2. Lãi vay
A17: Thời hạn cho vay | B17: 73 | C17: tháng (không kể thời gian ân hạn)
B18: 88 | C18: tháng (cả thời gian ân hạn)

Sheet VLD- Bảng 6
A2: BẢNG 6: NHU CẦU VỐN LƯU ĐỘNG
A3: STT | B3: KHOẢN MỤC | C3: Năm XDCB | D3: NĂM HOẠT ĐỘNG
D4: 1 | E4: 2 | F4: 3 | G4: 4 | H4: 5 | I4: 6 | J4: 7 | K4: 8 | L4: 9 | M4: 10 | N4: 11 | O4: 12 | P4: 13 | Q4: 14 | R4: 15
A5: 1 | B5: Doanh thu | D5: ='KQKD- Bảng 4 '!E5 -> 71514.893 | E5: ='KQKD- Bảng 4 '!F5 -> 300751.18 | F5: ='KQKD- Bảng 4 '!G5 -> 342853.23 | G5: ='KQKD- Bảng 4 '!H5 -> 351424.56 | H5: ='KQKD- Bảng 4 '!I5 -> 360210.17 | I5: ='KQKD- Bảng 4 '!J5 -> 369215.43 | J5: ='KQKD- Bảng 4 '!K5 -> 378445.81 | K5: ='KQKD- Bảng 4 '!L5 -> 387906.96 | ... R5: ='KQKD- Bảng 4 '!S5 -> 461099.48
A6: 2 | B6: Chi phí hoạt động | D6: ='KQKD- Bảng 4 '!E36+'KQKD- Bảng 4 '!E37+'KQKD- Bảng 4 '!E38+'KQKD- Bảng 4 '!E43+'KQKD- Bảng 4 '!E44+'KQKD- Bảng 4 '!E45+'KQKD- Bảng 4 '!E46+'KQKD- Bảng 4 '!E47+'KQKD- Bảng 4 '!E48 -> 16427.451 | E6: ='KQKD- Bảng 4 '!F36+'KQKD- Bảng 4 '!F37+'KQKD- Bảng 4 '!F38+'KQKD- Bảng 4 '!F43+'KQKD- Bảng 4 '!F44+'KQKD- Bảng 4 '!F45+'KQKD- Bảng 4 '!F46+'KQKD- Bảng 4 '!F47+'KQKD- Bảng 4 '!F48 -> 57340.478 | F6: ='KQKD- Bảng 4 '!G36+'KQKD- Bảng 4 '!G37+'KQKD- Bảng 4 '!G38+'KQKD- Bảng 4 '!G43+'KQKD- Bảng 4 '!G44+'KQKD- Bảng 4 '!G45+'KQKD- Bảng 4 '!G46+'KQKD- Bảng 4 '!G47+'KQKD- Bảng 4 '!G48 -> 65338.856 | G6: ='KQKD- Bảng 4 '!H36+'KQKD- Bảng 4 '!H37+'KQKD- Bảng 4 '!H38+'KQKD- Bảng 4 '!H43+'KQKD- Bảng 4 '!H44+'KQKD- Bảng 4 '!H45+'KQKD- Bảng 4 '!H46+'KQKD- Bảng 4 '!H47+'KQKD- Bảng 4 '!H48 -> 66972.552 | H6: ='KQKD- Bảng 4 '!I36+'KQKD- Bảng 4 '!I37+'KQKD- Bảng 4 '!I38+'KQKD- Bảng 4 '!I43+'KQKD- Bảng 4 '!I44+'KQKD- Bảng 4 '!I45+'KQKD- Bảng 4 '!I46+'KQKD- Bảng 4 '!I47+'KQKD- Bảng 4 '!I48 -> 68703.525 | I6: ='KQKD- Bảng 4 '!J36+'KQKD- Bảng 4 '!J37+'KQKD- Bảng 4 '!J38+'KQKD- Bảng 4 '!J43+'KQKD- Bảng 4 '!J44+'KQKD- Bảng 4 '!J45+'KQKD- Bảng 4 '!J46+'KQKD- Bảng 4 '!J47+'KQKD- Bảng 4 '!J48 -> 70654.714 | J6: ='KQKD- Bảng 4 '!K36+'KQKD- Bảng 4 '!K37+'KQKD- Bảng 4 '!K38+'KQKD- Bảng 4 '!K43+'KQKD- Bảng 4 '!K44+'KQKD- Bảng 4 '!K45+'KQKD- Bảng 4 '!K46+'KQKD- Bảng 4 '!K47+'KQKD- Bảng 4 '!K48 -> 72420.857 | K6: ='KQKD- Bảng 4 '!L36+'KQKD- Bảng 4 '!L37+'KQKD- Bảng 4 '!L38+'KQKD- Bảng 4 '!L43+'KQKD- Bảng 4 '!L44+'KQKD- Bảng 4 '!L45+'KQKD- Bảng 4 '!L46+'KQKD- Bảng 4 '!L47+'KQKD- Bảng 4 '!L48 -> 74231.653 | ... R6: ='KQKD- Bảng 4 '!S36+'KQKD- Bảng 4 '!S37+'KQKD- Bảng 4 '!S38+'KQKD- Bảng 4 '!S43+'KQKD- Bảng 4 '!S44+'KQKD- Bảng 4 '!S45+'KQKD- Bảng 4 '!S46+'KQKD- Bảng 4 '!S47+'KQKD- Bảng 4 '!S48 -> 88237.726
A7: 3 | B7: Chi phí nguyên, nhiên vật liệu | D7: ='KQKD- Bảng 4 '!E27+'KQKD- Bảng 4 '!E34+'KQKD- Bảng 4 '!E35+'KQKD- Bảng 4 '!E39+'KQKD- Bảng 4 '!E40 -> 62369.155 | E7: ='KQKD- Bảng 4 '!F27+'KQKD- Bảng 4 '!F34+'KQKD- Bảng 4 '!F35+'KQKD- Bảng 4 '!F39+'KQKD- Bảng 4 '!F40 -> 208429.34 | F7: ='KQKD- Bảng 4 '!G27+'KQKD- Bảng 4 '!G34+'KQKD- Bảng 4 '!G35+'KQKD- Bảng 4 '!G39+'KQKD- Bảng 4 '!G40 -> 234271.92 | G7: ='KQKD- Bảng 4 '!H27+'KQKD- Bảng 4 '!H34+'KQKD- Bảng 4 '!H35+'KQKD- Bảng 4 '!H39+'KQKD- Bảng 4 '!H40 -> 240129.52 | H7: ='KQKD- Bảng 4 '!I27+'KQKD- Bảng 4 '!I34+'KQKD- Bảng 4 '!I35+'KQKD- Bảng 4 '!I39+'KQKD- Bảng 4 '!I40 -> 245824.29 | I7: ='KQKD- Bảng 4 '!J27+'KQKD- Bảng 4 '!J34+'KQKD- Bảng 4 '!J35+'KQKD- Bảng 4 '!J39+'KQKD- Bảng 4 '!J40 -> 252286.39 | J7: ='KQKD- Bảng 4 '!K27+'KQKD- Bảng 4 '!K34+'KQKD- Bảng 4 '!K35+'KQKD- Bảng 4 '!K39+'KQKD- Bảng 4 '!K40 -> 258593.1 | K7: ='KQKD- Bảng 4 '!L27+'KQKD- Bảng 4 '!L34+'KQKD- Bảng 4 '!L35+'KQKD- Bảng 4 '!L39+'KQKD- Bảng 4 '!L40 -> 265056.75 | ... R7: ='KQKD- Bảng 4 '!S27+'KQKD- Bảng 4 '!S34+'KQKD- Bảng 4 '!S35+'KQKD- Bảng 4 '!S39+'KQKD- Bảng 4 '!S40 -> 315070.36
A8: 4 | B8: Các khoản phải thu AR | D8: =D5*'Thong so - Độ nhậy - Bảng 1'!$C$23 -> 715.14893 | E8: =E5*'Thong so - Độ nhậy - Bảng 1'!$C$23 -> 3007.5118 | F8: =F5*'Thong so - Độ nhậy - Bảng 1'!$C$23 -> 3428.5323 | G8: =G5*'Thong so - Độ nhậy - Bảng 1'!$C$23 -> 3514.2456 | H8: =H5*'Thong so - Độ nhậy - Bảng 1'!$C$23 -> 3602.1017 | I8: =I5*'Thong so - Độ nhậy - Bảng 1'!$C$23 -> 3692.1543 | J8: =J5*'Thong so - Độ nhậy - Bảng 1'!$C$23 -> 3784.4581 | K8: =K5*'Thong so - Độ nhậy - Bảng 1'!$C$23 -> 3879.0696 | ... R8: =R5*'Thong so - Độ nhậy - Bảng 1'!$C$23 -> 4610.9948
A9: 5 | B9: DAR = AR1 - AR2 | D9: =C8-D8 -> -715.14893 | E9: =D8-E8 -> -2292.3629 | F9: =E8-F8 -> -421.02046 | G9: =F8-G8 -> -85.713307 | H9: =G8-H8 -> -87.85614 | I9: =H8-I8 -> -90.052543 | J9: =I8-J8 -> -92.303857 | K9: =J8-K8 -> -94.611453 | ... R9: =Q8-R8 -> -112.46329
A10: 6 | B10: Các khoản phải trả AP | D10: =D6*'Thong so - Độ nhậy - Bảng 1'!$C$24 -> 164.27451 | E10: =E6*'Thong so - Độ nhậy - Bảng 1'!$C$24 -> 573.40478 | F10: =F6*'Thong so - Độ nhậy - Bảng 1'!$C$24 -> 653.38856 | G10: =G6*'Thong so - Độ nhậy - Bảng 1'!$C$24 -> 669.72552 | H10: =H6*'Thong so - Độ nhậy - Bảng 1'!$C$24 -> 687.03525 | I10: =I6*'Thong so - Độ nhậy - Bảng 1'!$C$24 -> 706.54714 | J10: =J6*'Thong so - Độ nhậy - Bảng 1'!$C$24 -> 724.20857 | K10: =K6*'Thong so - Độ nhậy - Bảng 1'!$C$24 -> 742.31653 | ... R10: =R6*'Thong so - Độ nhậy - Bảng 1'!$C$24 -> 882.37726
A11: 7 | B11: DAP = AP1 - AP2 | D11: =C10-D10 -> -164.27451 | E11: =D10-E10 -> -409.13027 | F11: =E10-F10 -> -79.983778 | G11: =F10-G10 -> -16.336964 | H11: =G10-H10 -> -17.309726 | I11: =H10-I10 -> -19.51189 | J11: =I10-J10 -> -17.661429 | K11: =J10-K10 -> -18.107964 | ... R11: =Q10-R10 -> -21.525055
A12: 8 | B12: Cân đối tiền mặt CB | D12: =D5*'Thong so - Độ nhậy - Bảng 1'!$C$25 -> 715.14893 | E12: =E5*'Thong so - Độ nhậy - Bảng 1'!$C$25 -> 3007.5118 | F12: =F5*'Thong so - Độ nhậy - Bảng 1'!$C$25 -> 3428.5323 | G12: =G5*'Thong so - Độ nhậy - Bảng 1'!$C$25 -> 3514.2456 | H12: =H5*'Thong so - Độ nhậy - Bảng 1'!$C$25 -> 3602.1017 | I12: =I5*'Thong so - Độ nhậy - Bảng 1'!$C$25 -> 3692.1543 | J12: =J5*'Thong so - Độ nhậy - Bảng 1'!$C$25 -> 3784.4581 | K12: =K5*'Thong so - Độ nhậy - Bảng 1'!$C$25 -> 3879.0696 | ... R12: =R5*'Thong so - Độ nhậy - Bảng 1'!$C$25 -> 4610.9948
A13: 9 | B13: DCB = CB2 - CB1 | D13: =-C12+D12 -> 715.14893 | E13: =-D12+E12 -> 2292.3629 | F13: =-E12+F12 -> 421.02046 | G13: =-F12+G12 -> 85.713307 | H13: =-G12+H12 -> 87.85614 | I13: =-H12+I12 -> 90.052543 | J13: =-I12+J12 -> 92.303857 | K13: =-J12+K12 -> 94.611453 | ... R13: =-Q12+R12 -> 112.46329
A14: 10 | B14: Tồn kho hàng hóa | D14: =D7/'Thong so - Độ nhậy - Bảng 1'!$C$26 -> 15592.289 | E14: =E7/'Thong so - Độ nhậy - Bảng 1'!$C$26 -> 52107.335 | F14: =F7/'Thong so - Độ nhậy - Bảng 1'!$C$26 -> 58567.981 | G14: =G7/'Thong so - Độ nhậy - Bảng 1'!$C$26 -> 60032.381 | H14: =H7/'Thong so - Độ nhậy - Bảng 1'!$C$26 -> 61456.071 | I14: =I7/'Thong so - Độ nhậy - Bảng 1'!$C$26 -> 63071.598 | J14: =J7/'Thong so - Độ nhậy - Bảng 1'!$C$26 -> 64648.276 | K14: =K7/'Thong so - Độ nhậy - Bảng 1'!$C$26 -> 66264.189 | ... R14: =R7/'Thong so - Độ nhậy - Bảng 1'!$C$26 -> 78767.589
A15: 11 | B15: Vốn lưu động (4-6+8+10) | D15: =D8-D10+D12+D14 -> 16858.312 | E15: =E8-E10+E12+E14 -> 57548.954 | F15: =F8-F10+F12+F14 -> 64771.657 | G15: =G8-G10+G12+G14 -> 66391.146 | H15: =H8-H10+H12+H14 -> 67973.24 | I15: =I8-I10+I12+I14 -> 69749.36 | J15: =J8-J10+J12+J14 -> 71492.983 | K15: =K8-K10+K12+K14 -> 73280.011 | ... R15: =R8-R10+R12+R14 -> 87107.202
A16: 12 | B16: Nhu cầu vay vốn | D16: ='Thong so - Độ nhậy - Bảng 1'!$C$27*D15 -> 14329.565 | E16: ='Thong so - Độ nhậy - Bảng 1'!$C$27*E15 -> 48916.611 | F16: ='Thong so - Độ nhậy - Bảng 1'!$C$27*F15 -> 55055.908 | G16: ='Thong so - Độ nhậy - Bảng 1'!$C$27*G15 -> 56432.474 | H16: ='Thong so - Độ nhậy - Bảng 1'!$C$27*H15 -> 57777.254 | I16: ='Thong so - Độ nhậy - Bảng 1'!$C$27*I15 -> 59286.956 | J16: ='Thong so - Độ nhậy - Bảng 1'!$C$27*J15 -> 60769.036 | K16: ='Thong so - Độ nhậy - Bảng 1'!$C$27*K15 -> 62288.01 | ... R16: ='Thong so - Độ nhậy - Bảng 1'!$C$27*R15 -> 74041.121
A17: 12 | B17: Lãi vay VLĐ | D17: =D16*'Thong so - Độ nhậy - Bảng 1'!$N$20 -> 1003.0696 | E17: =E16*'Thong so - Độ nhậy - Bảng 1'!$N$20 -> 3424.1628 | F17: =F16*'Thong so - Độ nhậy - Bảng 1'!$N$20 -> 3853.9136 | G17: =G16*'Thong so - Độ nhậy - Bảng 1'!$N$20 -> 3950.2732 | H17: =H16*'Thong so - Độ nhậy - Bảng 1'!$N$20 -> 4044.4078 | I17: =I16*'Thong so - Độ nhậy - Bảng 1'!$N$20 -> 4150.0869 | J17: =J16*'Thong so - Độ nhậy - Bảng 1'!$N$20 -> 4253.8325 | K17: =K16*'Thong so - Độ nhậy - Bảng 1'!$N$20 -> 4360.1607 | ... R17: =R16*'Thong so - Độ nhậy - Bảng 1'!$N$20 -> 5182.8785

Sheet NPV (Tong dau tu) -Bảng 7
A1: BẢNG 7: DÒNG TIỀN THEO QUAN ĐIỂM TỔNG ĐẦU TƯ (TIP)
A3: STT | B3: KHOẢN MỤC | C3: 2017 | D3: 2018 | E3: 2019 | F3: 2020 | G3: 2021 | H3: 2022 | I3: 2023 | J3: 2024 | K3: 2025 | L3: 2026 | M3: 2027 | N3: 2028 | O3: 2029 | P3: 2030 | Q3: 2031 | R3: 2032
A5: 1 | B5: Dòng tiền vào
B6: - Doanh thu | D6: ='KQKD- Bảng 4 '!E5 -> 71514.893 | E6: ='KQKD- Bảng 4 '!F5 -> 300751.18 | F6: ='KQKD- Bảng 4 '!G5 -> 342853.23 | G6: ='KQKD- Bảng 4 '!H5 -> 351424.56 | H6: ='KQKD- Bảng 4 '!I5 -> 360210.17 | I6: ='KQKD- Bảng 4 '!J5 -> 369215.43 | J6: ='KQKD- Bảng 4 '!K5 -> 378445.81 | K6: ='KQKD- Bảng 4 '!L5 -> 387906.96 | ... R6: ='KQKD- Bảng 4 '!S5 -> 461099.48
