Workbook

Sheet Thong so - Độ nhậy - Bảng 1
A2: BẢNG 1: CÁC THÔNG SỐ ĐẦU VÀO CỦA DỰ ÁN | S2: Bảng 8: Phân tích độ nhạy dự án
A3: Thông số về vốn đầu tư và nguồn vốn | G3: Thông số về dự án và vận hành dự án | K3: Phương án trả nợ | S3: Khi tăng lãi suất
C4: Trước thuế | D4: VAT | E4: Sau thuế | F4: Tỷ trọng | H4: Địa điểm xây dựng: | I4: Thanh Hóa | K4: I | L4: Khoản vay NHTM và nước ngoài | S4: Chỉ tiêu đánh giá | T4: 0 | U4: 0.05 | V4: 0.07 | W4: 0.1 | X4: 0.15
A5: A | B5: Tổng nhu cầu vốn trong thời gian xây dựng | C5: =(C6+C14) -> 425835 | D5: =D6+D14 -> 40105.8 | E5: =E6+E14 -> 465940.8 | F5: =C5/C5 -> 1 | H5: Chủ đầu tư: Công ty TNHH XD & sản xuất VLXD Bình Minh | K5: 1 | L5: Thời gian cho vay | N5: =N6+N7 -> 14.5 | S5: NPV | T5: ='NPV (Tong dau tu) -Bảng 7'!C19 -> 103242.43 | U5: 82607.187 | V5: 74777.613 | W5: 63483.103 | X5: 45773.203
B6: Tổng mức đầu tư chưa bao gồm lãi vay | C6: =SUM(C7:C13) -> 401058 | D6: =SUM(D7:D13) -> 40105.8 | E6: =SUM(E7:E13) -> 441163.8 | F6: =C6/C5 -> 0.94181549 | H6: Thời gian xây dựng | I6: 2 | J6: năm | K6: 2 | L6: Thời gian trả nợ | N6: ='KH trả nợ-Bảng 5'!B17 -> 13 | O6: năm | S6: IRR | T6: ='NPV (Tong dau tu) -Bảng 7'!C20 -> 0.11932043 | U6: 0.11981137 | V6: 0.12000845 | W6: 0.12031155 | X6: 0.12083173
A7: 1 | B7: Xây lắp | C7: =304728*(1+N25) -> 304728 | D7: =C7*10% -> 30472.8 | E7: =C7+D7 -> 335200.8 | F7: =C7/C5 -> 0.71560111 | G7: I | H7: Chỉ tiêu về chế độ dự án | K7: 3 | L7: Thời gian ân hạn | N7: =N8 -> 1.5 | O7: năm
A8: 2 | B8: Thiết bị | C8: =27877*(1+N25) -> 27877 | D8: =C8*10% -> 2787.7 | E8: =C8+D8 -> 30664.7 | F8: =C8/C5 -> 0.065464323 | G8: 1 | H8: Công suất thiết kế | I8: =60000*(1-$N$29) -> 60000 | J8: m3/ngày đêm | K8: 4 | L8: Thời gian xây dựng | N8: 1.5 | O8: năm | S8: Khi giảm giá bán
A9: 3 | B9: Chi phí quản lý dự án | C9: =3453*(1+N25) -> 3453 | D9: =C9*10% -> 345.3 | E9: =C9+D9 -> 3798.3 | F9: =C9/$C$5 -> 0.0081087745 | H9: 2 Năm đầu | I9: 0.4 | J9: CSTK | K9: 5 | L9: Trả nợ gốc theo nguồn ngân lưu thực tế của dự án | S9: Chỉ tiêu đánh giá | T9: 0 | U9: 0.01 | V9: 0.02 | W9: 0.03 | X9: 0.04
A10: 4 | B10: Chi phí đền bù, GPMB | C10: =7273*(1+N25) -> 7273 | D10: =C10*10% -> 727.3 | E10: =C10+D10 -> 8000.3 | F10: =C10/$C$5 -> 0.017079385 | H10: 2 Năm tiếp theo | I10: 0.45 | J10: CSTK | K10: 6 | L10: Nguồn trả nợ | S10: NPV | T10: ='NPV (Tong dau tu) -Bảng 7'!C19 -> 103242.43 | U10: 94343.159 | V10: 85392.324 | W10: 76441.489 | X10: 67490.654
A11: 5 | B11: Chi phí tư vấn dự án | C11: =10325*(1+N25) -> 10325 | D11: =C11*10% -> 1032.5 | E11: =C11+D11 -> 11357.5 | F11: =C11/$C$5 -> 0.02424648 | H11: Năm thứ 16 | I11: 0.9 | J11: CSTK | K11: - | L11: KHCB | N11: 0.8 | O11: KHCB | S11: IRR | T11: ='NPV (Tong dau tu) -Bảng 7'!C20 -> 0.11932043 | U11: 0.11727029 | V11: 0.11518703 | W11: 0.11308521 | X11: 0.11096401
A12: 6 | B12: Chi phi khác | C12: =2018*(1+N25) -> 2018 | D12: =C12*10% -> 201.8 | E12: =C12+D12 -> 2219.8 | F12: =C12/$C$5 -> 0.0047389247 | H12: Năm thứ 17 | I12: 0.95 | J12: CSTK | K12: - | L12: Lợi nhuận sau thuế dùng trả nợ | N12: =D17 -> 0.69275496 | O12: LT thuần
A13: 7 | B13: Dự phòng | C13: =45384*(1+N25) -> 45384 | D13: =C13*10% -> 4538.4 | E13: =C13+D13 -> 49922.4 | F13: =C13/$C$5 -> 0.10657649 | H13: Từ năm thứ 18 | I13: 1 | J13: CSTK | K13: - | L13: Nguồn khác (.............) | N13: 0 | O13: trđ
A14: 8 | B14: Lãi vay trong thời gian thi công | C14: =24777*(1+N25) -> 24777 | E14: =C14+D14 -> 24777 | F14: =C14/$C$5 -> 0.058184508 | G14: 2 | H14: Sản phẩm | K14: II | L14: Chi phí sử dụng VTC (chi phí cơ hội) | N14: =7%*(1+N27) -> 0.07 | O14: năm | S14: Khi chi phí hoạt động tăng
A15: B | B15: Cơ cấu nguồn vốn | C15: =C16+C17+C22 -> 425836 | D15: Tỷ trọng | H15: Nước sạch | K15: III | L15: Lãi suất vay vốn cố định | S15: Chỉ tiêu đánh giá | T15: 0 | U15: 0.02 | V15: 0.03 | W15: 0.05 | X15: 0.06
A16: 1 | B16: Vốn tự có tham gia dự án (không tính VAT) | C16: 130836 | D16: =C16/C15 -> 0.30724504 | G16: 3 | H16: Giá bán bình quân sản phẩm | K16: 1 | L16: Vốn vay nội tệ NHTM | N16: =10.5%*(1+N27) -> 0.105 | O16: năm | S16: NPV | T16: ='NPV (Tong dau tu) -Bảng 7'!C19 -> 103242.43 | U16: 95778.249 | V16: 92020.377 | W16: 84504.633 | X16: 80746.761
A17: 2 | B17: Vốn vay NHTM | C17: 295000 | D17: =C17/C15 -> 0.69275496 | H17: Giá nước cho sinh hoạt | I17: =9500*(1-$N$26) -> 9500 | J17: VNĐ/m3 | K17: 2 | L17: Vốn vay cá nhân | S17: IRR | T17: ='NPV (Tong dau tu) -Bảng 7'!C20 -> 0.11932043 | U17: 0.11760176 | V17: 0.11673015 | W17: 0.11497748 | X17: 0.11409629
A18: 2.1 | B18: Cơ cấu vốn vay NHTM | C18: =C17 -> 295000 | H18: Giá nước cho thương mại | I18: =12000*(1-$N$26) -> 12000 | J18: VNĐ/m3 | K18: IV | L18: Tỷ suất chiết khấu (WACC) | N18: =(D16+D22)*N14+D17*N16 -> 0.094246424 | O18: năm
A19: * | B19: Đầu tư XDCB | C19: =C18-C20 -> 270223 | H19: Giá nước cho công cộng và công sở | I19: =12000*(1-$N$26) -> 12000 | J19: VNĐ/m3 | R19: NPV | T19: Sản lượng giảm
A20: * | B20: Lãi vay trong thời gian xây dựng | C20: =C14 -> 24777 | H20: Giá nước cho công nghiệp | I20: =10000*(1-$N$26) -> 10000 | J20: VNĐ/m3 | K20: V | L20: Lãi vay vốn lưu động | N20: 0.08 | S20: ='NPV (Tong dau tu) -Bảng 7'!C19 -> 103242.43 | T20: 0 | U20: 0.03 | V20: 0.05 | W20: 0.07 | X20: 0.08
A21: 2.2 | B21: Vay Agribank | C21: =C17 -> 295000 | G21: II | H21: Chi phí | K21: - | O21: năm | R21: Giá bán giảm | S21: 0 | T21: 103242.43 | U21: 90347.31 | V21: 81716.188 | W21: 73085.066 | X21: 68769.505
G22: 1 | H22: C/Phí nguyên vật liệu đầu vào | L22: Thời gian xây dựng | N22: 1.5 | O22: năm | S22: 0.01 | T22: 94343.159 | U22: 81665.001 | V22: 73212.895 | W22: 64760.79 | X22: 60519.695
A23: Thông số về vốn lưu động | H23: Nước thô | I23: =(1+$N$30)*1100 -> 1100 | J23: VNĐ/m3 | S23: 0.02 | T23: 85392.324 | U23: 72982.691 | V23: 64709.602 | W23: 56372.83 | X23: 52155.106
A24: 1 | B24: Khoản phải thu | C24: 0.01 | D24: DT | H24: Điện | I24: =(1+$N$30)*403 -> 403 | J24: VNĐ/m3 | K24: Hồ sơ biến đổi | S24: 0.03 | T24: 76441.489 | U24: 64300.381 | V24: 56137.34 | W24: 47865.019 | X24: 43724.389
A25: 2 | B25: Khoản phải trả | C25: 0.01 | D25: CP | H25: Hóa chất | I25: =(1+$N$30)*366 -> 366 | J25: VNĐ/m3 | L25: Tăng tổng mức đầu tư | N25: 0 | S25: 0.04 | T25: 67490.654 | U25: 55538.63 | V25: 47440.647 | W25: 39342.664 | X25: 35293.672
A26: 3 | B26: Cân đối tiền mặt | C26: 0.01 | D26: DT | H26: Đường ống nước thô | I26: =(1+$N$30)*1500 -> 1500 | J26: VNĐ/m3 | L26: Giá bán giảm | N26: 0 | S26: 0.05 | T26: 58491.23 | U26: 46649.722 | V26: 38735.015 | W26: 30820.308 | X26: 26821.06
A27: 4 | B27: Vòng quay hàng tồn kho | C27: 3 | D27: Vòng/năm | G27: 2 | H27: Chi phí sản xuất chung | I27: =83 -> 83 | J27: VNĐ/m3 | L27: Tăng lãi suất cho vay | N27: 0
A28: 5 | B28: Nhu cầu vay vốn | C28: 0.9 | D28: VLĐ | G28: 3 | H28: Chi phí quản lý doanh nghiệp | I28: =222 -> 222 | J28: VNĐ/m3 | R28: IRR | T28: Sản lượng giảm
A29: 6 | B29: Vòng quay VLĐ | C29: 2 | D29: Vòng/năm | G29: 4 | H29: Chi phí lương nhân công | I29: =258 -> 258 | J29: VNĐ/m3 | L29: Tỷ lệ giảm sản lượng | N29: 0 | S29: ='NPV (Tong dau tu) -Bảng 7'!C20 -> 0.11932043 | T29: 0 | U29: 0.03 | V29: =V20 -> 0.05 | W29: =W20 -> 0.07 | X29: =X20 -> 0.08
A30: Thông số về thuế | G30: 5 | H30: Chi phí bán hàng | I30: =219 -> 219 | J30: VNĐ/m3 | L30: Chi phí nguyên liệu đầu vào tăng | N30: 0 | R30: Giá bán giảm | S30: 0 | T30: 0.11932043 | U30: 0.11634386 | V30: 0.11432814 | W30: 0.11229469 | X30: 0.11127109
A31: 1 | B31: Thuế TNDN | C31: 0.2 | G31: III | H31: Khấu hao | S31: 0.01 | T31: 0.11727029 | U31: 0.11431531 | V31: 0.11232421 | W31: 0.1103154 | X31: 0.10929998
A32: - | H32: Xây dựng | I32: 25 | J32: năm | K32: Hiệu quả của dự án | S32: 0.02 | T32: 0.11518703 | U32: 0.11226898 | V32: 0.11030252 | W32: 0.10830087 | X32: 0.10727999
A33: - | H33: Công nghệ | I33: 25 | J33: năm | L33: NPV | N33: ='NPV (Tong dau tu) -Bảng 7'!C19 -> 103242.43 | S33: 0.03 | T33: 0.11308521 | U33: 0.11020411 | V33: 0.10824336 | W33: 0.10623593 | X33: 0.10522441
H34: Thiết bị và điện | I34: 15 | J34: năm | L34: IRR | N34: ='NPV (Tong dau tu) -Bảng 7'!C20 -> 0.11932043 | S34: 0.04 | T34: 0.11096401 | U34: 0.10809809 | V34: 0.1061318 | W34: 0.10414853 | X34: 0.10315031
H35: Vòng đời dự án | I35: 50 | J35: năm | L35: Thời gian hoàn vốn | N35: ='NPV (Tong dau tu) -Bảng 7'!C23 -> 17 | S35: 0.05 | T35: 0.1088092 | U35: 0.10593817 | V35: 0.10399845 | W35: 0.10204176 | X35: 0.1010459
B55: 2.1 | C55: Cơ cấu vốn vay NHTM | D55: =D56+D57 -> 163033
B56: * | C56: Đầu tư XDCB | D56: 163033 | E56: =D56/D52 -> #DIV/0!
B57: * | C57: Lãi vay trong thời gian xây dựng | D57: =D51 -> 0 | E57: =D57/D52 -> #DIV/0!
B58: 2.2 | C58: Vay Agribank CN Long Biên | D58: =D54 -> 0

Sheet Tổng mức đầu tư
A1: Bảng 2: THÔNG SỐ DỰ ÁN
A2: ĐẦU TƯ NHÀ MÁY NƯỚC SẠCH BÌNH MINH GIAI ĐOẠN II - CÔNG SUẤT 60.000 M3/NGÀY ĐÊM
D3: Đơn vị: triệu đồng
A4: 1. Chi tiết các hạng chi phí của dự án đầu tư
A5: TT | B5: Hạng mục đầu tư | C5: Giá trị đầu tư trước thuế | D5: Giá trị đầu tư sau thuế
A6: 1 | B6: Chi phí xây dựng | C6: =G6/1000000 -> 304728.1 | D6: =E6/1000000 -> 335200.91 | E6: =SUM(E7,E14,E23) -> 335200914692 | F6: =SUM(F7,F14,F23) -> 304728104266 | G6: =SUM(G7,G14,G23) -> 3.047281e+11
A7: 1.1 | B7: Phần xây dựng | C7: =G7/1000000 -> 66158.546 | D7: =E7/1000000 -> 72774.401 | E7: =SUM(E8:E13) -> 72774400701 | F7: =SUM(F8:F13) -> 66158546092 | G7: =SUM(G8:G13) -> 6.6158546e+10
B8: Hồ lắng bùn | C8: =G8/1000000 -> 2408.9711 | D8: =E8/1000000 -> 2649.8682 | E8: 2649868174 | F8: 2408971068 | G8: =E8/11*10 -> 2.4089711e+09 | H8: =G8-F8 -> -0.72727299
B9: Bể lắng - bể trộn | C9: =G9/1000000 -> 8473.9882 | D9: =E9/1000000 -> 9321.387 | E9: 9321386989 | F9: 8473988172 | G9: =E9/11*10 -> 8.4739882e+09 | H9: =G9-F9 -> -0.18181896
B10: Bể lọc | C10: =G10/1000000 -> 11992.391 | D10: =E10/1000000 -> 13191.63 | E10: 13191630428 | F10: 11992391298 | G10: =E10/11*10 -> 1.1992391e+10 | H10: =G10-F10 -> 0.18181801
B11: Bể chứa | C11: =G11/1000000 -> 18356.999 | D11: =E11/1000000 -> 20192.699 | E11: 20192699213 | F11: 18356999284 | G11: =E11/11*10 -> 1.8356999e+10 | H11: =G11-F11 -> 0.54545593
B12: Ga thoát nước mưa | C12: =G12/1000000 -> 1442.4377 | D12: =E12/1000000 -> 1586.6815 | E12: 1586681487 | F12: 1442437716 | G12: =E12/11*10 -> 1.4424377e+09 | H12: =G12-F12 -> -0.54545474
B13: Tuyến ống truyền tải | C13: =G13/1000000 -> 23483.759 | D13: =E13/1000000 -> 25832.134 | E13: 25832134410 | F13: 23483758554 | G13: =E13/11*10 -> 2.3483759e+10 | H13: =G13-F13 -> 0.54545593
A14: 1.2 | B14: Phần công nghệ | C14: =G14/1000000 -> 229870.67 | D14: =E14/1000000 -> 252857.74 | E14: =SUM(E15:E22) -> 252857738023 | F14: =SUM(F15:F22) -> 229870670930 | G14: =E14/11*10 -> 229870670930 | H14: =G14-F14 -> 0
B15: Đường ống kỹ thuật | C15: =G15/1000000 -> 10024.293 | D15: =E15/1000000 -> 11026.722 | E15: 11026722106 | F15: 10024292823 | G15: =E15/11*10 -> 1.0024293e+10 | H15: =G15-F15 -> 0.63636398
B16: Trạm bơm nước thô | C16: =G16/1000000 -> 1756.1936 | D16: =E16/1000000 -> 1931.813 | E16: 1931812954 | F16: 1756193595 | G16: =E16/11*10 -> 1.7561936e+09 | H16: =G16-F16 -> -0.45454526
B17: Trạm bơm cấp 2 | C17: =G17/1000000 -> 2634.277 | D17: =E17/1000000 -> 2897.7047 | E17: 2897704700 | F17: 2634277000 | G17: =E17/11*10 -> 2634277000 | H17: =G17-F17 -> 0
B18: Cụm bê trộn, lắng ngang, bể phản ứng, bể lọc | C18: =G18/1000000 -> 23558.172 | D18: =E18/1000000 -> 25913.99 | E18: 25913989579 | F18: 23558172345 | G18: =E18/11*10 -> 2.3558172e+10 | H18: =G18-F18 -> -0.45454407
B19: Bể chứa nước lọc | C19: =G19/1000000 -> 827.18144 | D19: =E19/1000000 -> 909.89958 | E19: 909899583 | F19: 827181439 | G19: =E19/11*10 -> 8.2718144e+08 | H19: =G19-F19 -> 0.090909004
B20: Nhà hóa chất | C20: =G20/1000000 -> 2722.4783 | D20: =E20/1000000 -> 2994.7261 | E20: 2994726146 | F20: 2722478314 | G20: =E20/11*10 -> 2.7224783e+09 | H20: =G20-F20 -> 0.5454545
B21: Hố thu bùn | C21: =G21/1000000 -> 718.51032 | D21: =E21/1000000 -> 790.36136 | E21: 790361356 | F21: 718510324 | G21: =E21/11*10 -> 7.1851032e+08 | H21: =G21-F21 -> -0.36363637
B22: Đường ống truyền tải | C22: =G22/1000000 -> 187629.57 | D22: =E22/1000000 -> 206392.52 | E22: 206392521599 | F22: 187629565090 | G22: =E22/11*10 -> 187629565090 | H22: =G22-F22 -> 0
A23: 1.3 | B23: Phần điện | C23: =G23/1000000 -> 8698.8872 | D23: =E23/1000000 -> 9568.776 | E23: =SUM(E24,E30) -> 9568775968 | F23: =SUM(F24,F30) -> 8698887244 | G23: =E23/11*10 -> 8.6988872e+09 | H23: =G23-F23 -> -0.36363602
B24: Điện điều khiển | C24: =G24/1000000 -> 6819.545 | D24: =E24/1000000 -> 7501.4995 | E24: =SUM(E25:E29) -> 7501499540 | F24: =SUM(F25:F29) -> 6819545036 | G24: =E24/11*10 -> 6.819545e+09 | H24: =G24-F24 -> 0.36363602
B25: - Hệ thống Scanda | C25: =G25/1000000 -> 1543.7942 | D25: =E25/1000000 -> 1698.1737 | E25: 1698173657 | F25: 1543794234 | G25: =E25/11*10 -> 1.5437942e+09 | H25: =G25-F25 -> -0.36363626
B26: - Trạm bơm nước thô | C26: =G26/1000000 -> 1039.3688 | D26: =E26/1000000 -> 1143.3056 | E26: 1143305629 | F26: 1039368753 | G26: =E26/11*10 -> 1.0393688e+09 | H26: =G26-F26 -> 0.63636363
B27: - Trạm bơm cấp 2 | C27: =G27/1000000 -> 3041.6513 | D27: =E27/1000000 -> 3345.8164 | E27: 3345816394 | F27: 3041651267 | G27: =E27/11*10 -> 3.0416513e+09 | H27: =G27-F27 -> 0.27272749
B28: - Điều khiển rửa lọc | C28: =G28/1000000 -> 857.79479 | D28: =E28/1000000 -> 943.57427 | E28: 943574270 | F28: 857794791 | G28: =E28/11*10 -> 8.5779479e+08 | H28: =G28-F28 -> -0.090909004
B29: - Nhà hóa chất Nhà Clo | C29: =G29/1000000 -> 336.93599 | D29: =E29/1000000 -> 370.62959 | E29: 370629590 | F29: 336935991 | G29: =E29/11*10 -> 3.3693599e+08 | H29: =G29-F29 -> -0.090909064
B30: Điện trạm biến áp | C30: =G30/1000000 -> 1879.3422 | D30: =E30/1000000 -> 2067.2764 | E30: 2067276428 | F30: 1879342208 | G30: =E30/11*10 -> 1.8793422e+09 | H30: =G30-F30 -> -0.72727275
A31: 2 | B31: Chi phí thiết bị | C31: =G31/1000000 -> 27877.46 | D31: =E31/1000000 -> 30665.206 | E31: =SUM(E32:E35) -> 30665206000 | F31: =SUM(F32:F35) -> 27877460000 | G31: =E31/11*10 -> 27877460000 | H31: =G31-F31 -> 0
B32: Trạm bơm nước thô | C32: =G32/1000000 -> 6454.8 | D32: =E32/1000000 -> 7100.28 | E32: 7100280000 | F32: 6454800000 | G32: =E32/11*10 -> 6454800000 | H32: =G32-F32 -> 0
B33: Trạm bơm cấp II | C33: =G33/1000000 -> 6796 | D33: =E33/1000000 -> 7475.6 | E33: 7475600000 | F33: 6796000000 | G33: =E33/11*10 -> 6796000000 | H33: =G33-F33 -> 0
B34: Cụm bể trộn,lắng ngang, bể phản ứng, bể lọc | C34: =G34/1000000 -> 11193.66 | D34: =E34/1000000 -> 12313.026 | E34: 12313026000 | F34: 11193660000 | G34: =E34/11*10 -> 11193660000 | H34: =G34-F34 -> 0
B35: Hố thu bùn | C35: =G35/1000000 -> 3433 | D35: =E35/1000000 -> 3776.3 | E35: 3776300000 | F35: 3433000000 | G35: =E35/11*10 -> 3433000000 | H35: =G35-F35 -> 0
A36: 3 | B36: Chi phí quản lý dự án | C36: =G36/1000000 -> 3453.0505 | D36: =E36/1000000 -> 3798.3555 | E36: 3798355544 | F36: =E36*0.9 -> 3.41852e+09 | G36: =E36/11*10 -> 3.4530505e+09 | H36: =G36-F36 -> 34530505 | J36: =E36-F36 -> 3.7983555e+08 | K36: =J36/F36 -> 0.11111111 | L36: =F36*1.1 -> 3.760372e+09
A37: 4 | B37: Bồi thường giải phóng mặt bằng | C37: =G37/1000000 -> 7272.7273 | D37: =E37/1000000 -> 8000 | E37: 8000000000 | F37: =E37*0.9 -> 7200000000 | G37: =E37/11*10 -> 7.2727273e+09 | H37: =G37-F37 -> 72727273 | J37: =E37-F37 -> 800000000 | K37: =J37/F37 -> 0.11111111
A38: 5 | B38: Chi phí tư vấn đầu tư xây dựng | C38: =G38/1000000 -> 10325.268 | D38: =E38/1000000 -> 11357.795 | E38: 11357794863 | F38: =E38*0.9 -> 1.0222015e+10 | G38: =E38/11*10 -> 1.0325268e+10 | H38: =G38-F38 -> 1.0325268e+08 | J38: =E38-F38 -> 1.1357795e+09 | K38: =J38/F38 -> 0.11111111
A39: 6 | B39: Chi tư vấn khác | C39: =G39/1000000 -> 2017.9723 | D39: =E39/1000000 -> 2219.7695 | E39: 2219769532 | F39: =E39*0.9 -> 1.9977926e+09 | G39: =E39/11*10 -> 2.0179723e+09 | H39: =G39-F39 -> 20179723 | J39: =E39-F39 -> 2.2197695e+08 | K39: =J39/F39 -> 0.11111111
A40: 7 | B40: Lãi vay thi công | C40: =G40/1000000 -> 24777.188 | D40: =E40/1000000 -> 24777.188 | E40: 24777187500 | F40: 24777187500 | G40: =E40 -> 24777187500 | H40: =G40-F40 -> 0 | J40: =E40-F40 -> 0 | K40: =J40/F40 -> 0
...

Sheet Khấu hao- Bảng 3
A1: Bảng 3: Kế hoạch khấu hao
AC2: ='[4]4 DT CP LN'!AB2 -> Đơn vị tính: triệu đồng
A3: TT | B3: Chỉ tiêu | C3: Giá trị | D3: Thời gian khấu hao | E3: Năm hoạt động
E4: 1 | F4: 2 | G4: 3 | H4: 4 | I4: 5 | J4: 6 | K4: 7 | L4: 8 | M4: 9 | N4: 10 | O4: 11 | P4: 12 | Q4: 13 | R4: 14 | S4: 15 | T4: 16 | U4: 17 | V4: 18 | W4: 19 | X4: 20 | Y4: 21 | Z4: 22 | AA4: 23 | AB4: 24 | AC4: 25
B5: ='[4]4 DT CP LN'!$B$6 -> Hệ số khai thác | E5: ='[4]4 DT CP LN'!D6 -> 0.4 | F5: ='[4]4 DT CP LN'!E6 -> 0.4 | G5: ='[4]4 DT CP LN'!F6 -> 0.45 | H5: ='[4]4 DT CP LN'!G6 -> 0.45 | I5: ='[4]4 DT CP LN'!H6 -> 0.5 | J5: ='[4]4 DT CP LN'!I6 -> 0.5 | K5: ='[4]4 DT CP LN'!J6 -> 0.55 | L5: ='[4]4 DT CP LN'!K6 -> 0.55 | ... AC5: ='[4]4 DT CP LN'!AB6 -> 1 | AD5: =SUM(E6:AC6) -> 1116000
B6: ='[4]4 DT CP LN'!$B$7 -> Công suất hệ thống cấp nước | E6: ='[4]4 DT CP LN'!D7 -> 24000 | F6: ='[4]4 DT CP LN'!E7 -> 24000 | G6: ='[4]4 DT CP LN'!F7 -> 27000 | H6: ='[4]4 DT CP LN'!G7 -> 27000 | I6: ='[4]4 DT CP LN'!H7 -> 30000 | J6: ='[4]4 DT CP LN'!I7 -> 30000 | K6: ='[4]4 DT CP LN'!J7 -> 33000 | L6: ='[4]4 DT CP LN'!K7 -> 33000 | ... AC6: ='[4]4 DT CP LN'!AB7 -> 60000 | AD6: =SUM(E6:X6) -> 816000
A7: 1 | B7: ='[4]1 thong so'!B46 -> Hạng mục xây dựng | C7: ='[4]1 thong so'!C46 -> 84702.942 | D7: 25 | E7: =$C7*E$6/$AD$5 -> 1821.5686 | F7: =$C7*F$6/$AD$5 -> 1821.5686 | G7: =$C7*G$6/$AD$5 -> 2049.2647 | H7: =$C7*H$6/$AD$5 -> 2049.2647 | I7: =$C7*I$6/$AD$5 -> 2276.9608 | J7: =$C7*J$6/$AD$5 -> 2276.9608 | K7: =$C7*K$6/$AD$5 -> 2504.6569 | L7: =$C7*L$6/$AD$5 -> 2504.6569 | ... AC7: =$C7*AC$6/$AD$5 -> 4553.9216 | AD7: =SUM(E6:S6) -> 525000
A8: 2 | B8: ='[4]1 thong so'!B47 -> Hạng mục công nghệ | C8: ='[4]1 thong so'!C47 -> 294303.96 | D8: 25 | E8: =$C8*E$6/$AD$5 -> 6329.1174 | F8: =$C8*F$6/$AD$5 -> 6329.1174 | G8: =$C8*G$6/$AD$5 -> 7120.2571 | H8: =$C8*H$6/$AD$5 -> 7120.2571 | I8: =$C8*I$6/$AD$5 -> 7911.3968 | J8: =$C8*J$6/$AD$5 -> 7911.3968 | K8: =$C8*K$6/$AD$5 -> 8702.5365 | L8: =$C8*L$6/$AD$5 -> 8702.5365 | ... AC8: =$C8*AC$6/$AD$5 -> 15822.794
A9: 3 | B9: ='[4]1 thong so'!B48 -> Hạng mục thiết bị và điện | C9: ='[4]1 thong so'!C48 -> 46828.783 | D9: 15 | E9: =$C9*E$6/$AD$7 -> 2140.7444 | F9: =$C9*F$6/$AD$7 -> 2140.7444 | G9: =$C9*G$6/$AD$7 -> 2408.3374 | H9: =$C9*H$6/$AD$7 -> 2408.3374 | I9: =$C9*I$6/$AD$7 -> 2675.9305 | J9: =$C9*J$6/$AD$7 -> 2675.9305 | K9: =$C9*K$6/$AD$7 -> 2943.5235 | L9: =$C9*L$6/$AD$7 -> 2943.5235 | ... S9: =$C9*S$6/$AD$7 -> 4549.0818
B10: Tổng giá trị khấu hao | C10: =SUM(C7:C9) -> 425835.69 | E10: =SUM(E7:E9) -> 10291.43 | F10: =SUM(F7:F9) -> 10291.43 | G10: =SUM(G7:G9) -> 11577.859 | H10: =SUM(H7:H9) -> 11577.859 | I10: =SUM(I7:I9) -> 12864.288 | J10: =SUM(J7:J9) -> 12864.288 | K10: =SUM(K7:K9) -> 14150.717 | L10: =SUM(L7:L9) -> 14150.717 | ... AC10: =SUM(AC7:AC9) -> 20376.715 | AD10: =SUM(E10:AC10) -> 425835.69
C11: Ghi chú:
C12: Công ty thực hiện khấu hao theo công suất khai thác của nhà máy

Sheet KQKD- Bảng 4
A1: Bảng 4: Kết quả kinh doanh
A3: STT | B3: Khoản mục | D3: Năm hoạt động
D4: 1 | E4: 2 | F4: 3 | G4: 4 | H4: 5 | I4: 6 | J4: 7 | K4: 8 | L4: 9 | M4: 10 | N4: 11 | O4: 12 | P4: 13 | Q4: 14 | R4: 15
A5: STT | B5: Khoản mục | D5: Năm 2018 | E5: Năm 2019 | F5: Năm 2020 | G5: Năm 2021 | H5: Năm 2022 | I5: Năm 2023 | J5: Năm 2024 | K5: Năm 2025 | L5: Năm 2026 | M5: Năm 2027 | N5: Năm 2028 | O5: Năm 2029 | P5: Năm 2030 | Q5: Năm 2031 | R5: Năm 2032 | S5: Năm 2033 | T5: Năm 2034 | U5: Năm 2035 | V5: Năm 2036 | W5: Năm 2037 | X5: Năm 2038 | Y5: Năm 2039 | Z5: Năm 2040 | AA5: Năm 2041 | AB5: Năm 2042
A6: 1 | B6: Mức huy động CSTK | D6: 0.4 | E6: 0.4 | F6: 0.45 | G6: 0.45 | H6: 0.5 | I6: 0.5 | J6: 0.55 | K6: 0.55 | L6: 0.6 | M6: 0.6 | N6: 0.65 | O6: 0.7 | P6: 0.75 | Q6: 0.8 | R6: 0.85 | S6: 0.9 | T6: 0.95 | U6: 1 | V6: 1 | W6: 1 | X6: 1 | Y6: 1 | Z6: 1 | AA6: 1 | AB6: 1
A7: 2 | B7: Sản lượng nước sản xuất thực tế | D7: =D6*'Thong so - Độ nhậy - Bảng 1'!$I$8*365 -> 8760000 | E7: =E6*'Thong so - Độ nhậy - Bảng 1'!$I$8*365 -> 8760000 | F7: =F6*'Thong so - Độ nhậy - Bảng 1'!$I$8*365 -> 9855000 | G7: =G6*'Thong so - Độ nhậy - Bảng 1'!$I$8*365 -> 9855000 | H7: =H6*'Thong so - Độ nhậy - Bảng 1'!$I$8*365 -> 10950000 | I7: =I6*'Thong so - Độ nhậy - Bảng 1'!$I$8*365 -> 10950000 | J7: =J6*'Thong so - Độ nhậy - Bảng 1'!$I$8*365 -> 12045000 | K7: =K6*'Thong so - Độ nhậy - Bảng 1'!$I$8*365 -> 12045000 | ... AB7: =AB6*'Thong so - Độ nhậy - Bảng 1'!$I$8*365 -> 21900000
A8: 3 | B8: Doanh thu | D8: =SUM(D9:D12) -> 87452.394 | E8: =SUM(E9:E12) -> 87452.394 | F8: =SUM(F9:F12) -> 98383.943 | G8: =SUM(G9:G12) -> 98383.943 | H8: =SUM(H9:H12) -> 109315.49 | I8: =SUM(I9:I12) -> 109315.49 | J8: =SUM(J9:J12) -> 120247.04 | K8: =SUM(K9:K12) -> 120247.04 | ... AB8: =SUM(AB9:AB12) -> 218630.99
B9: Doanh thu bán nước sinh hoạt | C9: 0.1697 | D9: =$C$9*D7*'Thong so - Độ nhậy - Bảng 1'!$I$17/1000000 -> 14122.434 | E9: =$C$9*E7*'Thong so - Độ nhậy - Bảng 1'!$I$17/1000000 -> 14122.434 | F9: =$C$9*F7*'Thong so - Độ nhậy - Bảng 1'!$I$17/1000000 -> 15887.738 | G9: =$C$9*G7*'Thong so - Độ nhậy - Bảng 1'!$I$17/1000000 -> 15887.738 | H9: =$C$9*H7*'Thong so - Độ nhậy - Bảng 1'!$I$17/1000000 -> 17653.042 | I9: =$C$9*I7*'Thong so - Độ nhậy - Bảng 1'!$I$17/1000000 -> 17653.042 | J9: =$C$9*J7*'Thong so - Độ nhậy - Bảng 1'!$I$17/1000000 -> 19418.347 | K9: =$C$9*K7*'Thong so - Độ nhậy - Bảng 1'!$I$17/1000000 -> 19418.347 | ... AB9: =$C$9*AB7*'Thong so - Độ nhậy - Bảng 1'!$I$17/1000000 -> 35306.085
B10: Doanh thu bán nước thương mại | C10: 0.017 | D10: =$C$10*D7*'Thong so - Độ nhậy - Bảng 1'!$I$18/1000000 -> 1787.04 | E10: =$C$10*E7*'Thong so - Độ nhậy - Bảng 1'!$I$18/1000000 -> 1787.04 | F10: =$C$10*F7*'Thong so - Độ nhậy - Bảng 1'!$I$18/1000000 -> 2010.42 | G10: =$C$10*G7*'Thong so - Độ nhậy - Bảng 1'!$I$18/1000000 -> 2010.42 | H10: =$C$10*H7*'Thong so - Độ nhậy - Bảng 1'!$I$18/1000000 -> 2233.8 | I10: =$C$10*I7*'Thong so - Độ nhậy - Bảng 1'!$I$18/1000000 -> 2233.8 | J10: =$C$10*J7*'Thong so - Độ nhậy - Bảng 1'!$I$18/1000000 -> 2457.18 | K10: =$C$10*K7*'Thong so - Độ nhậy - Bảng 1'!$I$18/1000000 -> 2457.18 | ... AB10: =$C$10*AB7*'Thong so - Độ nhậy - Bảng 1'!$I$18/1000000 -> 4467.6
B11: Doanh thu bán nước công cộng, công sở | C11: 0.017 | D11: =$C$11*D7*'Thong so - Độ nhậy - Bảng 1'!$I$19/1000000 -> 1787.04 | E11: =$C$11*E7*'Thong so - Độ nhậy - Bảng 1'!$I$19/1000000 -> 1787.04 | F11: =$C$11*F7*'Thong so - Độ nhậy - Bảng 1'!$I$19/1000000 -> 2010.42 | G11: =$C$11*G7*'Thong so - Độ nhậy - Bảng 1'!$I$19/1000000 -> 2010.42 | H11: =$C$11*H7*'Thong so - Độ nhậy - Bảng 1'!$I$19/1000000 -> 2233.8 | I11: =$C$11*I7*'Thong so - Độ nhậy - Bảng 1'!$I$19/1000000 -> 2233.8 | J11: =$C$11*J7*'Thong so - Độ nhậy - Bảng 1'!$I$19/1000000 -> 2457.18 | K11: =$C$11*K7*'Thong so - Độ nhậy - Bảng 1'!$I$19/1000000 -> 2457.18 | ... AB11: =$C$11*AB7*'Thong so - Độ nhậy - Bảng 1'!$I$19/1000000 -> 4467.6
B12: Doanh thu bán nước công nghiệp | C12: 0.7963 | D12: =$C$12*D7*'Thong so - Độ nhậy - Bảng 1'!$I$20/1000000 -> 69755.88 | E12: =$C$12*E7*'Thong so - Độ nhậy - Bảng 1'!$I$20/1000000 -> 69755.88 | F12: =$C$12*F7*'Thong so - Độ nhậy - Bảng 1'!$I$20/1000000 -> 78475.365 | G12: =$C$12*G7*'Thong so - Độ nhậy - Bảng 1'!$I$20/1000000 -> 78475.365 | H12: =$C$12*H7*'Thong so - Độ nhậy - Bảng 1'!$I$20/1000000 -> 87194.85 | I12: =$C$12*I7*'Thong so - Độ nhậy - Bảng 1'!$I$20/1000000 -> 87194.85 | J12: =$C$12*J7*'Thong so - Độ nhậy - Bảng 1'!$I$20/1000000 -> 95914.335 | K12: =$C$12*K7*'Thong so - Độ nhậy - Bảng 1'!$I$20/1000000 -> 95914.335 | ... AB12: =$C$12*AB7*'Thong so - Độ nhậy - Bảng 1'!$I$20/1000000 -> 174389.7
A13: 4 | B13: Chi phí | D13: =D16+D21+D22+D23+D24 -> 45453.45 | E13: =E16+E21+E22+E23+E24 -> 45453.45 | F13: =F16+F21+F22+F23+F24 -> 51135.131 | G13: =G16+G21+G22+G23+G24 -> 51135.131 | H13: =H16+H21+H22+H23+H24 -> 56816.812 | I13: =I16+I21+I22+I23+I24 -> 56816.812 | J13: =J16+J21+J22+J23+J24 -> 62498.494 | K13: =K16+K21+K22+K23+K24 -> 62498.494 | ... AB13: =AB16+AB21+AB22+AB23+AB24 -> 113633.62
B14: Tỷ lệ hao hụt | D14: 0.2 | E14: 0.2 | F14: 0.2 | G14: 0.2 | H14: 0.2 | I14: 0.2 | J14: 0.2 | K14: 0.2 | L14: 0.2 | M14: 0.2 | N14: 0.2 | O14: 0.2 | P14: 0.2 | Q14: 0.2 | R14: 0.2 | S14: 0.2 | T14: 0.2 | U14: 0.2 | V14: 0.2 | W14: 0.2 | X14: 0.2 | Y14: 0.2 | Z14: 0.2 | AA14: 0.2 | AB14: 0.2
B15: Công suất nước phát ra | D15: =D7/(1-D14) -> 10950000 | E15: =E7/(1-E14) -> 10950000 | F15: =F7/(1-F14) -> 12318750 | G15: =G7/(1-G14) -> 12318750 | H15: =H7/(1-H14) -> 13687500 | I15: =I7/(1-I14) -> 13687500 | J15: =J7/(1-J14) -> 15056250 | K15: =K7/(1-K14) -> 15056250 | ... AB15: =AB7/(1-AB14) -> 27375000
A16: 4.1 | B16: Nguyên vật liệu | D16: =SUM(D17:D20) -> 36890.55 | E16: =SUM(E17:E20) -> 36890.55 | F16: =SUM(F17:F20) -> 41501.869 | G16: =SUM(G17:G20) -> 41501.869 | H16: =SUM(H17:H20) -> 46113.188 | I16: =SUM(I17:I20) -> 46113.188 | J16: =SUM(J17:J20) -> 50724.506 | K16: =SUM(K17:K20) -> 50724.506 | ... AB16: =SUM(AB17:AB20) -> 92226.375
B17: Nước thô | D17: ='Thong so - Độ nhậy - Bảng 1'!$I$23*D15/1000000 -> 12045 | E17: ='Thong so - Độ nhậy - Bảng 1'!$I$23*E15/1000000 -> 12045 | F17: ='Thong so - Độ nhậy - Bảng 1'!$I$23*F15/1000000 -> 13550.625 | G17: ='Thong so - Độ nhậy - Bảng 1'!$I$23*G15/1000000 -> 13550.625 | H17: ='Thong so - Độ nhậy - Bảng 1'!$I$23*H15/1000000 -> 15056.25 | I17: ='Thong so - Độ nhậy - Bảng 1'!$I$23*I15/1000000 -> 15056.25 | J17: ='Thong so - Độ nhậy - Bảng 1'!$I$23*J15/1000000 -> 16561.875 | K17: ='Thong so - Độ nhậy - Bảng 1'!$I$23*K15/1000000 -> 16561.875 | ... AB17: ='Thong so - Độ nhậy - Bảng 1'!$I$23*AB15/1000000 -> 30112.5
B18: Điện | D18: ='Thong so - Độ nhậy - Bảng 1'!$I$24*'KQKD- Bảng 4'!D15/1000000 -> 4412.85 | E18: ='Thong so - Độ nhậy - Bảng 1'!$I$24*'KQKD- Bảng 4'!E15/1000000 -> 4412.85 | F18: ='Thong so - Độ nhậy - Bảng 1'!$I$24*'KQKD- Bảng 4'!F15/1000000 -> 4964.4563 | G18: ='Thong so - Độ nhậy - Bảng 1'!$I$24*'KQKD- Bảng 4'!G15/1000000 -> 4964.4563 | H18: ='Thong so - Độ nhậy - Bảng 1'!$I$24*'KQKD- Bảng 4'!H15/1000000 -> 5516.0625 | I18: ='Thong so - Độ nhậy - Bảng 1'!$I$24*'KQKD- Bảng 4'!I15/1000000 -> 5516.0625 | J18: ='Thong so - Độ nhậy - Bảng 1'!$I$24*'KQKD- Bảng 4'!J15/1000000 -> 6067.6687 | K18: ='Thong so - Độ nhậy - Bảng 1'!$I$24*'KQKD- Bảng 4'!K15/1000000 -> 6067.6687 | ... AB18: ='Thong so - Độ nhậy - Bảng 1'!$I$24*'KQKD- Bảng 4'!AB15/1000000 -> 11032.125
B19: Hóa chất | D19: ='Thong so - Độ nhậy - Bảng 1'!$I$25*'KQKD- Bảng 4'!D15/1000000 -> 4007.7 | E19: ='Thong so - Độ nhậy - Bảng 1'!$I$25*'KQKD- Bảng 4'!E15/1000000 -> 4007.7 | F19: ='Thong so - Độ nhậy - Bảng 1'!$I$25*'KQKD- Bảng 4'!F15/1000000 -> 4508.6625 | G19: ='Thong so - Độ nhậy - Bảng 1'!$I$25*'KQKD- Bảng 4'!G15/1000000 -> 4508.6625 | H19: ='Thong so - Độ nhậy - Bảng 1'!$I$25*'KQKD- Bảng 4'!H15/1000000 -> 5009.625 | I19: ='Thong so - Độ nhậy - Bảng 1'!$I$25*'KQKD- Bảng 4'!I15/1000000 -> 5009.625 | J19: ='Thong so - Độ nhậy - Bảng 1'!$I$25*'KQKD- Bảng 4'!J15/1000000 -> 5510.5875 | K19: ='Thong so - Độ nhậy - Bảng 1'!$I$25*'KQKD- Bảng 4'!K15/1000000 -> 5510.5875 | ... AB19: ='Thong so - Độ nhậy - Bảng 1'!$I$25*'KQKD- Bảng 4'!AB15/1000000 -> 10019.25
B20: Đường ống nước thô | D20: ='Thong so - Độ nhậy - Bảng 1'!$I$26*'KQKD- Bảng 4'!D15/1000000 -> 16425 | E20: ='Thong so - Độ nhậy - Bảng 1'!$I$26*'KQKD- Bảng 4'!E15/1000000 -> 16425 | F20: ='Thong so - Độ nhậy - Bảng 1'!$I$26*'KQKD- Bảng 4'!F15/1000000 -> 18478.125 | G20: ='Thong so - Độ nhậy - Bảng 1'!$I$26*'KQKD- Bảng 4'!G15/1000000 -> 18478.125 | H20: ='Thong so - Độ nhậy - Bảng 1'!$I$26*'KQKD- Bảng 4'!H15/1000000 -> 20531.25 | I20: ='Thong so - Độ nhậy - Bảng 1'!$I$26*'KQKD- Bảng 4'!I15/1000000 -> 20531.25 | J20: ='Thong so - Độ nhậy - Bảng 1'!$I$26*'KQKD- Bảng 4'!J15/1000000 -> 22584.375 | K20: ='Thong so - Độ nhậy - Bảng 1'!$I$26*'KQKD- Bảng 4'!K15/1000000 -> 22584.375 | ... AB20: ='Thong so - Độ nhậy - Bảng 1'!$I$26*'KQKD- Bảng 4'!AB15/1000000 -> 41062.5
A21: 4.2 | B21: Chi phí quản lý | D21: ='Thong so - Độ nhậy - Bảng 1'!$I$28*'KQKD- Bảng 4'!D15/1000000 -> 2430.9 | E21: ='Thong so - Độ nhậy - Bảng 1'!$I$28*'KQKD- Bảng 4'!E15/1000000 -> 2430.9 | F21: ='Thong so - Độ nhậy - Bảng 1'!$I$28*'KQKD- Bảng 4'!F15/1000000 -> 2734.7625 | G21: ='Thong so - Độ nhậy - Bảng 1'!$I$28*'KQKD- Bảng 4'!G15/1000000 -> 2734.7625 | H21: ='Thong so - Độ nhậy - Bảng 1'!$I$28*'KQKD- Bảng 4'!H15/1000000 -> 3038.625 | I21: ='Thong so - Độ nhậy - Bảng 1'!$I$28*'KQKD- Bảng 4'!I15/1000000 -> 3038.625 | J21: ='Thong so - Độ nhậy - Bảng 1'!$I$28*'KQKD- Bảng 4'!J15/1000000 -> 3342.4875 | K21: ='Thong so - Độ nhậy - Bảng 1'!$I$28*'KQKD- Bảng 4'!K15/1000000 -> 3342.4875 | ... AB21: ='Thong so - Độ nhậy - Bảng 1'!$I$28*'KQKD- Bảng 4'!AB15/1000000 -> 6077.25
A22: 4.3 | B22: Chi phí bán hàng | D22: ='Thong so - Độ nhậy - Bảng 1'!$I$30*'KQKD- Bảng 4'!D15/1000000 -> 2398.05 | E22: ='Thong so - Độ nhậy - Bảng 1'!$I$30*'KQKD- Bảng 4'!E15/1000000 -> 2398.05 | F22: ='Thong so - Độ nhậy - Bảng 1'!$I$30*'KQKD- Bảng 4'!F15/1000000 -> 2697.8063 | G22: ='Thong so - Độ nhậy - Bảng 1'!$I$30*'KQKD- Bảng 4'!G15/1000000 -> 2697.8063 | H22: ='Thong so - Độ nhậy - Bảng 1'!$I$30*'KQKD- Bảng 4'!H15/1000000 -> 2997.5625 | I22: ='Thong so - Độ nhậy - Bảng 1'!$I$30*'KQKD- Bảng 4'!I15/1000000 -> 2997.5625 | J22: ='Thong so - Độ nhậy - Bảng 1'!$I$30*'KQKD- Bảng 4'!J15/1000000 -> 3297.3187 | K22: ='Thong so - Độ nhậy - Bảng 1'!$I$30*'KQKD- Bảng 4'!K15/1000000 -> 3297.3187 | ... AB22: ='Thong so - Độ nhậy - Bảng 1'!$I$30*'KQKD- Bảng 4'!AB15/1000000 -> 5995.125
A23: 4.4 | B23: Chi phí lương nhân công | D23: ='Thong so - Độ nhậy - Bảng 1'!$I$29*'KQKD- Bảng 4'!D15/1000000 -> 2825.1 | E23: ='Thong so - Độ nhậy - Bảng 1'!$I$29*'KQKD- Bảng 4'!E15/1000000 -> 2825.1 | F23: ='Thong so - Độ nhậy - Bảng 1'!$I$29*'KQKD- Bảng 4'!F15/1000000 -> 3178.2375 | G23: ='Thong so - Độ nhậy - Bảng 1'!$I$29*'KQKD- Bảng 4'!G15/1000000 -> 3178.2375 | H23: ='Thong so - Độ nhậy - Bảng 1'!$I$29*'KQKD- Bảng 4'!H15/1000000 -> 3531.375 | I23: ='Thong so - Độ nhậy - Bảng 1'!$I$29*'KQKD- Bảng 4'!I15/1000000 -> 3531.375 | J23: ='Thong so - Độ nhậy - Bảng 1'!$I$29*'KQKD- Bảng 4'!J15/1000000 -> 3884.5125 | K23: ='Thong so - Độ nhậy - Bảng 1'!$I$29*'KQKD- Bảng 4'!K15/1000000 -> 3884.5125 | ... AB23: ='Thong so - Độ nhậy - Bảng 1'!$I$29*'KQKD- Bảng 4'!AB15/1000000 -> 7062.75
A24: 4.5 | B24: Chi phí sản xuất chung | D24: ='Thong so - Độ nhậy - Bảng 1'!$I$27*'KQKD- Bảng 4'!D15/1000000 -> 908.85 | E24: ='Thong so - Độ nhậy - Bảng 1'!$I$27*'KQKD- Bảng 4'!E15/1000000 -> 908.85 | F24: ='Thong so - Độ nhậy - Bảng 1'!$I$27*'KQKD- Bảng 4'!F15/1000000 -> 1022.4562 | G24: ='Thong so - Độ nhậy - Bảng 1'!$I$27*'KQKD- Bảng 4'!G15/1000000 -> 1022.4562 | H24: ='Thong so - Độ nhậy - Bảng 1'!$I$27*'KQKD- Bảng 4'!H15/1000000 -> 1136.0625 | I24: ='Thong so - Độ nhậy - Bảng 1'!$I$27*'KQKD- Bảng 4'!I15/1000000 -> 1136.0625 | J24: ='Thong so - Độ nhậy - Bảng 1'!$I$27*'KQKD- Bảng 4'!J15/1000000 -> 1249.6688 | K24: ='Thong so - Độ nhậy - Bảng 1'!$I$27*'KQKD- Bảng 4'!K15/1000000 -> 1249.6688 | ... AB24: ='Thong so - Độ nhậy - Bảng 1'!$I$27*'KQKD- Bảng 4'!AB15/1000000 -> 2272.125
A25: 5 | B25: LN trước khấu hao và lãi vay | D25: =D8-D13 -> 41998.944 | E25: =E8-E13 -> 41998.944 | F25: =F8-F13 -> 47248.812 | G25: =G8-G13 -> 47248.812 | H25: =H8-H13 -> 52498.68 | I25: =I8-I13 -> 52498.68 | J25: =J8-J13 -> 57748.548 | K25: =K8-K13 -> 57748.548 | ... AB25: =AB8-AB13 -> 104997.36
A26: 6 | B26: Khấu hao cơ bản | D26: ='Khấu hao- Bảng 3'!E10 -> 10291.43 | E26: ='Khấu hao- Bảng 3'!F10 -> 10291.43 | F26: ='Khấu hao- Bảng 3'!G10 -> 11577.859 | G26: ='Khấu hao- Bảng 3'!H10 -> 11577.859 | H26: ='Khấu hao- Bảng 3'!I10 -> 12864.288 | I26: ='Khấu hao- Bảng 3'!J10 -> 12864.288 | J26: ='Khấu hao- Bảng 3'!K10 -> 14150.717 | K26: ='Khấu hao- Bảng 3'!L10 -> 14150.717 | ... AB26: ='Khấu hao- Bảng 3'!AC10 -> 20376.715
A27: 7 | B27: Lãi vay vốn lưu động | D27: ='VLD- Bảng 6'!D17 -> 1005.1394 | E27: ='VLD- Bảng 6'!E17 -> 1005.1394 | F27: ='VLD- Bảng 6'!F17 -> 1130.7818 | G27: ='VLD- Bảng 6'!G17 -> 1130.7818 | H27: ='VLD- Bảng 6'!H17 -> 1256.4242 | I27: ='VLD- Bảng 6'!I17 -> 1256.4242 | J27: ='VLD- Bảng 6'!J17 -> 1382.0666 | K27: ='VLD- Bảng 6'!K17 -> 1382.0666 | ... AB27: ='VLD- Bảng 6'!AB17 -> 2512.8484
A28: 8 | B28: Lãi vay vốn cố định | D28: ='KH trả nợ-Bảng 5'!C12 -> 30975 | E28: ='KH trả nợ-Bảng 5'!D12 -> 30139.146 | F28: ='KH trả nợ-Bảng 5'!E12 -> 29241.89 | G28: ='KH trả nợ-Bảng 5'!F12 -> 27961.036 | H28: ='KH trả nợ-Bảng 5'!G12 -> 26605.646 | I28: ='KH trả nợ-Bảng 5'!H12 -> 24839.998 | J28: ='KH trả nợ-Bảng 5'!I12 -> 22971.604 | K28: ='KH trả nợ-Bảng 5'!J12 -> 20663.099 | ... AB28: ='KH trả nợ-Bảng 5'!AA12 -> 0
A29: 9 | B29: Lợi nhuận trước thuế | D29: =D25-D26-D27-D28 -> -272.62581 | E29: =E25-E26-E27-E28 -> 563.22863 | F29: =F25-F26-F27-F28 -> 5298.2806 | G29: =G25-G26-G27-G28 -> 6579.1353 | H29: =H25-H26-H27-H28 -> 11772.321 | I29: =I25-I26-I27-I28 -> 13537.97 | J29: =J25-J26-J27-J28 -> 19244.16 | K29: =K25-K26-K27-K28 -> 21552.665 | ... AB29: =AB25-AB26-AB27-AB28 -> 82107.796
A30: 10 | B30: Thuế TNDN | D30: =IF(D29<0,0,D29*'Thong so - Độ nhậy - Bảng 1'!$C$31) -> 0 | E30: =IF(E29<0,0,E29*'Thong so - Độ nhậy - Bảng 1'!$C$31) -> 112.64573 | F30: =IF(F29<0,0,F29*'Thong so - Độ nhậy - Bảng 1'!$C$31) -> 1059.6561 | G30: =IF(G29<0,0,G29*'Thong so - Độ nhậy - Bảng 1'!$C$31) -> 1315.8271 | H30: =IF(H29<0,0,H29*'Thong so - Độ nhậy - Bảng 1'!$C$31) -> 2354.4643 | I30: =IF(I29<0,0,I29*'Thong so - Độ nhậy - Bảng 1'!$C$31) -> 2707.5939 | J30: =IF(J29<0,0,J29*'Thong so - Độ nhậy - Bảng 1'!$C$31) -> 3848.8321 | K30: =IF(K29<0,0,K29*'Thong so - Độ nhậy - Bảng 1'!$C$31) -> 4310.5331 | ... AB30: =IF(AB29<0,0,AB29*'Thong so - Độ nhậy - Bảng 1'!$C$31) -> 16421.559
A31: 12 | B31: LN sau thuế (EAT) | D31: =D29-D30 -> -272.62581 | E31: =E29-E30 -> 450.58291 | F31: =F29-F30 -> 4238.6245 | G31: =G29-G30 -> 5263.3082 | H31: =H29-H30 -> 9417.8571 | I31: =I29-I30 -> 10830.376 | J31: =J29-J30 -> 15395.328 | K31: =K29-K30 -> 17242.132 | ... AB31: =AB29-AB30 -> 65686.237
E32: =E26+E31 -> 10742.013
D33: =D13+D27 -> 46458.589 | E33: =E27+E32 -> 11747.153 | F33: =IF(F30<=0,0,1) -> 1 | G33: =IF(G30<=0,0,1) -> 1 | H33: =IF(H30<=0,0,1) -> 1 | I33: =IF(I30<=0,0,1) -> 1 | J33: =IF(J30<=0,0,1) -> 1 | K33: =IF(K30<=0,0,1) -> 1 | L33: =IF(L30<=0,0,1) -> 1 | M33: =IF(M30<=0,0,1) -> 1
D34: =D33+B34 -> 46458.589 | E34: =E28+E33 -> 41886.298 | F34: =F33+E34 -> 41887.298 | G34: =G33+F34 -> 41888.298 | H34: =H33+G34 -> 41889.298 | I34: =I33+H34 -> 41890.298 | J34: =J33+I34 -> 41891.298 | K34: =K33+J34 -> 41892.298 | L34: =L33+K34 -> 41893.298 | M34: =M33+L34 -> 41894.298
D35: =IF(D33<=0,0,SUM(D30:$M$30,#REF!)) -> #REF! | E35: =E29+E34 -> 42449.527 | F35: =IF(F33<=0,0,SUM(F30:$M$30,#REF!)) -> #REF! | G35: =IF(G33<=0,0,SUM(G30:$M$30,#REF!)) -> #REF! | H35: =IF(H33<=0,0,SUM(H30:$M$30,#REF!)) -> #REF! | I35: =IF(I33<=0,0,SUM(I30:$M$30,#REF!)) -> #REF! | J35: =IF(J33<=0,0,SUM(J30:$M$30,#REF!)) -> #REF! | K35: =IF(K33<=0,0,SUM(K30:$M$30,#REF!)) -> #REF! | L35: =IF(L33<=0,0,SUM(L30:$M$30,#REF!)) -> #REF! | M35: =IF(M33<=0,0,SUM(M30:$M$30,#REF!)) -> #REF!
D36: =#REF!/D30*100 -> #REF! | E36: =E30+E35 -> 42562.173 | F36: =#REF!/F30*100 -> #REF! | G36: =#REF!/G30*100 -> #REF! | H36: =#REF!/H30*100 -> #REF! | I36: =#REF!/I30*100 -> #REF! | J36: =#REF!/J30*100 -> #REF! | K36: =#REF!/K30*100 -> #REF! | L36: =#REF!/L30*100 -> #REF! | M36: =#REF!/M30*100 -> #REF!
D38: =D26 -> 10291.43 | E38: =E26 -> 10291.43 | F38: =F26 -> 11577.859 | G38: =G26 -> 11577.859 | H38: =H26 -> 12864.288 | I38: =I26 -> 12864.288 | J38: =J26 -> 14150.717 | K38: =K26 -> 14150.717 | ... M38: =M26 -> 15437.146
D39: =D31 -> -272.62581 | E39: =E31 -> 450.58291 | F39: =F31 -> 4238.6245 | G39: =G31 -> 5263.3082 | H39: =H31 -> 9417.8571 | I39: =I31 -> 10830.376 | J39: =J31 -> 15395.328 | K39: =K31 -> 17242.132 | ... M39: =M31 -> 24599.746
D40: =SUM(D38:D39) -> 10018.805 | E40: =SUM(E38:E39) -> 10742.013 | F40: =SUM(F38:F39) -> 15816.484 | G40: =SUM(G38:G39) -> 16841.167 | H40: =SUM(H38:H39) -> 22282.145 | I40: =SUM(I38:I39) -> 23694.664 | J40: =SUM(J38:J39) -> 29546.045 | K40: =SUM(K38:K39) -> 31392.849 | ... M40: =SUM(M38:M39) -> 40036.891
B41: ='Thong so - Độ nhậy - Bảng 1'!C5 -> 425835 | D41: =B41-D40 -> 415816.2 | E41: =D41-E40 -> 405074.18 | F41: =E41-F40 -> 389257.7 | G41: =F41-G40 -> 372416.53 | H41: =G41-H40 -> 350134.39 | I41: =H41-I40 -> 326439.72 | J41: =I41-J40 -> 296893.68 | K41: =J41-K40 -> 265500.83 | L41: =K41-L40 -> 227797.04 | M41: =L41-M40 -> 187760.15
D43: =D26/#REF! -> #REF!
...

Sheet KH trả nợ-Bảng 5
A1: BẢNG 5: KẾ HOẠCH TRẢ NỢ GỐC
B2: 0 | C2: 1 | D2: 2 | E2: 3 | F2: 4 | G2: 5 | H2: 6 | I2: 7 | J2: 8 | K2: 9 | L2: 10 | M2: 10 | N2: 11 | O2: 14 | P2: 15 | Q2: 16 | R2: 17 | S2: 18 | T2: 19 | U2: 20 | V2: 21 | W2: 22 | X2: 23 | Y2: 24 | Z2: 25
A3: Thông số | B3: Năm XDCB | C3: Năm 2018 | D3: Năm 2019 | E3: Năm 2020 | F3: Năm 2021 | G3: Năm 2022 | H3: Năm 2023 | I3: Năm 2024 | J3: Năm 2025 | K3: Năm 2026 | L3: Năm 2027 | M3: Năm 2028 | N3: Năm 2029 | O3: Năm 2030 | P3: Năm 2031 | Q3: Năm 2032 | R3: Năm 2033 | S3: Năm 2034 | T3: Năm 2035 | U3: Năm 2036 | V3: Năm 2037 | W3: Năm 2038 | X3: Năm 2039 | Y3: Năm 2040 | Z3: Năm 2041 | AA3: Năm 2042
A4: I. Nguồn trả nợ gốc | C4: =SUM(C5:C6) -> 7960.5185 | D4: =SUM(D5:D6) -> 8545.2879 | E4: =SUM(E5:E6) -> 12198.616 | F4: =SUM(F5:F6) -> 12908.47 | G4: =SUM(G5:G6) -> 16815.698 | H4: =SUM(H5:H6) -> 17794.227 | I4: =SUM(I5:I6) -> 21985.763 | J4: =SUM(J5:J6) -> 23265.146 | ... Z4: =SUM(Z5:Z6) -> 61805.839
A5: 1. Khấu hao cơ bản | C5: ='Thong so - Độ nhậy - Bảng 1'!$N$11*'KQKD- Bảng 4'!D26 -> 8233.1444 | D5: ='Thong so - Độ nhậy - Bảng 1'!$N$11*'KQKD- Bảng 4'!E26 -> 8233.1444 | E5: ='Thong so - Độ nhậy - Bảng 1'!$N$11*'KQKD- Bảng 4'!F26 -> 9262.2874 | F5: ='Thong so - Độ nhậy - Bảng 1'!$N$11*'KQKD- Bảng 4'!G26 -> 9262.2874 | G5: ='Thong so - Độ nhậy - Bảng 1'!$N$11*'KQKD- Bảng 4'!H26 -> 10291.43 | H5: ='Thong so - Độ nhậy - Bảng 1'!$N$11*'KQKD- Bảng 4'!I26 -> 10291.43 | I5: ='Thong so - Độ nhậy - Bảng 1'!$N$11*'KQKD- Bảng 4'!J26 -> 11320.573 | J5: ='Thong so - Độ nhậy - Bảng 1'!$N$11*'KQKD- Bảng 4'!K26 -> 11320.573 | ... AA5: ='Thong so - Độ nhậy - Bảng 1'!$N$11*'KQKD- Bảng 4'!AB26 -> 16301.372
A6: 2. Lợi nhuận sau thuế | C6: =IF('KQKD- Bảng 4'!D31>0,'KQKD- Bảng 4'!D31*'Thong so - Độ nhậy - Bảng 1'!$N$12,'KQKD- Bảng 4'!D31) -> -272.62581 | D6: =IF('KQKD- Bảng 4'!E31>0,'KQKD- Bảng 4'!E31*'Thong so - Độ nhậy - Bảng 1'!$N$12,'KQKD- Bảng 4'!E31) -> 312.14354 | E6: =IF('KQKD- Bảng 4'!F31>0,'KQKD- Bảng 4'!F31*'Thong so - Độ nhậy - Bảng 1'!$N$12,'KQKD- Bảng 4'!F31) -> 2936.3281 | F6: =IF('KQKD- Bảng 4'!G31>0,'KQKD- Bảng 4'!G31*'Thong so - Độ nhậy - Bảng 1'!$N$12,'KQKD- Bảng 4'!G31) -> 3646.1829 | G6: =IF('KQKD- Bảng 4'!H31>0,'KQKD- Bảng 4'!H31*'Thong so - Độ nhậy - Bảng 1'!$N$12,'KQKD- Bảng 4'!H31) -> 6524.2672 | H6: =IF('KQKD- Bảng 4'!I31>0,'KQKD- Bảng 4'!I31*'Thong so - Độ nhậy - Bảng 1'!$N$12,'KQKD- Bảng 4'!I31) -> 7502.7965 | I6: =IF('KQKD- Bảng 4'!J31>0,'KQKD- Bảng 4'!J31*'Thong so - Độ nhậy - Bảng 1'!$N$12,'KQKD- Bảng 4'!J31) -> 10665.19 | J6: =IF('KQKD- Bảng 4'!K31>0,'KQKD- Bảng 4'!K31*'Thong so - Độ nhậy - Bảng 1'!$N$12,'KQKD- Bảng 4'!K31) -> 11944.573 | ... AA6: =IF('KQKD- Bảng 4'!AB31>0,'KQKD- Bảng 4'!AB31*'Thong so - Độ nhậy - Bảng 1'!$N$12,'KQKD- Bảng 4'!AB31) -> 45504.466
A7: Cân đối trả nợ
A8: II. Trả nợ Agribank | C8: =IF(C9<C11,C9/C11*12/100+C3-1,0) -> 0 | D8: =IF(D9<D4,IF(C13>0,D9/D4+C2,0),0) -> 0 | E8: =IF(E9<E4,IF(D13>0,E9/E4+D2,0),0) -> 0 | F8: =IF(F9<F4,IF(E13>0,F9/F4+E2,0),0) -> 0 | G8: =IF(G9<G4,IF(F13>0,G9/G4+F2,0),0) -> 0 | H8: =IF(H9<H4,IF(G13>0,H9/H4+G2,0),0) -> 0 | I8: =IF(I9<I4,IF(H13>0,I9/I4+H2,0),0) -> 0 | J8: =IF(J9<J4,IF(I13>0,J9/J4+I2,0),0) -> 0 | K8: =IF(K9<K4,IF(J13>0,K9/K4+J2,0),0) -> 0
A9: 1. Dư nợ đầu kỳ | B9: 295000 | C9: =B13 -> 295000 | D9: =C13 -> 287039.48 | E9: =D13 -> 278494.19 | F9: =E13 -> 266295.58 | G9: =F13 -> 253387.11 | H9: =G13 -> 236571.41 | I9: =H13 -> 218777.18 | J9: =I13 -> 196791.42 | ... O9: =N13 -> 42694.949
A10: 2. Giải ngân trong kỳ
A11: 3. Trả Gốc | C11: =C4 -> 7960.5185 | D11: =D4 -> 8545.2879 | E11: =E4 -> 12198.616 | F11: =F4 -> 12908.47 | G11: =G4 -> 16815.698 | H11: =H4 -> 17794.227 | I11: =I4 -> 21985.763 | J11: =J4 -> 23265.146 | ... N11: =N4 -> 39407.269 | O11: =N13 -> 42694.949
A12: 4. Lãi vay | C12: =C9*'Thong so - Độ nhậy - Bảng 1'!$N$16 -> 30975 | D12: =D9*'Thong so - Độ nhậy - Bảng 1'!$N$16 -> 30139.146 | E12: =E9*'Thong so - Độ nhậy - Bảng 1'!$N$16 -> 29241.89 | F12: =F9*'Thong so - Độ nhậy - Bảng 1'!$N$16 -> 27961.036 | G12: =G9*'Thong so - Độ nhậy - Bảng 1'!$N$16 -> 26605.646 | H12: =H9*'Thong so - Độ nhậy - Bảng 1'!$N$16 -> 24839.998 | I12: =I9*'Thong so - Độ nhậy - Bảng 1'!$N$16 -> 22971.604 | J12: =J9*'Thong so - Độ nhậy - Bảng 1'!$N$16 -> 20663.099 | ... O12: =O9*'Thong so - Độ nhậy - Bảng 1'!$N$16 -> 4482.9697
A13: 4. Dư nợ cuối kỳ | B13: =IF(B9>B11,B9-B11,0) -> 295000 | C13: =IF(C9>C11,C9-C11,0) -> 287039.48 | D13: =IF(D9>D11,D9-D11,0)+D10 -> 278494.19 | E13: =IF(E9>E11,E9-E11,0) -> 266295.58 | F13: =IF(F9>F11,F9-F11,0) -> 253387.11 | G13: =IF(G9>G11,G9-G11,0) -> 236571.41 | H13: =IF(H9>H11,H9-H11,0) -> 218777.18 | I13: =IF(I9>I11,I9-I11,0) -> 196791.42 | J13: =IF(J9>J11,J9-J11,0) -> 173526.27 | K13: =IF(K9>K11,K9-K11,0) -> 145751.23 | L13: =IF(L9>L11,L9-L11,0) -> 116359.92 | ... O13: =IF(O9>O11,O9-O11,0) -> 0
A14: III. Tổng trả nợ gốc | C14: =C15+C16 -> 7960.5185 | D14: =D15+D16 -> 8545.2879 | E14: =E15+E16 -> 12198.616 | F14: =F15+F16 -> 12908.47 | G14: =G15+G16 -> 16815.698 | H14: =H15+H16 -> 17794.227 | I14: =I15+I16 -> 21985.763 | J14: =J15+J16 -> 23265.146 | ... O14: =O15+O16 -> 42694.949
A15: 1. Gốc | C15: =C11 -> 7960.5185 | D15: =D11 -> 8545.2879 | E15: =E11 -> 12198.616 | F15: =F11 -> 12908.47 | G15: =G11 -> 16815.698 | H15: =H11 -> 17794.227 | I15: =I11 -> 21985.763 | J15: =J11 -> 23265.146 | ... O15: =O11 -> 42694.949
A16: 2. Lãi vay
A17: Thời hạn cho vay | B17: 13 | C17: năm (không kể thời gian ân hạn)
B18: =B17+2 -> 15 | C18: năm (cả thời gian ân hạn)
A19: Thời gian ân hạn | B19: 2 | C19: năm

Sheet VLD- Bảng 6
A2: BẢNG 6: NHU CẦU VỐN LƯU ĐỘNG
A3: STT | B3: KHOẢN MỤC | C3: Năm XDCB | D3: NĂM HOẠT ĐỘNG
D4: 1 | E4: 2 | F4: 3 | G4: 4 | H4: 5 | I4: 6 | J4: 7 | K4: 8 | L4: 9 | M4: 10 | N4: 11 | O4: 12 | P4: 13 | Q4: 14 | R4: 15 | S4: 16 | T4: 17 | U4: 18 | V4: 19 | W4: 20 | X4: 21 | Y4: 22 | Z4: 23 | AA4: 24 | AB4: 25
A5: 1 | B5: Doanh thu | D5: ='KQKD- Bảng 4'!D8 -> 87452.394 | E5: ='KQKD- Bảng 4'!E8 -> 87452.394 | F5: ='KQKD- Bảng 4'!F8 -> 98383.943 | G5: ='KQKD- Bảng 4'!G8 -> 98383.943 | H5: ='KQKD- Bảng 4'!H8 -> 109315.49 | I5: ='KQKD- Bảng 4'!I8 -> 109315.49 | J5: ='KQKD- Bảng 4'!J8 -> 120247.04 | K5: ='KQKD- Bảng 4'!K8 -> 120247.04 | ... AB5: ='KQKD- Bảng 4'!AB8 -> 218630.99
A6: 2 | B6: Chi phí hoạt động | D6: ='KQKD- Bảng 4'!D21+'KQKD- Bảng 4'!D22+'KQKD- Bảng 4'!D23+'KQKD- Bảng 4'!D24 -> 8562.9 | E6: ='KQKD- Bảng 4'!E21+'KQKD- Bảng 4'!E22+'KQKD- Bảng 4'!E23+'KQKD- Bảng 4'!E24 -> 8562.9 | F6: ='KQKD- Bảng 4'!F21+'KQKD- Bảng 4'!F22+'KQKD- Bảng 4'!F23+'KQKD- Bảng 4'!F24 -> 9633.2625 | G6: ='KQKD- Bảng 4'!G21+'KQKD- Bảng 4'!G22+'KQKD- Bảng 4'!G23+'KQKD- Bảng 4'!G24 -> 9633.2625 | H6: ='KQKD- Bảng 4'!H21+'KQKD- Bảng 4'!H22+'KQKD- Bảng 4'!H23+'KQKD- Bảng 4'!H24 -> 10703.625 | I6: ='KQKD- Bảng 4'!I21+'KQKD- Bảng 4'!I22+'KQKD- Bảng 4'!I23+'KQKD- Bảng 4'!I24 -> 10703.625 | J6: ='KQKD- Bảng 4'!J21+'KQKD- Bảng 4'!J22+'KQKD- Bảng 4'!J23+'KQKD- Bảng 4'!J24 -> 11773.987 | K6: ='KQKD- Bảng 4'!K21+'KQKD- Bảng 4'!K22+'KQKD- Bảng 4'!K23+'KQKD- Bảng 4'!K24 -> 11773.987 | ... AB6: ='KQKD- Bảng 4'!AB21+'KQKD- Bảng 4'!AB22+'KQKD- Bảng 4'!AB23+'KQKD- Bảng 4'!AB24 -> 21407.25
A7: 3 | B7: Chi phí nguyên, nhiên vật liệu | D7: ='KQKD- Bảng 4'!D16 -> 36890.55 | E7: ='KQKD- Bảng 4'!E16 -> 36890.55 | F7: ='KQKD- Bảng 4'!F16 -> 41501.869 | G7: ='KQKD- Bảng 4'!G16 -> 41501.869 | H7: ='KQKD- Bảng 4'!H16 -> 46113.188 | I7: ='KQKD- Bảng 4'!I16 -> 46113.188 | J7: ='KQKD- Bảng 4'!J16 -> 50724.506 | K7: ='KQKD- Bảng 4'!K16 -> 50724.506 | ... AB7: ='KQKD- Bảng 4'!AB16 -> 92226.375
A8: 4 | B8: Các khoản phải thu AR | D8: =D5*'Thong so - Độ nhậy - Bảng 1'!$C$24 -> 874.52394 | E8: =E5*'Thong so - Độ nhậy - Bảng 1'!$C$24 -> 874.52394 | F8: =F5*'Thong so - Độ nhậy - Bảng 1'!$C$24 -> 983.83943 | G8: =G5*'Thong so - Độ nhậy - Bảng 1'!$C$24 -> 983.83943 | H8: =H5*'Thong so - Độ nhậy - Bảng 1'!$C$24 -> 1093.1549 | I8: =I5*'Thong so - Độ nhậy - Bảng 1'!$C$24 -> 1093.1549 | J8: =J5*'Thong so - Độ nhậy - Bảng 1'!$C$24 -> 1202.4704 | K8: =K5*'Thong so - Độ nhậy - Bảng 1'!$C$24 -> 1202.4704 | ... AB8: =AB5*'Thong so - Độ nhậy - Bảng 1'!$C$24 -> 2186.3099
A9: 5 | B9: DAR = AR1 - AR2 | D9: =C8-D8 -> -874.52394 | E9: =D8-E8 -> 0 | F9: =E8-F8 -> -109.31549 | G9: =F8-G8 -> 0 | H9: =G8-H8 -> -109.31549 | I9: =H8-I8 -> 0 | J9: =I8-J8 -> -109.31549 | K9: =J8-K8 -> 0 | ... AB9: =AA8-AB8 -> 0
A10: 6 | B10: Các khoản phải trả AP | D10: =D6*'Thong so - Độ nhậy - Bảng 1'!$C$25 -> 85.629 | E10: =E6*'Thong so - Độ nhậy - Bảng 1'!$C$25 -> 85.629 | F10: =F6*'Thong so - Độ nhậy - Bảng 1'!$C$25 -> 96.332625 | G10: =G6*'Thong so - Độ nhậy - Bảng 1'!$C$25 -> 96.332625 | H10: =H6*'Thong so - Độ nhậy - Bảng 1'!$C$25 -> 107.03625 | I10: =I6*'Thong so - Độ nhậy - Bảng 1'!$C$25 -> 107.03625 | J10: =J6*'Thong so - Độ nhậy - Bảng 1'!$C$25 -> 117.73987 | K10: =K6*'Thong so - Độ nhậy - Bảng 1'!$C$25 -> 117.73987 | ... AB10: =AB6*'Thong so - Độ nhậy - Bảng 1'!$C$25 -> 214.0725
A11: 7 | B11: DAP = AP1 - AP2 | D11: =C10-D10 -> -85.629 | E11: =D10-E10 -> 0 | F11: =E10-F10 -> -10.703625 | G11: =F10-G10 -> 0 | H11: =G10-H10 -> -10.703625 | I11: =H10-I10 -> 0 | J11: =I10-J10 -> -10.703625 | K11: =J10-K10 -> 0 | ... AB11: =AA10-AB10 -> 0
A12: 8 | B12: Cân đối tiền mặt CB | D12: =D5*'Thong so - Độ nhậy - Bảng 1'!$C$26 -> 874.52394 | E12: =E5*'Thong so - Độ nhậy - Bảng 1'!$C$26 -> 874.52394 | F12: =F5*'Thong so - Độ nhậy - Bảng 1'!$C$26 -> 983.83943 | G12: =G5*'Thong so - Độ nhậy - Bảng 1'!$C$26 -> 983.83943 | H12: =H5*'Thong so - Độ nhậy - Bảng 1'!$C$26 -> 1093.1549 | I12: =I5*'Thong so - Độ nhậy - Bảng 1'!$C$26 -> 1093.1549 | J12: =J5*'Thong so - Độ nhậy - Bảng 1'!$C$26 -> 1202.4704 | K12: =K5*'Thong so - Độ nhậy - Bảng 1'!$C$26 -> 1202.4704 | ... AB12: =AB5*'Thong so - Độ nhậy - Bảng 1'!$C$26 -> 2186.3099
A13: 9 | B13: DCB = CB2 - CB1 | D13: =-C12+D12 -> 874.52394 | E13: =-D12+E12 -> 0 | F13: =-E12+F12 -> 109.31549 | G13: =-F12+G12 -> 0 | H13: =-G12+H12 -> 109.31549 | I13: =-H12+I12 -> 0 | J13: =-I12+J12 -> 109.31549 | K13: =-J12+K12 -> 0 | ... AB13: =-AA12+AB12 -> 0
A14: 10 | B14: Tồn kho hàng hóa | D14: =D7/'Thong so - Độ nhậy - Bảng 1'!$C$27 -> 12296.85 | E14: =E7/'Thong so - Độ nhậy - Bảng 1'!$C$27 -> 12296.85 | F14: =F7/'Thong so - Độ nhậy - Bảng 1'!$C$27 -> 13833.956 | G14: =G7/'Thong so - Độ nhậy - Bảng 1'!$C$27 -> 13833.956 | H14: =H7/'Thong so - Độ nhậy - Bảng 1'!$C$27 -> 15371.062 | I14: =I7/'Thong so - Độ nhậy - Bảng 1'!$C$27 -> 15371.062 | J14: =J7/'Thong so - Độ nhậy - Bảng 1'!$C$27 -> 16908.169 | K14: =K7/'Thong so - Độ nhậy - Bảng 1'!$C$27 -> 16908.169 | ... AB14: =AB7/'Thong so - Độ nhậy - Bảng 1'!$C$27 -> 30742.125
A15: 11 | B15: Vốn lưu động (4-6+8+10) | D15: =D8-D10+D12+D14 -> 13960.269 | E15: =E8-E10+E12+E14 -> 13960.269 | F15: =F8-F10+F12+F14 -> 15705.302 | G15: =G8-G10+G12+G14 -> 15705.302 | H15: =H8-H10+H12+H14 -> 17450.336 | I15: =I8-I10+I12+I14 -> 17450.336 | J15: =J8-J10+J12+J14 -> 19195.37 | K15: =K8-K10+K12+K14 -> 19195.37 | ... AB15: =AB8-AB10+AB12+AB14 -> 34900.672
A16: 12 | B16: Nhu cầu vay vốn | D16: ='Thong so - Độ nhậy - Bảng 1'!$C$28*D15 -> 12564.242 | E16: ='Thong so - Độ nhậy - Bảng 1'!$C$28*E15 -> 12564.242 | F16: ='Thong so - Độ nhậy - Bảng 1'!$C$28*F15 -> 14134.772 | G16: ='Thong so - Độ nhậy - Bảng 1'!$C$28*G15 -> 14134.772 | H16: ='Thong so - Độ nhậy - Bảng 1'!$C$28*H15 -> 15705.302 | I16: ='Thong so - Độ nhậy - Bảng 1'!$C$28*I15 -> 15705.302 | J16: ='Thong so - Độ nhậy - Bảng 1'!$C$28*J15 -> 17275.833 | K16: ='Thong so - Độ nhậy - Bảng 1'!$C$28*K15 -> 17275.833 | ... AB16: ='Thong so - Độ nhậy - Bảng 1'!$C$28*AB15 -> 31410.605
A17: 12 | B17: Lãi vay VLĐ | D17: =D16*'Thong so - Độ nhậy - Bảng 1'!$N$20 -> 1005.1394 | E17: =E16*'Thong so - Độ nhậy - Bảng 1'!$N$20 -> 1005.1394 | F17: =F16*'Thong so - Độ nhậy - Bảng 1'!$N$20 -> 1130.7818 | G17: =G16*'Thong so - Độ nhậy - Bảng 1'!$N$20 -> 1130.7818 | H17: =H16*'Thong so - Độ nhậy - Bảng 1'!$N$20 -> 1256.4242 | I17: =I16*'Thong so - Độ nhậy - Bảng 1'!$N$20 -> 1256.4242 | J17: =J16*'Thong so - Độ nhậy - Bảng 1'!$N$20 -> 1382.0666 | K17: =K16*'Thong so - Độ nhậy - Bảng 1'!$N$20 -> 1382.0666 | ... AB17: =AB16*'Thong so - Độ nhậy - Bảng 1'!$N$20 -> 2512.8484

Sheet NPV (Tong dau tu) -Bảng 7
A1: BẢNG 7: DÒNG TIỀN THEO QUAN ĐIỂM TỔNG ĐẦU TƯ (TIP)
A3: STT | B3: KHOẢN MỤC | C3: 2016 | D3: 2017 | E3: 2018 | F3: 2019 | G3: 2020 | H3: 2021 | I3: 2022 | J3: 2023 | K3: 2024 | L3: 2025 | M3: 2026 | N3: 2027 | O3: 2028 | P3: 2029 | Q3: 2030 | R3: 2031 | S3: 2032 | T3: 2033 | U3: 2034 | V3: 2035 | W3: 2036 | X3: 2037 | Y3: 2038 | Z3: 2039 | AA3: 2040 | AB3: 2041 | AC3: 2042
A5: 1 | B5: Dòng tiền vào
B6: - Doanh thu | E6: ='KQKD- Bảng 4'!D8 -> 87452.394 | F6: ='KQKD- Bảng 4'!E8 -> 87452.394 | G6: ='KQKD- Bảng 4'!F8 -> 98383.943 | H6: ='KQKD- Bảng 4'!G8 -> 98383.943 | I6: ='KQKD- Bảng 4'!H8 -> 109315.49 | J6: ='KQKD- Bảng 4'!I8 -> 109315.49 | K6: ='KQKD- Bảng 4'!J8 -> 120247.04 | L6: ='KQKD- Bảng 4'!K8 -> 120247.04 | ... AC6: ='KQKD- Bảng 4'!AB8 -> 218630.99
B7: - DAR | E7: ='VLD- Bảng 6'!D9 -> -874.52394 | F7: ='VLD- Bảng 6'!E9 -> 0 | G7: ='VLD- Bảng 6'!F9 -> -109.31549 | H7: ='VLD- Bảng 6'!G9 -> 0 | I7: ='VLD- Bảng 6'!H9 -> -109.31549 | J7: ='VLD- Bảng 6'!I9 -> 0 | K7: ='VLD- Bảng 6'!J9 -> -109.31549 | L7: ='VLD- Bảng 6'!K9 -> 0 | ... AC7: ='VLD- Bảng 6'!AB9 -> 0
B8: - Thanh lý tài sản | F8: 0 | G8: 0 | H8: 0 | I8: 0 | J8: 0 | K8: 0 | L8: 0 | M8: 0 | N8: 0 | O8: 0 | P8: 0 | Q8: 0 | R8: 0 | S8: 0 | T8: 0 | U8: 0 | V8: 0 | W8: 0 | X8: 0 | Y8: 0 | Z8: 0 | AA8: 0 | AB8: 0 | AC8: 0
B9: - Hoàn thuế VAT
B10: Tổng ngân lưu vào | C10: 0 | D10: =SUM(D6:D9) -> 0 | E10: =SUM(E6:E9) -> 86577.87 | F10: =SUM(F6:F9) -> 87452.394 | G10: =SUM(G6:G9) -> 98274.628 | H10: =SUM(H6:H9) -> 98383.943 | I10: =SUM(I6:I9) -> 109206.18 | J10: =SUM(J6:J9) -> 109315.49 | K10: =SUM(K6:K9) -> 120137.73 | ... AC10: =SUM(AC6:AC9) -> 218630.99
A11: 2 | B11: Dòng tiền ra
B12: - Chi phí đầu tư | C12: 113750 | D12: 312086 | G12: 0 | H12: 0 | I12: 0 | J12: 0 | K12: 0 | L12: 0 | M12: 0 | N12: 0 | O12: 0 | P12: 0 | Q12: 0 | R12: 0 | S12: 0 | T12: 0 | U12: 0 | V12: 0 | W12: 0 | X12: 0 | Y12: 0 | Z12: 0 | AA12: 0 | AB12: 0 | AC12: 0
B13: - Chi phí hoạt động | E13: ='KQKD- Bảng 4'!D13 -> 45453.45 | F13: ='KQKD- Bảng 4'!E13 -> 45453.45 | G13: ='KQKD- Bảng 4'!F13 -> 51135.131 | H13: ='KQKD- Bảng 4'!G13 -> 51135.131 | I13: ='KQKD- Bảng 4'!H13 -> 56816.812 | J13: ='KQKD- Bảng 4'!I13 -> 56816.812 | K13: ='KQKD- Bảng 4'!J13 -> 62498.494 | L13: ='KQKD- Bảng 4'!K13 -> 62498.494 | ... AC13: ='KQKD- Bảng 4'!AB13 -> 113633.62
B14: - DAP | E14: ='VLD- Bảng 6'!D11 -> -85.629 | F14: ='VLD- Bảng 6'!E11 -> 0 | G14: ='VLD- Bảng 6'!F11 -> -10.703625 | H14: ='VLD- Bảng 6'!G11 -> 0 | I14: ='VLD- Bảng 6'!H11 -> -10.703625 | J14: ='VLD- Bảng 6'!I11 -> 0 | K14: ='VLD- Bảng 6'!J11 -> -10.703625 | L14: ='VLD- Bảng 6'!K11 -> 0 | ... AC14: ='VLD- Bảng 6'!AB11 -> 0
B15: - DCB | E15: ='VLD- Bảng 6'!D13 -> 874.52394 | F15: ='VLD- Bảng 6'!E13 -> 0 | G15: ='VLD- Bảng 6'!F13 -> 109.31549 | H15: ='VLD- Bảng 6'!G13 -> 0 | I15: ='VLD- Bảng 6'!H13 -> 109.31549 | J15: ='VLD- Bảng 6'!I13 -> 0 | K15: ='VLD- Bảng 6'!J13 -> 109.31549 | L15: ='VLD- Bảng 6'!K13 -> 0 | ... AC15: ='VLD- Bảng 6'!AB13 -> 0
B16: - Thuế TNDN | E16: ='KQKD- Bảng 4'!D30 -> 0 | F16: ='KQKD- Bảng 4'!E30 -> 112.64573 | G16: ='KQKD- Bảng 4'!F30 -> 1059.6561 | H16: ='KQKD- Bảng 4'!G30 -> 1315.8271 | I16: ='KQKD- Bảng 4'!H30 -> 2354.4643 | J16: ='KQKD- Bảng 4'!I30 -> 2707.5939 | K16: ='KQKD- Bảng 4'!J30 -> 3848.8321 | L16: ='KQKD- Bảng 4'!K30 -> 4310.5331 | ... AC16: ='KQKD- Bảng 4'!AB30 -> 16421.559
B17: Tổng ngân lưu ra | C17: =SUM(C12:C16) -> 113750 | D17: =SUM(D12:D16) -> 312086 | E17: =SUM(E12:E16) -> 46242.345 | F17: =SUM(F12:F16) -> 45566.096 | G17: =SUM(G12:G16) -> 52293.399 | H17: =SUM(H12:H16) -> 52450.958 | I17: =SUM(I12:I16) -> 59269.889 | J17: =SUM(J12:J16) -> 59524.406 | ... AC17: =SUM(AC12:AC16) -> 130055.18
A18: 3 | B18: Ngân lưu ròng | C18: =C10-C17 -> -113750 | D18: =D10-D17 -> -312086 | E18: =E10-E17 -> 40335.525 | F18: =F10-F17 -> 41886.298 | G18: =G10-G17 -> 45981.229 | H18: =H10-H17 -> 45932.985 | I18: =I10-I17 -> 49936.288 | J18: =J10-J17 -> 49791.086 | ... AC18: =AC10-AC17 -> 88575.801
B19: NPVTIP -15 năm | C19: =NPV('Thong so - Độ nhậy - Bảng 1'!N18,'NPV (Tong dau tu) -Bảng 7'!D18:AC18) +C18 -> 103242.43
B20: IRRTIP- 15 năm | C20: =IRR(C18:AC18) -> 0.11932043
B21: Dòng tiền chiết khẩu | C21: =C18/(1+'Thong so - Độ nhậy - Bảng 1'!$N$18)^C24 -> -113750 | D21: =D18/(1+'Thong so - Độ nhậy - Bảng 1'!$N$18)^D24 -> -285206.32 | E21: =E18/(1+'Thong so - Độ nhậy - Bảng 1'!$N$18)^E24 -> 33686.62 | F21: =F18/(1+'Thong so - Độ nhậy - Bảng 1'!$N$18)^F24 -> 31968.818 | G21: =G18/(1+'Thong so - Độ nhậy - Bảng 1'!$N$18)^G24 -> 32071.556 | H21: =H18/(1+'Thong so - Độ nhậy - Bảng 1'!$N$18)^H24 -> 29278.511 | I21: =I18/(1+'Thong so - Độ nhậy - Bảng 1'!$N$18)^I24 -> 29088.776 | J21: =J18/(1+'Thong so - Độ nhậy - Bảng 1'!$N$18)^J24 -> 26506.089 | ... AC21: =AC18/(1+'Thong so - Độ nhậy - Bảng 1'!$N$18)^AC24 -> 8517.6846
B22: Dòng tiền chiết khấu lũy kế | C22: =C21 -> -113750 | D22: =C22+D21 -> -398956.32 | E22: =E21+D22 -> -365269.7 | F22: =F21+E22 -> -333300.89 | G22: =G21+F22 -> -301229.33 | H22: =H21+G22 -> -271950.82 | I22: =I21+H22 -> -242862.04 | J22: =J21+I22 -> -216355.95 | K22: =K21+J22 -> -190235.14 | L22: =L21+K22 -> -166476.91 | ... AC22: =AC21+AB22 -> 103242.43
B23: Thời gian hoàn vốn | C23: 17
C24: 0 | D24: 1 | E24: 2 | F24: 3 | G24: 4 | H24: 5 | I24: 6 | J24: 7 | K24: 8 | L24: 9 | M24: 10 | N24: 11 | O24: 12 | P24: 13 | Q24: 14 | R24: 15 | S24: 16 | T24: 17 | U24: 18 | V24: 19 | W24: 20 | X24: 21 | Y24: 22 | Z24: 23 | AA24: 24 | AB24: 25 | AC24: 26
F25: ='KQKD- Bảng 4'!D29 -> -272.62581 | G25: ='KQKD- Bảng 4'!E29 -> 563.22863 | H25: ='KQKD- Bảng 4'!F29 -> 5298.2806 | I25: ='KQKD- Bảng 4'!G29 -> 6579.1353 | J25: ='KQKD- Bảng 4'!H29 -> 11772.321 | K25: ='KQKD- Bảng 4'!I29 -> 13537.97 | L25: ='KQKD- Bảng 4'!J29 -> 19244.16 | M25: ='KQKD- Bảng 4'!K29 -> 21552.665 | N25: ='KQKD- Bảng 4'!L29 -> 27833.303
F26: =E18+F18-F25 -> 82494.449 | G26: =F26+G18-G25 -> 127912.45 | H26: =G26+H18-H25 -> 168547.15 | I26: =H26+I18-I25 -> 211904.31 | J26: =I26+J18-J25 -> 249923.07 | K26: =J26+K18-K25 -> 290076.89 | L26: =K26+L18-L25 -> 324270.74 | M26: =0.345*12 -> 4.14 | N26: =M26+N18 -> 56852.62 | O26: =N26+O18 -> 117358.26
D36: =2^1.05 -> 2.0705298
D37: =D36^1.05 -> 2.1472646

Sheet NPV - CĐT
B1: BẢNG 7: DÒNG TIỀN THEO QUAN ĐIỂM CHỦ ĐẦU TƯ (EPV)
B3: STT | C3: KHOẢN MỤC | D3: NĂM ĐẦU TƯ | F3: NĂM HOẠT ĐỘNG
D4: 0 | E4: 1 | F4: 1 | G4: 2 | H4: 3 | I4: 4 | J4: 5 | K4: 6 | L4: 7 | M4: 8 | N4: 9 | O4: 10
B5: 1 | C5: Dòng tiền vào
C6: - Doanh thu | F6: ='NPV (Tong dau tu) -Bảng 7'!F6 -> 87452.394 | G6: ='NPV (Tong dau tu) -Bảng 7'!G6 -> 98383.943 | H6: ='NPV (Tong dau tu) -Bảng 7'!H6 -> 98383.943 | I6: ='NPV (Tong dau tu) -Bảng 7'!I6 -> 109315.49 | J6: ='NPV (Tong dau tu) -Bảng 7'!J6 -> 109315.49 | K6: ='NPV (Tong dau tu) -Bảng 7'!K6 -> 120247.04 | L6: ='NPV (Tong dau tu) -Bảng 7'!L6 -> 120247.04 | M6: ='NPV (Tong dau tu) -Bảng 7'!M6 -> 131178.59 | ... O6: ='NPV (Tong dau tu) -Bảng 7'!O6 -> 142110.14
C7: - DAR | F7: ='NPV (Tong dau tu) -Bảng 7'!F7 -> 0 | G7: ='NPV (Tong dau tu) -Bảng 7'!G7 -> -109.31549 | H7: ='NPV (Tong dau tu) -Bảng 7'!H7 -> 0 | I7: ='NPV (Tong dau tu) -Bảng 7'!I7 -> -109.31549 | J7: ='NPV (Tong dau tu) -Bảng 7'!J7 -> 0 | K7: ='NPV (Tong dau tu) -Bảng 7'!K7 -> -109.31549 | L7: ='NPV (Tong dau tu) -Bảng 7'!L7 -> 0 | M7: ='NPV (Tong dau tu) -Bảng 7'!M7 -> -109.31549 | ... O7: ='NPV (Tong dau tu) -Bảng 7'!O7 -> -109.31549
C8: - Thanh lý tài sản | F8: 0 | G8: 0 | H8: 0 | I8: 0 | J8: 0 | K8: 0 | L8: 0 | M8: 0 | N8: 0 | O8: 0
C9: - Vay NHTM trong nước | E9: 114000
C10: - Hoàn thuế VAT | F10: ='NPV (Tong dau tu) -Bảng 7'!F9 -> 0 | G10: ='NPV (Tong dau tu) -Bảng 7'!G9 -> 0 | H10: ='NPV (Tong dau tu) -Bảng 7'!H9 -> 0 | I10: ='NPV (Tong dau tu) -Bảng 7'!I9 -> 0 | J10: ='NPV (Tong dau tu) -Bảng 7'!J9 -> 0 | K10: ='NPV (Tong dau tu) -Bảng 7'!K9 -> 0 | L10: ='NPV (Tong dau tu) -Bảng 7'!L9 -> 0
C11: Tổng ngân lưu vào | D11: =SUM(D6:D10) -> 0 | E11: =SUM(E6:E10) -> 114000 | F11: =SUM(F6:F10) -> 87452.394 | G11: =SUM(G6:G10) -> 98274.628 | H11: =SUM(H6:H10) -> 98383.943 | I11: =SUM(I6:I10) -> 109206.18 | J11: =SUM(J6:J10) -> 109315.49 | K11: =SUM(K6:K10) -> 120137.73 | ... O11: =SUM(O6:O10) -> 142000.82
B12: 2 | C12: Dòng tiền ra
C13: - Chi phí đầu tư | D13: ='NPV (Tong dau tu) -Bảng 7'!D12 -> 312086 | E13: ='NPV (Tong dau tu) -Bảng 7'!E12 -> 0
C14: - Chi phí hoạt động | F14: ='NPV (Tong dau tu) -Bảng 7'!F13 -> 45453.45 | G14: ='NPV (Tong dau tu) -Bảng 7'!G13 -> 51135.131 | H14: ='NPV (Tong dau tu) -Bảng 7'!H13 -> 51135.131 | I14: ='NPV (Tong dau tu) -Bảng 7'!I13 -> 56816.812 | J14: ='NPV (Tong dau tu) -Bảng 7'!J13 -> 56816.812 | K14: ='NPV (Tong dau tu) -Bảng 7'!K13 -> 62498.494 | L14: ='NPV (Tong dau tu) -Bảng 7'!L13 -> 62498.494 | M14: ='NPV (Tong dau tu) -Bảng 7'!M13 -> 68180.175 | ... O14: ='NPV (Tong dau tu) -Bảng 7'!O13 -> 73861.856
C15: - DAP | F15: ='NPV (Tong dau tu) -Bảng 7'!F14 -> 0 | G15: ='NPV (Tong dau tu) -Bảng 7'!G14 -> -10.703625 | H15: ='NPV (Tong dau tu) -Bảng 7'!H14 -> 0 | I15: ='NPV (Tong dau tu) -Bảng 7'!I14 -> -10.703625 | J15: ='NPV (Tong dau tu) -Bảng 7'!J14 -> 0 | K15: ='NPV (Tong dau tu) -Bảng 7'!K14 -> -10.703625 | L15: ='NPV (Tong dau tu) -Bảng 7'!L14 -> 0 | M15: ='NPV (Tong dau tu) -Bảng 7'!M14 -> -10.703625 | ... O15: ='NPV (Tong dau tu) -Bảng 7'!O14 -> -10.703625
C16: - DCB | F16: ='NPV (Tong dau tu) -Bảng 7'!F15 -> 0 | G16: ='NPV (Tong dau tu) -Bảng 7'!G15 -> 109.31549 | H16: ='NPV (Tong dau tu) -Bảng 7'!H15 -> 0 | I16: ='NPV (Tong dau tu) -Bảng 7'!I15 -> 109.31549 | J16: ='NPV (Tong dau tu) -Bảng 7'!J15 -> 0 | K16: ='NPV (Tong dau tu) -Bảng 7'!K15 -> 109.31549 | L16: ='NPV (Tong dau tu) -Bảng 7'!L15 -> 0 | M16: ='NPV (Tong dau tu) -Bảng 7'!M15 -> 109.31549 | ... O16: ='NPV (Tong dau tu) -Bảng 7'!O15 -> 109.31549
C17: - Thuế TNDN | F17: ='NPV (Tong dau tu) -Bảng 7'!F16 -> 112.64573 | G17: ='NPV (Tong dau tu) -Bảng 7'!G16 -> 1059.6561 | H17: ='NPV (Tong dau tu) -Bảng 7'!H16 -> 1315.8271 | I17: ='NPV (Tong dau tu) -Bảng 7'!I16 -> 2354.4643 | J17: ='NPV (Tong dau tu) -Bảng 7'!J16 -> 2707.5939 | K17: ='NPV (Tong dau tu) -Bảng 7'!K16 -> 3848.8321 | L17: ='NPV (Tong dau tu) -Bảng 7'!L16 -> 4310.5331 | M17: ='NPV (Tong dau tu) -Bảng 7'!M16 -> 5566.6605 | ... O17: ='NPV (Tong dau tu) -Bảng 7'!O16 -> 7534.7133
C18: - Trả nợ NHTM trong nước | F18: ='KH trả nợ-Bảng 5'!C15 -> 7960.5185 | G18: ='KH trả nợ-Bảng 5'!D15 -> 8545.2879 | H18: ='KH trả nợ-Bảng 5'!E15 -> 12198.616 | I18: ='KH trả nợ-Bảng 5'!F15 -> 12908.47 | J18: ='KH trả nợ-Bảng 5'!G15 -> 16815.698 | K18: ='KH trả nợ-Bảng 5'!H15 -> 17794.227 | L18: ='KH trả nợ-Bảng 5'!I15 -> 21985.763 | M18: ='KH trả nợ-Bảng 5'!J15 -> 23265.146 | N18: ='KH trả nợ-Bảng 5'!K15 -> 27775.043 | O18: ='KH trả nợ-Bảng 5'!L14 -> 29391.312
C19: Tổng ngân lưu ra | D19: =SUM(D13:D18) -> 312086 | E19: =SUM(E13:E18) -> 0 | F19: =SUM(F13:F18) -> 53526.614 | G19: =SUM(G13:G18) -> 60838.687 | H19: =SUM(H13:H18) -> 64649.574 | I19: =SUM(I13:I18) -> 72178.359 | J19: =SUM(J13:J18) -> 76340.104 | K19: =SUM(K13:K18) -> 84240.165 | ... O19: =SUM(O13:O18) -> 110886.49
